<?xml version="1.0" encoding="utf-8"?>
<!-- This URDF was automatically created by SolidWorks to URDF Exporter! Originally created by Stephen Brawner (brawner@gmail.com) 
     Commit Version: 1.6.0-4-g7f85cfe  Build Version: 1.6.7995.38578
     For more information, please see http://wiki.ros.org/sw_urdf_exporter -->
<robot
  name="humanoid_arm_5dof">
  <link
    name="base_fixture_link">
    <inertial>
      <origin
        xyz="0.0200383951813436 0.0118733123574186 0.366640083424823"
        rpy="0 0 0" />
      <mass
        value="10.0408046496141" />
      <inertia
        ixx="2.85095653203043"
        ixy="-0.0251848948200707"
        ixz="-0.217965410721046"
        iyy="2.87853790929507"
        iyz="-0.129150632133139"
        izz="0.185251983223026" />
    </inertial>
    <visual>
      <origin
        xyz="0 0 0"
        rpy="0 0 0" />
      <geometry>
        <mesh
          filename="package://humanoid_arm_5dof/meshes/base_fixture_link.STL" />
      </geometry>
      <material
        name="">
        <color
          rgba="0.792156862745098 0.819607843137255 0.933333333333333 1" />
      </material>
    </visual>
    <collision>
      <origin
        xyz="0 0 0"
        rpy="0 0 0" />
      <geometry>
        <mesh
          filename="package://humanoid_arm_5dof/meshes/base_fixture_link.STL" />
      </geometry>
    </collision>
  </link>
  <link
    name="left_shoulder_pitch_rs04_actuator">
    <inertial>
      <origin
        xyz="-0.0245322216652193 1.17283960321402E-12 -9.62341317745086E-13"
        rpy="0 0 0" />
      <mass
        value="0.517423577893352" />
      <inertia
        ixx="0.000876413569064526"
        ixy="-1.15569175323377E-17"
        ixz="-1.47661559628948E-16"
        iyy="0.000542404795301473"
        iyz="-3.54714747575891E-06"
        izz="0.00054116434911771" />
    </inertial>
    <visual>
      <origin
        xyz="0 0 0"
        rpy="0 0 0" />
      <geometry>
        <mesh
          filename="package://humanoid_arm_5dof/meshes/left_shoulder_pitch_rs04_actuator.STL" />
      </geometry>
      <material
        name="">
        <color
          rgba="0.823529411764706 0.823529411764706 1 1" />
      </material>
    </visual>
    <collision>
      <origin
        xyz="0 0 0"
        rpy="0 0 0" />
      <geometry>
        <mesh
          filename="package://humanoid_arm_5dof/meshes/left_shoulder_pitch_rs04_actuator.STL" />
      </geometry>
    </collision>
  </link>
  <joint
    name="left_shoulder_pitch_rs04_actuator_fixture_link"
    type="fixed">
    <origin
      xyz="0.329242881244431 0.195085661056411 1.45000000000145"
      rpy="-0.61079662163343 0 0.534907346303552" />
    <parent
      link="base_fixture_link" />
    <child
      link="left_shoulder_pitch_rs04_actuator" />
    <axis
      xyz="0 0 0" />
  </joint>
  <link
    name="left_shoulder_pitch_rs04_flange">
    <inertial>
      <origin
        xyz="-0.00188936806429174 -9.55715032069371E-05 2.58079792323507E-05"
        rpy="0 0 0" />
      <mass
        value="0.00758352122244539" />
      <inertia
        ixx="2.3623080270335E-06"
        ixy="3.38151434411678E-21"
        ixz="-3.40136667881805E-21"
        iyy="1.1940642065959E-06"
        iyz="-2.64697796016969E-21"
        izz="1.1940642065959E-06" />
    </inertial>
    <visual>
      <origin
        xyz="0 0 0"
        rpy="0 0 0" />
      <geometry>
        <mesh
          filename="package://humanoid_arm_5dof/meshes/left_shoulder_pitch_rs04_flange.STL" />
      </geometry>
      <material
        name="">
        <color
          rgba="0.823529411764706 0.823529411764706 1 1" />
      </material>
    </visual>
    <collision>
      <origin
        xyz="0 0 0"
        rpy="0 0 0" />
      <geometry>
        <mesh
          filename="package://humanoid_arm_5dof/meshes/left_shoulder_pitch_rs04_flange.STL" />
      </geometry>
    </collision>
  </link>
  <joint
    name="left_shoulder_pitch_rs04_joint"
    type="revolute">
    <origin
      xyz="0 0 0"
      rpy="0 0 0" />
    <parent
      link="left_shoulder_pitch_rs04_actuator" />
    <child
      link="left_shoulder_pitch_rs04_flange" />
    <axis
      xyz="1 0 0" />
    <limit
      lower="-3.14"
      upper="3.14"
      effort="120"
      velocity="3" />
    <safety_controller
      soft_upper_limit="3.14"
      soft_lower_limit="-3.14"
      k_velocity="0" />
  </joint>
  <link
    name="m5x22_screws_left_shoulder_pitch">
    <inertial>
      <origin
        xyz="0.00639350433679509 -0.00479834508260391 0.00128572351563494"
        rpy="0 0 0" />
      <mass
        value="0.00474644340626602" />
      <inertia
        ixx="2.66191925293527E-08"
        ixy="-1.25098390543482E-13"
        ixz="-1.97477628165889E-13"
        iyy="3.31053916794899E-07"
        iyz="8.62570748379259E-14"
        izz="3.31054672965682E-07" />
    </inertial>
    <visual>
      <origin
        xyz="0 0 0"
        rpy="0 0 0" />
      <geometry>
        <mesh
          filename="package://humanoid_arm_5dof/meshes/m5x22_screws_left_shoulder_pitch.STL" />
      </geometry>
      <material
        name="">
        <color
          rgba="0.792156862745098 0.819607843137255 0.933333333333333 1" />
      </material>
    </visual>
    <collision>
      <origin
        xyz="0 0 0"
        rpy="0 0 0" />
      <geometry>
        <mesh
          filename="package://humanoid_arm_5dof/meshes/m5x22_screws_left_shoulder_pitch.STL" />
      </geometry>
    </collision>
  </link>
  <joint
    name="m5x22_screws_left_shoulder_pitch_fixture_joint"
    type="fixed">
    <origin
      xyz="0 0 0"
      rpy="0 0 0" />
    <parent
      link="left_shoulder_pitch_rs04_flange" />
    <child
      link="m5x22_screws_left_shoulder_pitch" />
    <axis
      xyz="0 0 0" />
  </joint>
  <link
    name="left_shoulder_pitch">
    <inertial>
      <origin
        xyz="0.0682474669413152 0.0395514519675162 -5.23399199936492E-06"
        rpy="0 0 0" />
      <mass
        value="1.19772100018969" />
      <inertia
        ixx="0.00347656174617422"
        ixy="-0.00164350112486171"
        ixz="-3.10209101414679E-07"
        iyy="0.00604621894393634"
        iyz="-1.29484961695989E-07"
        izz="0.00615255051609316" />
    </inertial>
    <visual>
      <origin
        xyz="0 0 0"
        rpy="0 0 0" />
      <geometry>
        <mesh
          filename="package://humanoid_arm_5dof/meshes/left_shoulder_pitch.STL" />
      </geometry>
      <material
        name="">
        <color
          rgba="0.952941176470588 0.996078431372549 0.694117647058824 1" />
      </material>
    </visual>
    <collision>
      <origin
        xyz="0 0 0"
        rpy="0 0 0" />
      <geometry>
        <mesh
          filename="package://humanoid_arm_5dof/meshes/left_shoulder_pitch.STL" />
      </geometry>
    </collision>
  </link>
  <joint
    name="left_shoulder_pitch_fixture_joint"
    type="fixed">
    <origin
      xyz="0 0 0"
      rpy="0 0 0" />
    <parent
      link="m5x22_screws_left_shoulder_pitch" />
    <child
      link="left_shoulder_pitch" />
    <axis
      xyz="0 0 0" />
  </joint>
  <link
    name="m5x22_screws_left_shoulder_roll">
    <inertial>
      <origin
        xyz="0.116724155999436 0.0615935045052161 2.41514964096634E-05"
        rpy="0 0 0" />
      <mass
        value="0.00610257053905786" />
      <inertia
        ixx="4.25641380807017E-07"
        ixy="1.38655676077118E-13"
        ixz="4.6529540191251E-13"
        iyy="3.42246799589697E-08"
        iyz="2.62635762215098E-13"
        izz="4.25641102603534E-07" />
    </inertial>
    <visual>
      <origin
        xyz="0 0 0"
        rpy="0 0 0" />
      <geometry>
        <mesh
          filename="package://humanoid_arm_5dof/meshes/m5x22_screws_left_shoulder_roll.STL" />
      </geometry>
      <material
        name="">
        <color
          rgba="0.792156862745098 0.819607843137255 0.933333333333333 1" />
      </material>
    </visual>
    <collision>
      <origin
        xyz="0 0 0"
        rpy="0 0 0" />
      <geometry>
        <mesh
          filename="package://humanoid_arm_5dof/meshes/m5x22_screws_left_shoulder_roll.STL" />
      </geometry>
    </collision>
  </link>
  <joint
    name="m5x22_screws_left_shoulder_roll_fixture_joint"
    type="fixed">
    <origin
      xyz="0 0 0"
      rpy="0 0 0" />
    <parent
      link="left_shoulder_pitch" />
    <child
      link="m5x22_screws_left_shoulder_roll" />
    <axis
      xyz="0 0 0" />
  </joint>
  <link
    name="left_shoulder_roll_rs04_flange">
    <inertial>
      <origin
        xyz="-3.47499806707674E-14 -0.00211063193645256 1.1797052223983E-10"
        rpy="0 0 0" />
      <mass
        value="0.00758352122244542" />
      <inertia
        ixx="1.1940642065959E-06"
        ixy="-8.20563167652603E-22"
        ixz="-4.63221143029695E-22"
        iyy="2.3623080270335E-06"
        iyz="-2.72684316151908E-15"
        izz="1.1940642065959E-06" />
    </inertial>
    <visual>
      <origin
        xyz="0 0 0"
        rpy="0 0 0" />
      <geometry>
        <mesh
          filename="package://humanoid_arm_5dof/meshes/left_shoulder_roll_rs04_flange.STL" />
      </geometry>
      <material
        name="">
        <color
          rgba="0.823529411764706 0.823529411764706 1 1" />
      </material>
    </visual>
    <collision>
      <origin
        xyz="0 0 0"
        rpy="0 0 0" />
      <geometry>
        <mesh
          filename="package://humanoid_arm_5dof/meshes/left_shoulder_roll_rs04_flange.STL" />
      </geometry>
    </collision>
  </link>
  <joint
    name="left_shoulder_roll_rs04_flange_joint"
    type="fixed">
    <origin
      xyz="0.116775431275821 0.0487000000004332 -2.70558071411298E-05"
      rpy="0 0 3.14159265358979" />
    <parent
      link="m5x22_screws_left_shoulder_roll" />
    <child
      link="left_shoulder_roll_rs04_flange" />
    <axis
      xyz="0 0 0" />
  </joint>
  <link
    name="left_shoulder_roll_rs04_actuator">
    <inertial>
      <origin
        xyz="7.5431275761817E-05 0.0205322216645354 2.70558719566161E-05"
        rpy="0 0 0" />
      <mass
        value="0.517423577893356" />
      <inertia
        ixx="0.000542006962748034"
        ixy="-8.42033081173248E-15"
        ixz="-3.59408880621033E-06"
        iyy="0.000876413569064537"
        iyz="-7.81742997158635E-13"
        izz="0.000541562181671229" />
    </inertial>
    <visual>
      <origin
        xyz="0 0 0"
        rpy="0 0 0" />
      <geometry>
        <mesh
          filename="package://humanoid_arm_5dof/meshes/left_shoulder_roll_rs04_actuator.STL" />
      </geometry>
      <material
        name="">
        <color
          rgba="0.823529411764706 0.823529411764706 1 1" />
      </material>
    </visual>
    <collision>
      <origin
        xyz="0 0 0"
        rpy="0 0 0" />
      <geometry>
        <mesh
          filename="package://humanoid_arm_5dof/meshes/left_shoulder_roll_rs04_actuator.STL" />
      </geometry>
    </collision>
  </link>
  <joint
    name="left_shoulder_roll_rs04_joint"
    type="revolute">
    <origin
      xyz="0 0 0"
      rpy="0 0 0" />
    <parent
      link="left_shoulder_roll_rs04_flange" />
    <child
      link="left_shoulder_roll_rs04_actuator" />
    <axis
      xyz="0 -1 0" />
    <limit
      lower="-3.5"
      upper="0.6"
      effort="120"
      velocity="3" />
    <safety_controller
      soft_upper_limit="3.14"
      soft_lower_limit="-3.14"
      k_velocity="0" />
  </joint>
  <link
    name="m4x25_left_shoulder_screws_roll">
    <inertial>
      <origin
        xyz="5.45041063048091E-05 0.0496289837029047 5.40653504537136E-05"
        rpy="0 0 0" />
      <mass
        value="0.00451430348886338" />
      <inertia
        ixx="3.68173387240373E-07"
        ixy="-6.77491685654944E-15"
        ixz="6.50698816450757E-17"
        iyy="1.54230097659287E-08"
        iyz="3.36388331196065E-16"
        izz="3.68173386339836E-07" />
    </inertial>
    <visual>
      <origin
        xyz="0 0 0"
        rpy="0 0 0" />
      <geometry>
        <mesh
          filename="package://humanoid_arm_5dof/meshes/m4x25_left_shoulder_screws_roll.STL" />
      </geometry>
      <material
        name="">
        <color
          rgba="0.792156862745098 0.819607843137255 0.933333333333333 1" />
      </material>
    </visual>
    <collision>
      <origin
        xyz="0 0 0"
        rpy="0 0 0" />
      <geometry>
        <mesh
          filename="package://humanoid_arm_5dof/meshes/m4x25_left_shoulder_screws_roll.STL" />
      </geometry>
    </collision>
  </link>
  <joint
    name="m4x25_left_shoulder_screws_roll_fixture_joint"
    type="fixed">
    <origin
      xyz="0 0 0"
      rpy="0 0 0" />
    <parent
      link="left_shoulder_roll_rs04_actuator" />
    <child
      link="m4x25_left_shoulder_screws_roll" />
    <axis
      xyz="0 0 0" />
  </joint>
  <link
    name="left_shoulder_roll">
    <inertial>
      <origin
        xyz="-0.00752228691013401 0.0497547007138057 -0.0556811680024578"
        rpy="0 0 0" />
      <mass
        value="0.997620690019998" />
      <inertia
        ixx="0.00534467265523802"
        ixy="-8.46143380992818E-05"
        ixz="-0.000430210472532785"
        iyy="0.00591903784526592"
        iyz="-0.000640722365831411"
        izz="0.00178281861548494" />
    </inertial>
    <visual>
      <origin
        xyz="0 0 0"
        rpy="0 0 0" />
      <geometry>
        <mesh
          filename="package://humanoid_arm_5dof/meshes/left_shoulder_roll.STL" />
      </geometry>
      <material
        name="">
        <color
          rgba="0.952941176470588 0.996078431372549 0.694117647058824 1" />
      </material>
    </visual>
    <collision>
      <origin
        xyz="0 0 0"
        rpy="0 0 0" />
      <geometry>
        <mesh
          filename="package://humanoid_arm_5dof/meshes/left_shoulder_roll.STL" />
      </geometry>
    </collision>
  </link>
  <joint
    name="left_shoulde_roll_fixture_joint"
    type="fixed">
    <origin
      xyz="0 0 0"
      rpy="0 0 0" />
    <parent
      link="m4x25_left_shoulder_screws_roll" />
    <child
      link="left_shoulder_roll" />
    <axis
      xyz="0 0 0" />
  </joint>
  <link
    name="m4x16_left_shoulder_yaw_screws">
    <inertial>
      <origin
        xyz="2.30950814028574E-10 5.06211073059148E-10 0.0451525729719058"
        rpy="0 0 0" />
      <mass
        value="0.00270184474693413" />
      <inertia
        ixx="1.03557857485271E-07"
        ixy="1.5585002358545E-16"
        ixz="-1.92166044513534E-15"
        iyy="1.0355785773746E-07"
        iyz="-4.01415381842613E-15"
        izz="1.05098007898705E-08" />
    </inertial>
    <visual>
      <origin
        xyz="0 0 0"
        rpy="0 0 0" />
      <geometry>
        <mesh
          filename="package://humanoid_arm_5dof/meshes/m4x16_left_shoulder_yaw_screws.STL" />
      </geometry>
      <material
        name="">
        <color
          rgba="0.792156862745098 0.819607843137255 0.933333333333333 1" />
      </material>
    </visual>
    <collision>
      <origin
        xyz="0 0 0"
        rpy="0 0 0" />
      <geometry>
        <mesh
          filename="package://humanoid_arm_5dof/meshes/m4x16_left_shoulder_yaw_screws.STL" />
      </geometry>
    </collision>
  </link>
  <joint
    name="m4x16_left_shoulder_yaw_screws_fixture_joint"
    type="fixed">
    <origin
      xyz="-0.021972 0.0377 -0.17358"
      rpy="0.057123 0.11257 0.47088" />
    <parent
      link="left_shoulder_roll" />
    <child
      link="m4x16_left_shoulder_yaw_screws" />
    <axis
      xyz="0 0 0" />
  </joint>
  <link
    name="left_shoulder_yaw_rs03_actuator">
    <inertial>
      <origin
        xyz="-0.000137350571109196 -0.000269996934420202 0.02508416517084"
        rpy="0 0 0" />
      <mass
        value="0.356550969588108" />
      <inertia
        ixx="0.000274320425080908"
        ixy="-2.07349930601436E-06"
        ixz="-2.56253646594402E-07"
        iyy="0.000271291938182262"
        iyz="-5.14924748624114E-07"
        izz="0.000381662133737712" />
    </inertial>
    <visual>
      <origin
        xyz="0 0 0"
        rpy="0 0 0" />
      <geometry>
        <mesh
          filename="package://humanoid_arm_5dof/meshes/left_shoulder_yaw_rs03_actuator.STL" />
      </geometry>
      <material
        name="">
        <color
          rgba="0.823529411764706 0.823529411764706 1 1" />
      </material>
    </visual>
    <collision>
      <origin
        xyz="0 0 0"
        rpy="0 0 0" />
      <geometry>
        <mesh
          filename="package://humanoid_arm_5dof/meshes/left_shoulder_yaw_rs03_actuator.STL" />
      </geometry>
    </collision>
  </link>
  <joint
    name="left_shoulder_yaw_rs03_actuator_fixture_link"
    type="fixed">
    <origin
      xyz="0 0 0"
      rpy="0 0 0" />
    <parent
      link="m4x16_left_shoulder_yaw_screws" />
    <child
      link="left_shoulder_yaw_rs03_actuator" />
    <axis
      xyz="0 0 0" />
  </joint>
  <link
    name="left_shoulder_yaw_rs03_flange">
    <inertial>
      <origin
        xyz="-1.87114213012762E-10 -3.64114516315794E-10 -0.00125625967423182"
        rpy="0 0 0" />
      <mass
        value="0.00407555097398881" />
      <inertia
        ixx="5.67676746163435E-07"
        ixy="1.60142166590266E-21"
        ixz="6.47210061448945E-16"
        iyy="5.6767674616344E-07"
        iyz="1.28044726556791E-15"
        izz="1.13114082374845E-06" />
    </inertial>
    <visual>
      <origin
        xyz="0 0 0"
        rpy="0 0 0" />
      <geometry>
        <mesh
          filename="package://humanoid_arm_5dof/meshes/left_shoulder_yaw_rs03_flange.STL" />
      </geometry>
      <material
        name="">
        <color
          rgba="0.823529411764706 0.823529411764706 1 1" />
      </material>
    </visual>
    <collision>
      <origin
        xyz="0 0 0"
        rpy="0 0 0" />
      <geometry>
        <mesh
          filename="package://humanoid_arm_5dof/meshes/left_shoulder_yaw_rs03_flange.STL" />
      </geometry>
    </collision>
  </link>
  <joint
    name="left_shoulder_yaw_rs03_joint"
    type="revolute">
    <origin
      xyz="0 0 0"
      rpy="0 0 0" />
    <parent
      link="left_shoulder_yaw_rs03_actuator" />
    <child
      link="left_shoulder_yaw_rs03_flange" />
    <axis
      xyz="0 0 1" />
    <limit
      lower="-3.14"
      upper="3.14"
      effort="60"
      velocity="1.6" />
    <safety_controller
      soft_upper_limit="3.14"
      soft_lower_limit="-3.14"
      k_velocity="0" />
  </joint>
  <link
    name="left_shoulder_yaw_shaft">
    <inertial>
      <origin
        xyz="-2.02680094929519E-10 -3.89372090126017E-10 -0.0119851125561186"
        rpy="0 0 0" />
      <mass
        value="0.000903649674374" />
      <inertia
        ixx="4.41715688076243E-08"
        ixy="-6.82424005356248E-24"
        ixz="-4.86629629806428E-17"
        iyy="4.41715688076243E-08"
        iyz="-9.62753835773825E-17"
        izz="1.8053981329595E-09" />
    </inertial>
    <visual>
      <origin
        xyz="0 0 0"
        rpy="0 0 0" />
      <geometry>
        <mesh
          filename="package://humanoid_arm_5dof/meshes/left_shoulder_yaw_shaft.STL" />
      </geometry>
      <material
        name="">
        <color
          rgba="0.823529411764706 0.823529411764706 1 1" />
      </material>
    </visual>
    <collision>
      <origin
        xyz="0 0 0"
        rpy="0 0 0" />
      <geometry>
        <mesh
          filename="package://humanoid_arm_5dof/meshes/left_shoulder_yaw_shaft.STL" />
      </geometry>
    </collision>
  </link>
  <joint
    name="left_shoulder_yaw_shaft_fixture_joint"
    type="fixed">
    <origin
      xyz="0 0 0"
      rpy="0 0 0" />
    <parent
      link="left_shoulder_yaw_rs03_flange" />
    <child
      link="left_shoulder_yaw_shaft" />
    <axis
      xyz="0 0 0" />
    <limit
      lower="0"
      upper="0"
      effort="0"
      velocity="0" />
  </joint>
  <link
    name="left_shoulder_yaw_flange">
    <inertial>
      <origin
        xyz="-1.95517602108453E-10 -3.76683129132971E-10 -0.00898037825638709"
        rpy="0 0 0" />
      <mass
        value="0.035353146109952" />
      <inertia
        ixx="9.85459914701274E-06"
        ixy="-7.54070449822593E-08"
        ixz="1.07041732007387E-14"
        iyy="9.5933770582241E-06"
        iyz="2.03233659115925E-14"
        izz="1.87117812635894E-05" />
    </inertial>
    <visual>
      <origin
        xyz="0 0 0"
        rpy="0 0 0" />
      <geometry>
        <mesh
          filename="package://humanoid_arm_5dof/meshes/left_shoulder_yaw_flange.STL" />
      </geometry>
      <material
        name="">
        <color
          rgba="0.952941176470588 0.996078431372549 0.694117647058824 1" />
      </material>
    </visual>
    <collision>
      <origin
        xyz="0 0 0"
        rpy="0 0 0" />
      <geometry>
        <mesh
          filename="package://humanoid_arm_5dof/meshes/left_shoulder_yaw_flange.STL" />
      </geometry>
    </collision>
  </link>
  <joint
    name="left_shoulder_yaw_flange_fixture_joint"
    type="fixed">
    <origin
      xyz="0 0 0"
      rpy="0 0 0" />
    <parent
      link="left_shoulder_yaw_shaft" />
    <child
      link="left_shoulder_yaw_flange" />
    <axis
      xyz="0 0 0" />
  </joint>
  <link
    name="1220_m4x16_left_shoulder_yaw_screws">
    <inertial>
      <origin
        xyz="-2.81852874373101E-10 1.37418965096003E-11 -0.0114719356062276"
        rpy="0 0 0" />
      <mass
        value="0.0014103641869818" />
      <inertia
        ixx="3.71610598568609E-08"
        ixy="-3.34573878262386E-21"
        ixz="-3.74186542691842E-17"
        iyy="3.71610598568593E-08"
        iyz="-7.40170108439937E-17"
        izz="4.58636225470942E-09" />
    </inertial>
    <visual>
      <origin
        xyz="0 0 0"
        rpy="0 0 0" />
      <geometry>
        <mesh
          filename="package://humanoid_arm_5dof/meshes/1220_m4x16_left_shoulder_yaw_screws.STL" />
      </geometry>
      <material
        name="">
        <color
          rgba="0.792156862745098 0.819607843137255 0.933333333333333 1" />
      </material>
    </visual>
    <collision>
      <origin
        xyz="0 0 0"
        rpy="0 0 0" />
      <geometry>
        <mesh
          filename="package://humanoid_arm_5dof/meshes/1220_m4x16_left_shoulder_yaw_screws.STL" />
      </geometry>
    </collision>
  </link>
  <joint
    name="1220_m4x16_left_shoulder_yaw_screws_fixture_joint"
    type="fixed">
    <origin
      xyz="0 0 0"
      rpy="0 0 0" />
    <parent
      link="left_shoulder_yaw_flange" />
    <child
      link="1220_m4x16_left_shoulder_yaw_screws" />
    <axis
      xyz="0 0 0" />
  </joint>
  <link
    name="m4x25_left_shoulder_yaw_screws">
    <inertial>
      <origin
        xyz="-7.14075243379853E-10 -1.46624090646696E-09 -0.0144289836576852"
        rpy="0 0 0" />
      <mass
        value="0.00270858202481966" />
      <inertia
        ixx="2.20903769276245E-07"
        ixy="4.52767736253233E-13"
        ixz="-2.02342446045285E-15"
        iyy="2.2090429349599E-07"
        iyz="-4.21234135285762E-15"
        izz="9.25380471510245E-09" />
    </inertial>
    <visual>
      <origin
        xyz="0 0 0"
        rpy="0 0 0" />
      <geometry>
        <mesh
          filename="package://humanoid_arm_5dof/meshes/m4x25_left_shoulder_yaw_screws.STL" />
      </geometry>
      <material
        name="">
        <color
          rgba="0.792156862745098 0.819607843137255 0.933333333333333 1" />
      </material>
    </visual>
    <collision>
      <origin
        xyz="0 0 0"
        rpy="0 0 0" />
      <geometry>
        <mesh
          filename="package://humanoid_arm_5dof/meshes/m4x25_left_shoulder_yaw_screws.STL" />
      </geometry>
    </collision>
  </link>
  <joint
    name="m4x25_left_shoulder_yaw_screws_fixture_joint"
    type="fixed">
    <origin
      xyz="0 0 0"
      rpy="0 0 0" />
    <parent
      link="1220_m4x16_left_shoulder_yaw_screws" />
    <child
      link="m4x25_left_shoulder_yaw_screws" />
    <axis
      xyz="0 0 0" />
  </joint>
  <link
    name="left_shoulder_yaw">
    <inertial>
      <origin
        xyz="-0.0276085511800001 1.01191147727775E-06 -0.0766319307372525"
        rpy="0 0 0" />
      <mass
        value="0.488068654985182" />
      <inertia
        ixx="0.00146908224164198"
        ixy="2.07765537622168E-07"
        ixz="-0.0002712158976042"
        iyy="0.00131630379047452"
        iyz="6.91084280013616E-08"
        izz="0.000811624953253176" />
    </inertial>
    <visual>
      <origin
        xyz="0 0 0"
        rpy="0 0 0" />
      <geometry>
        <mesh
          filename="package://humanoid_arm_5dof/meshes/left_shoulder_yaw.STL" />
      </geometry>
      <material
        name="">
        <color
          rgba="0.952941176470588 0.996078431372549 0.694117647058824 1" />
      </material>
    </visual>
    <collision>
      <origin
        xyz="0 0 0"
        rpy="0 0 0" />
      <geometry>
        <mesh
          filename="package://humanoid_arm_5dof/meshes/left_shoulder_yaw.STL" />
      </geometry>
    </collision>
  </link>
  <joint
    name="left_shoulder_yaw_fixture_joint"
    type="fixed">
    <origin
      xyz="0 0 0"
      rpy="0 0 0" />
    <parent
      link="m4x25_left_shoulder_yaw_screws" />
    <child
      link="left_shoulder_yaw" />
    <axis
      xyz="0 0 0" />
  </joint>
  <link
    name="m4x16_eft_elbow_screws">
    <inertial>
      <origin
        xyz="0.0203953561620978 0.0412900580937556 9.08278563471754E-10"
        rpy="0 0 0" />
      <mass
        value="0.00270184358647752" />
      <inertia
        ixx="8.53078780998125E-08"
        ixy="-3.69467570072025E-08"
        ixz="-1.81084961912539E-15"
        iyy="2.8759756336897E-08"
        iyz="-3.58607420046829E-15"
        izz="1.03557847634921E-07" />
    </inertial>
    <visual>
      <origin
        xyz="0 0 0"
        rpy="0 0 0" />
      <geometry>
        <mesh
          filename="package://humanoid_arm_5dof/meshes/m4x16_eft_elbow_screws.STL" />
      </geometry>
      <material
        name="">
        <color
          rgba="0.792156862745098 0.819607843137255 0.933333333333333 1" />
      </material>
    </visual>
    <collision>
      <origin
        xyz="0 0 0"
        rpy="0 0 0" />
      <geometry>
        <mesh
          filename="package://humanoid_arm_5dof/meshes/m4x16_eft_elbow_screws.STL" />
      </geometry>
    </collision>
  </link>
  <joint
    name="m4x16_eft_elbow_screws_fixture_joint"
    type="fixed">
    <origin
      xyz="0 0 -0.0987000004167595"
      rpy="0 0 2.02959481544726" />
    <parent
      link="left_shoulder_yaw" />
    <child
      link="m4x16_eft_elbow_screws" />
    <axis
      xyz="0 0 0" />
  </joint>
  <link
    name="left_elbow_rs03_actuator">
    <inertial>
      <origin
        xyz="0.0111097812067071 0.022489732261155 -0.000302908478301722"
        rpy="0 0 0" />
      <mass
        value="0.35655089089686" />
      <inertia
        ixx="0.000296217970952692"
        ixy="4.22025243355313E-05"
        ixz="-2.44834218567739E-07"
        iyy="0.000360818228627732"
        iyz="-5.20600164179532E-07"
        izz="0.000270239476177012" />
    </inertial>
    <visual>
      <origin
        xyz="0 0 0"
        rpy="0 0 0" />
      <geometry>
        <mesh
          filename="package://humanoid_arm_5dof/meshes/left_elbow_rs03_actuator.STL" />
      </geometry>
      <material
        name="">
        <color
          rgba="0.823529411764706 0.823529411764706 1 1" />
      </material>
    </visual>
    <collision>
      <origin
        xyz="0 0 0"
        rpy="0 0 0" />
      <geometry>
        <mesh
          filename="package://humanoid_arm_5dof/meshes/left_elbow_rs03_actuator.STL" />
      </geometry>
    </collision>
  </link>
  <joint
    name="left_elbow_rs03_actuator_ficture_link"
    type="fixed">
    <origin
      xyz="0 0 0"
      rpy="0 0 0" />
    <parent
      link="m4x16_eft_elbow_screws" />
    <child
      link="left_elbow_rs03_actuator" />
    <axis
      xyz="0 0 0" />
  </joint>
  <link
    name="left_elbow_rs03_flange">
    <inertial>
      <origin
        xyz="-0.000556362193148363 -0.00112634311572446 -1.66571867410426E-10"
        rpy="0 0 0" />
      <mass
        value="0.00407555097398885" />
      <inertia
        ixx="6.7819170155555E-07"
        ixy="2.23735674477819E-07"
        ixz="2.60474555916408E-16"
        iyy="1.02062586835636E-06"
        iyz="5.27326436127583E-16"
        izz="5.67676746163446E-07" />
    </inertial>
    <visual>
      <origin
        xyz="0 0 0"
        rpy="0 0 0" />
      <geometry>
        <mesh
          filename="package://humanoid_arm_5dof/meshes/left_elbow_rs03_flange.STL" />
      </geometry>
      <material
        name="">
        <color
          rgba="0.823529411764706 0.823529411764706 1 1" />
      </material>
    </visual>
    <collision>
      <origin
        xyz="0 0 0"
        rpy="0 0 0" />
      <geometry>
        <mesh
          filename="package://humanoid_arm_5dof/meshes/left_elbow_rs03_flange.STL" />
      </geometry>
    </collision>
  </link>
  <joint
    name="left_elbow_rs03_joint"
    type="revolute">
    <origin
      xyz="0 0 0"
      rpy="0 0 0" />
    <parent
      link="left_elbow_rs03_actuator" />
    <child
      link="left_elbow_rs03_flange" />
    <axis
      xyz="0.442871169532447 0.896585259301625 0" />
    <limit
      lower="-1.3"
      upper="1.9"
      effort="60"
      velocity="1.6" />
    <safety_controller
      soft_upper_limit="3.14"
      soft_lower_limit="-3.14"
      k_velocity="0" />
  </joint>
  <link
    name="left_elbow_shaft">
    <inertial>
      <origin
        xyz="-0.514023069140735 0.0789116755168446 -0.294612658289237"
        rpy="0 0 0" />
      <mass
        value="16.3859228521728" />
      <inertia
        ixx="4.1673871202224"
        ixy="0.924028147321054"
        ixz="-3.13052394045389"
        iyy="7.10700853734092"
        iyz="1.12422208277889"
        izz="3.92149051316227" />
    </inertial>
    <visual>
      <origin
        xyz="0 0 0"
        rpy="0 0 0" />
      <geometry>
        <mesh
          filename="package://humanoid_arm_5dof/meshes/left_elbow_shaft.STL" />
      </geometry>
      <material
        name="">
        <color
          rgba="0.752941176470588 0.752941176470588 0.752941176470588 1" />
      </material>
    </visual>
    <collision>
      <origin
        xyz="0 0 0"
        rpy="0 0 0" />
      <geometry>
        <mesh
          filename="package://humanoid_arm_5dof/meshes/left_elbow_shaft.STL" />
      </geometry>
    </collision>
  </link>
  <joint
    name="left_elbow_shaft_fixture_joint"
    type="fixed">
    <origin
      xyz="0 0 0"
      rpy="0 0 0" />
    <parent
      link="left_elbow_rs03_flange" />
    <child
      link="left_elbow_shaft" />
    <axis
      xyz="0 0 0" />
  </joint>
  <link
    name="m4x25_left_elbow_screws">
    <inertial>
      <origin
        xyz="-0.00623517634432247 -0.0126230081894332 -1.57502966224854E-09"
        rpy="0 0 0" />
      <mass
        value="0.00270858033444496" />
      <inertia
        ixx="1.79392020952072E-07"
        ixy="-8.40403333155854E-08"
        ixz="-2.22145094796311E-15"
        iyy="5.0765769574879E-08"
        iyz="-4.80384087242943E-15"
        izz="2.20904014947486E-07" />
    </inertial>
    <visual>
      <origin
        xyz="0 0 0"
        rpy="0 0 0" />
      <geometry>
        <mesh
          filename="package://humanoid_arm_5dof/meshes/m4x25_left_elbow_screws.STL" />
      </geometry>
      <material
        name="">
        <color
          rgba="0.792156862745098 0.819607843137255 0.933333333333333 1" />
      </material>
    </visual>
    <collision>
      <origin
        xyz="0 0 0"
        rpy="0 0 0" />
      <geometry>
        <mesh
          filename="package://humanoid_arm_5dof/meshes/m4x25_left_elbow_screws.STL" />
      </geometry>
    </collision>
  </link>
  <joint
    name="m4x25_left_elbow_screws_fixture_joint"
    type="fixed">
    <origin
      xyz="0 0 0"
      rpy="0 0 0" />
    <parent
      link="left_elbow_shaft" />
    <child
      link="m4x25_left_elbow_screws" />
    <axis
      xyz="0 0 0" />
  </joint>
  <link
    name="left_elbow">
    <inertial>
      <origin
        xyz="-0.00117659887327504 -0.0226416994032843 -0.0323595586651757"
        rpy="0 0 0" />
      <mass
        value="0.779765455632657" />
      <inertia
        ixx="0.00250248627290095"
        ixy="0.000107026109490901"
        ixz="0.000573101025966973"
        iyy="0.0029164827029391"
        iyz="0.000125954185253177"
        izz="0.000972784435246921" />
    </inertial>
    <visual>
      <origin
        xyz="0 0 0"
        rpy="0 0 0" />
      <geometry>
        <mesh
          filename="package://humanoid_arm_5dof/meshes/left_elbow.STL" />
      </geometry>
      <material
        name="">
        <color
          rgba="0.952941176470588 0.996078431372549 0.694117647058824 1" />
      </material>
    </visual>
    <collision>
      <origin
        xyz="0 0 0"
        rpy="0 0 0" />
      <geometry>
        <mesh
          filename="package://humanoid_arm_5dof/meshes/left_elbow.STL" />
      </geometry>
    </collision>
  </link>
  <joint
    name="left_elbow_fixture_joint"
    type="fixed">
    <origin
      xyz="0 0 0"
      rpy="0 0 0" />
    <parent
      link="m4x25_left_elbow_screws" />
    <child
      link="left_elbow" />
    <axis
      xyz="0 0 0" />
  </joint>
  <link
    name="m3x20_left_wrist_screws">
    <inertial>
      <origin
        xyz="-0.00322617497203437 -0.0374854487546337 0.00322633891040525"
        rpy="0 0 0" />
      <mass
        value="0.00162137028637936" />
      <inertia
        ixx="8.36724015923329E-08"
        ixy="7.16921388671075E-16"
        ixz="-1.09755048245885E-14"
        iyy="3.32920091139157E-09"
        iyz="-1.16692689852525E-13"
        izz="8.36724115121392E-08" />
    </inertial>
    <visual>
      <origin
        xyz="0 0 0"
        rpy="0 0 0" />
      <geometry>
        <mesh
          filename="package://humanoid_arm_5dof/meshes/m3x20_left_wrist_screws.STL" />
      </geometry>
      <material
        name="">
        <color
          rgba="0.792156862745098 0.819607843137255 0.933333333333333 1" />
      </material>
    </visual>
    <collision>
      <origin
        xyz="0 0 0"
        rpy="0 0 0" />
      <geometry>
        <mesh
          filename="package://humanoid_arm_5dof/meshes/m3x20_left_wrist_screws.STL" />
      </geometry>
    </collision>
  </link>
  <joint
    name="m3x20_left_wrist_screws_fixture_joint"
    type="fixed">
    <origin
      xyz="0.0370688771049235 -0.0244446769789257 -0.15848929336033"
      rpy="-1.29963611177836 0 -2.02959481544726" />
    <parent
      link="left_elbow" />
    <child
      link="m3x20_left_wrist_screws" />
    <axis
      xyz="0 0 0" />
  </joint>
  <link
    name="left_wrist_actuator">
    <inertial>
      <origin
        xyz="-4.13003742316675E-10 -0.0230138334560079 1.84853627072101E-07"
        rpy="0 0 0" />
      <mass
        value="0.180583065420556" />
      <inertia
        ixx="8.80899821792287E-05"
        ixy="-3.82899833496449E-14"
        ixz="-1.46960216348621E-19"
        iyy="0.000127000739066128"
        iyz="5.64597535051919E-11"
        izz="8.80899821793108E-05" />
    </inertial>
    <visual>
      <origin
        xyz="0 0 0"
        rpy="0 0 0" />
      <geometry>
        <mesh
          filename="package://humanoid_arm_5dof/meshes/left_wrist_actuator.STL" />
      </geometry>
      <material
        name="">
        <color
          rgba="0.823529411764706 0.823529411764706 1 1" />
      </material>
    </visual>
    <collision>
      <origin
        xyz="0 0 0"
        rpy="0 0 0" />
      <geometry>
        <mesh
          filename="package://humanoid_arm_5dof/meshes/left_wrist_actuator.STL" />
      </geometry>
    </collision>
  </link>
  <joint
    name="left_wrist_actuator_fixture_link"
    type="fixed">
    <origin
      xyz="0 0 0"
      rpy="0 0 0" />
    <parent
      link="m3x20_left_wrist_screws" />
    <child
      link="left_wrist_actuator" />
    <axis
      xyz="0 0 0" />
  </joint>
  <link
    name="left_wrist_rs02_flange">
    <inertial>
      <origin
        xyz="-4.82471951279706E-10 -0.00198993498129152 2.15794503155564E-07"
        rpy="0 0 0" />
      <mass
        value="0.00245793392108136" />
      <inertia
        ixx="1.34950766910331E-07"
        ixy="-1.2632138736079E-16"
        ixz="-5.00444270594582E-22"
        iyy="2.63403217776607E-07"
        iyz="1.8638535856553E-13"
        izz="1.34950766910602E-07" />
    </inertial>
    <visual>
      <origin
        xyz="0 0 0"
        rpy="0 0 0" />
      <geometry>
        <mesh
          filename="package://humanoid_arm_5dof/meshes/left_wrist_rs02_flange.STL" />
      </geometry>
      <material
        name="">
        <color
          rgba="0.823529411764706 0.823529411764706 1 1" />
      </material>
    </visual>
    <collision>
      <origin
        xyz="0 0 0"
        rpy="0 0 0" />
      <geometry>
        <mesh
          filename="package://humanoid_arm_5dof/meshes/left_wrist_rs02_flange.STL" />
      </geometry>
    </collision>
  </link>
  <joint
    name="left_wrist_rs02_joint"
    type="revolute">
    <origin
      xyz="0 0 0"
      rpy="0 0 0" />
    <parent
      link="left_wrist_actuator" />
    <child
      link="left_wrist_rs02_flange" />
    <axis
      xyz="0 1 0" />
    <limit
      lower="-3.14"
      upper="3.14"
      effort="17"
      velocity="0.8" />
    <safety_controller
      soft_upper_limit="3.14"
      soft_lower_limit="-3.14"
      k_velocity="0" />
  </joint>
  <link
    name="m4x20_left_wrist_screws">
    <inertial>
      <origin
        xyz="3.318480701342E-08 0.00840266502725395 2.522636832758E-07"
        rpy="0 0 0" />
      <mass
        value="0.00232797016313296" />
      <inertia
        ixx="1.29587507987155E-07"
        ixy="-3.32247975473364E-13"
        ixz="3.13118102496286E-13"
        iyy="8.48546817357487E-09"
        iyz="-3.85647119718327E-13"
        izz="1.295872206399E-07" />
    </inertial>
    <visual>
      <origin
        xyz="0 0 0"
        rpy="0 0 0" />
      <geometry>
        <mesh
          filename="package://humanoid_arm_5dof/meshes/m4x20_left_wrist_screws.STL" />
      </geometry>
      <material
        name="">
        <color
          rgba="0.792156862745098 0.819607843137255 0.933333333333333 1" />
      </material>
    </visual>
    <collision>
      <origin
        xyz="0 0 0"
        rpy="0 0 0" />
      <geometry>
        <mesh
          filename="package://humanoid_arm_5dof/meshes/m4x20_left_wrist_screws.STL" />
      </geometry>
    </collision>
  </link>
  <joint
    name="m4x20_left_wrist_screws_fixture_joint"
    type="fixed">
    <origin
      xyz="0 0 0"
      rpy="0 0 0" />
    <parent
      link="left_wrist_rs02_flange" />
    <child
      link="m4x20_left_wrist_screws" />
    <axis
      xyz="0 0 0" />
  </joint>
  <link
    name="left_wrist_shaft">
    <inertial>
      <origin
        xyz="-4.92402230101163E-10 0.00798511240994593 2.30268373258014E-07"
        rpy="0 0 0" />
      <mass
        value="0.000903649674374024" />
      <inertia
        ixx="4.41715688076261E-08"
        ixy="4.16630927954905E-17"
        ixz="5.75924501490046E-23"
        iyy="1.80539813304875E-09"
        iyz="-6.14735948000537E-14"
        izz="4.41715688075369E-08" />
    </inertial>
    <visual>
      <origin
        xyz="0 0 0"
        rpy="0 0 0" />
      <geometry>
        <mesh
          filename="package://humanoid_arm_5dof/meshes/left_wrist_shaft.STL" />
      </geometry>
      <material
        name="">
        <color
          rgba="0.823529411764706 0.823529411764706 1 1" />
      </material>
    </visual>
    <collision>
      <origin
        xyz="0 0 0"
        rpy="0 0 0" />
      <geometry>
        <mesh
          filename="package://humanoid_arm_5dof/meshes/left_wrist_shaft.STL" />
      </geometry>
    </collision>
  </link>
  <joint
    name="left_wrist_shaft_fixture_joint"
    type="fixed">
    <origin
      xyz="0 0 0"
      rpy="0 0 0" />
    <parent
      link="m4x20_left_wrist_screws" />
    <child
      link="left_wrist_shaft" />
    <axis
      xyz="0 0 0" />
  </joint>
  <link
    name="left_wrist">
    <inertial>
      <origin
        xyz="-0.0126284320374921 0.0418086804500857 0.00594051710051513"
        rpy="0 0 0" />
      <mass
        value="0.38895090516656" />
      <inertia
        ixx="0.000833659232870932"
        ixy="0.000191177317797681"
        ixz="2.04628372102838E-06"
        iyy="0.000517833926370932"
        iyz="-8.95573646182272E-05"
        izz="0.000838969451703103" />
    </inertial>
    <visual>
      <origin
        xyz="0 0 0"
        rpy="0 0 0" />
      <geometry>
        <mesh
          filename="package://humanoid_arm_5dof/meshes/left_wrist.STL" />
      </geometry>
      <material
        name="">
        <color
          rgba="0.952941176470588 0.996078431372549 0.694117647058824 1" />
      </material>
    </visual>
    <collision>
      <origin
        xyz="0 0 0"
        rpy="0 0 0" />
      <geometry>
        <mesh
          filename="package://humanoid_arm_5dof/meshes/left_wrist.STL" />
      </geometry>
    </collision>
  </link>
  <joint
    name="left_wrist_fixture_joint"
    type="fixed">
    <origin
      xyz="0 0 0"
      rpy="0 0 0" />
    <parent
      link="left_wrist_shaft" />
    <child
      link="left_wrist" />
    <axis
      xyz="0 0 0" />
  </joint>
  <link
    name="m3x16_left_hand_screws">
    <inertial>
      <origin
        xyz="-0.0363345852832491 0.00271819509271642 0.00366478140739768"
        rpy="0 0 0" />
      <mass
        value="0.0013937417473266" />
      <inertia
        ixx="3.07153113593302E-09"
        ixy="-6.5417488854761E-15"
        ixz="-1.5862504728051E-14"
        iyy="4.88927935104843E-08"
        iyz="1.38689171238355E-16"
        izz="4.88928835911864E-08" />
    </inertial>
    <visual>
      <origin
        xyz="0 0 0"
        rpy="0 0 0" />
      <geometry>
        <mesh
          filename="package://humanoid_arm_5dof/meshes/m3x16_left_hand_screws.STL" />
      </geometry>
      <material
        name="">
        <color
          rgba="0.792156862745098 0.819607843137255 0.933333333333333 1" />
      </material>
    </visual>
    <collision>
      <origin
        xyz="0 0 0"
        rpy="0 0 0" />
      <geometry>
        <mesh
          filename="package://humanoid_arm_5dof/meshes/m3x16_left_hand_screws.STL" />
      </geometry>
    </collision>
  </link>
  <joint
    name="m3x16_left_hand_screws_fixture_joint"
    type="fixed">
    <origin
      xyz="0 0.0944999999998815 0"
      rpy="0.644848119833412 0.444064009162365 0" />
    <parent
      link="left_wrist" />
    <child
      link="m3x16_left_hand_screws" />
    <axis
      xyz="0 0 0" />
  </joint>
  <link
    name="left_hand_rs02">
    <inertial>
      <origin
        xyz="-0.0230139815130013 1.75887512554596E-07 2.56052493208259E-07"
        rpy="0 0 0" />
      <mass
        value="0.180583065420555" />
      <inertia
        ixx="0.000127000739066197"
        ixy="1.77900201711936E-11"
        ixz="-1.33876787626152E-11"
        iyy="8.80899821792351E-05"
        iyz="-5.95017248351714E-18"
        izz="8.80899821792316E-05" />
    </inertial>
    <visual>
      <origin
        xyz="0 0 0"
        rpy="0 0 0" />
      <geometry>
        <mesh
          filename="package://humanoid_arm_5dof/meshes/left_hand_rs02.STL" />
      </geometry>
      <material
        name="">
        <color
          rgba="0.823529411764706 0.823529411764706 1 1" />
      </material>
    </visual>
    <collision>
      <origin
        xyz="0 0 0"
        rpy="0 0 0" />
      <geometry>
        <mesh
          filename="package://humanoid_arm_5dof/meshes/left_hand_rs02.STL" />
      </geometry>
    </collision>
  </link>
  <joint
    name="left_hand_rs02_fixture_link"
    type="fixed">
    <origin
      xyz="0 0 0"
      rpy="0 0 0" />
    <parent
      link="m3x16_left_hand_screws" />
    <child
      link="left_hand_rs02" />
    <axis
      xyz="0 0 0" />
  </joint>
  <link
    name="left_hand_rs02_flange">
    <inertial>
      <origin
        xyz="-0.00201021341743707 1.85490444337688E-07 2.48825936743913E-07"
        rpy="0 0 0" />
      <mass
        value="0.00245793392108137" />
      <inertia
        ixx="2.63403217776839E-07"
        ixy="5.87286095370486E-14"
        ixz="-4.41955456994307E-14"
        iyy="1.34950766910359E-07"
        iyz="-2.04664433837912E-20"
        izz="1.34950766910349E-07" />
    </inertial>
    <visual>
      <origin
        xyz="0 0 0"
        rpy="0 0 0" />
      <geometry>
        <mesh
          filename="package://humanoid_arm_5dof/meshes/left_hand_rs02_flange.STL" />
      </geometry>
      <material
        name="">
        <color
          rgba="0.823529411764706 0.823529411764706 1 1" />
      </material>
    </visual>
    <collision>
      <origin
        xyz="0 0 0"
        rpy="0 0 0" />
      <geometry>
        <mesh
          filename="package://humanoid_arm_5dof/meshes/left_hand_rs02_flange.STL" />
      </geometry>
    </collision>
  </link>
  <joint
    name="left_hand_rs02_joint"
    type="revolute">
    <origin
      xyz="0 0 0"
      rpy="0 0 0" />
    <parent
      link="left_hand_rs02" />
    <child
      link="left_hand_rs02_flange" />
    <axis
      xyz="0.999999999999999 0 0" />
    <limit
      lower="-1.5"
      upper="1.7"
      effort="17"
      velocity="0.8" />
    <safety_controller
      soft_upper_limit="1.7"
      soft_lower_limit="-1.5"
      k_velocity="0" />
  </joint>
  <link
    name="left_hand">
    <inertial>
      <origin
        xyz="0.0119773488613211 0.0114767033189933 -0.0111414954392139"
        rpy="0 0 0" />
      <mass
        value="0.285530357048999" />
      <inertia
        ixx="0.000354627591386541"
        ixy="1.61688666535748E-05"
        ixz="-1.60212250645352E-05"
        iyy="0.000247513435753137"
        iyz="3.07039739705686E-05"
        izz="0.000247329282032819" />
    </inertial>
    <visual>
      <origin
        xyz="0 0 0"
        rpy="0 0 0" />
      <geometry>
        <mesh
          filename="package://humanoid_arm_5dof/meshes/left_hand.STL" />
      </geometry>
      <material
        name="">
        <color
          rgba="0.952941176470588 0.996078431372549 0.694117647058824 1" />
      </material>
    </visual>
    <collision>
      <origin
        xyz="0 0 0"
        rpy="0 0 0" />
      <geometry>
        <mesh
          filename="package://humanoid_arm_5dof/meshes/left_hand.STL" />
      </geometry>
    </collision>
  </link>
  <joint
    name="left_hand_fixture_joint"
    type="fixed">
    <origin
      xyz="0 0 0"
      rpy="0 0 0" />
    <parent
      link="left_hand_rs02_flange" />
    <child
      link="left_hand" />
    <axis
      xyz="0 0 0" />
  </joint>
</robot>