<?xml version="1.0" encoding="utf-8"?>
<!-- This URDF was automatically created by SolidWorks to URDF Exporter! Originally created by Stephen Brawner (brawner@gmail.com) 
     Commit Version: 1.6.0-4-g7f85cfe  Build Version: 1.6.7995.38578
     For more information, please see http://wiki.ros.org/sw_urdf_exporter -->
<robot
  name="humanoid_arm_5dof">
  <link
    name="base_fixture_link">
    <inertial>
      <origin
        xyz="-0.30933 -0.17963 -0.83636"
        rpy="0 0 0" />
      <mass
        value="400" />
      <inertia
        ixx="1.5338"
        ixy="-0.024766"
        ixz="-0.16927"
        iyy="1.5621"
        iyz="-0.098299"
        izz="0.18464" />
    </inertial>
    <visual>
      <origin
        xyz="0 0 0"
        rpy="0 0 0" />
      <geometry>
        <mesh
          filename="package://humanoid_arm_5dof/meshes/base_fixture_link.STL" />
      </geometry>
      <material
        name="">
        <color
          rgba="0.82353 0.82353 1 1" />
      </material>
    </visual>
    <collision>
      <origin
        xyz="0 0 0"
        rpy="0 0 0" />
      <geometry>
        <mesh
          filename="package://humanoid_arm_5dof/meshes/base_fixture_link.STL" />
      </geometry>
    </collision>
  </link>
  <link
    name="left_shoulder_pitch_rs04_actuator">
    <inertial>
      <origin
        xyz="-0.0212144936357581 -0.0123197061496136 -1.4773737788687E-12"
        rpy="0 0 0" />
      <mass
        value="0.517423577893353" />
      <inertia
        ixx="0.000791281929906339"
        ixy="0.000146596403770864"
        ixz="1.04334286421386E-06"
        iyy="0.000623975041966309"
        iyz="-1.79663299480507E-06"
        izz="0.000544725741611065" />
    </inertial>
    <visual>
      <origin
        xyz="0 0 0"
        rpy="0 0 0" />
      <geometry>
        <mesh
          filename="package://humanoid_arm_5dof/meshes/left_shoulder_pitch_rs04_actuator.STL" />
      </geometry>
      <material
        name="">
        <color
          rgba="0.823529411764706 0.823529411764706 1 1" />
      </material>
    </visual>
    <collision>
      <origin
        xyz="0 0 0"
        rpy="0 0 0" />
      <geometry>
        <mesh
          filename="package://humanoid_arm_5dof/meshes/left_shoulder_pitch_rs04_actuator.STL" />
      </geometry>
    </collision>
  </link>
  <joint
    name="left_shoulder_pitch_rs04_actuator_fixture_link"
    type="fixed">
    <origin
      xyz="0 0 0"
      rpy="0 0 0" />
    <parent
      link="base_fixture_link" />
    <child
      link="left_shoulder_pitch_rs04_actuator" />
    <axis
      xyz="0 0 0" />
  </joint>
  <link
    name="left_shoulder_pitch_rs04_flange">
    <inertial>
      <origin
        xyz="-0.00160023400777121 -0.00100669949731191 7.2930713943431E-05"
        rpy="0 0 0" />
      <mass
        value="0.0075835212224452" />
      <inertia
        ixx="2.06768924459392E-06"
        ixy="5.07332578299143E-07"
        ixz="-2.22346148654254E-21"
        iyy="1.48868298903537E-06"
        iyz="-1.83634095986772E-22"
        izz="1.19406420659588E-06" />
    </inertial>
    <visual>
      <origin
        xyz="0 0 0"
        rpy="0 0 0" />
      <geometry>
        <mesh
          filename="package://humanoid_arm_5dof/meshes/left_shoulder_pitch_rs04_flange.STL" />
      </geometry>
      <material
        name="">
        <color
          rgba="0.823529411764706 0.823529411764706 1 1" />
      </material>
    </visual>
    <collision>
      <origin
        xyz="0 0 0"
        rpy="0 0 0" />
      <geometry>
        <mesh
          filename="package://humanoid_arm_5dof/meshes/left_shoulder_pitch_rs04_flange.STL" />
      </geometry>
    </collision>
  </link>
  <joint
    name="left_shoulder_pitch_rs04_flange_joint"
    type="revolute">
    <origin
      xyz="0 0 0"
      rpy="0 0 0" />
    <parent
      link="left_shoulder_pitch_rs04_actuator" />
    <child
      link="left_shoulder_pitch_rs04_flange" />
    <axis
      xyz="0.86476 0.50218 0" />
    <limit
      lower="-3.14"
      upper="3.14"
      effort="120"
      velocity="3" />
    <safety_controller
      soft_upper_limit="3.14"
      soft_lower_limit="-3.14"
      k_velocity="0" />
  </joint>
  <link
    name="m5x22_screws_left_shoulder_pitch">
    <inertial>
      <origin
        xyz="0.00721932653764679 0.000299723765854409 0.00365316139821603"
        rpy="0 0 0" />
      <mass
        value="0.00474644340626596" />
      <inertia
        ixx="1.03394680133488E-07"
        ixy="-1.32206926832098E-07"
        ixz="-2.76565465282709E-13"
        iyy="2.54278723556565E-07"
        iyz="2.77265718526758E-13"
        izz="3.31054378599872E-07" />
    </inertial>
    <visual>
      <origin
        xyz="0 0 0"
        rpy="0 0 0" />
      <geometry>
        <mesh
          filename="package://humanoid_arm_5dof/meshes/m5x22_screws_left_shoulder_pitch.STL" />
      </geometry>
      <material
        name="">
        <color
          rgba="0.792156862745098 0.819607843137255 0.933333333333333 1" />
      </material>
    </visual>
    <collision>
      <origin
        xyz="0 0 0"
        rpy="0 0 0" />
      <geometry>
        <mesh
          filename="package://humanoid_arm_5dof/meshes/m5x22_screws_left_shoulder_pitch.STL" />
      </geometry>
    </collision>
  </link>
  <joint
    name="m5x22_screws_left_shoulder_pitch_fixture_joint"
    type="fixed">
    <origin
      xyz="0 0 0"
      rpy="0 0 0" />
    <parent
      link="left_shoulder_pitch_rs04_flange" />
    <child
      link="m5x22_screws_left_shoulder_pitch" />
    <axis
      xyz="0 0 0" />
  </joint>
  <link
    name="left_shoulder_pitch">
    <inertial>
      <origin
        xyz="0.042237918471645 0.0631675726694163 -0.0211624696602386"
        rpy="0 0 0" />
      <mass
        value="1.1977209978155" />
      <inertia
        ixx="0.00533841544672593"
        ixy="-0.00181737265213414"
        ixz="0.000735956230617811"
        iyy="0.00421467724737193"
        iyz="0.000482895977554852"
        izz="0.00612223849875834" />
    </inertial>
    <visual>
      <origin
        xyz="0 0 0"
        rpy="0 0 0" />
      <geometry>
        <mesh
          filename="package://humanoid_arm_5dof/meshes/left_shoulder_pitch.STL" />
      </geometry>
      <material
        name="">
        <color
          rgba="0.952941176470588 0.996078431372549 0.694117647058824 1" />
      </material>
    </visual>
    <collision>
      <origin
        xyz="0 0 0"
        rpy="0 0 0" />
      <geometry>
        <mesh
          filename="package://humanoid_arm_5dof/meshes/left_shoulder_pitch.STL" />
      </geometry>
    </collision>
  </link>
  <joint
    name="left_shoulder_pitch_fixture_joint"
    type="fixed">
    <origin
      xyz="0 0 0"
      rpy="0 0 0" />
    <parent
      link="m5x22_screws_left_shoulder_pitch" />
    <child
      link="left_shoulder_pitch" />
    <axis
      xyz="0 0 0" />
  </joint>
  <link
    name="m5x22_screws_left_shoulder_roll">
    <inertial>
      <origin
        xyz="5.12752764362245E-05 -0.012893504504802 5.12072510493455E-05"
        rpy="0 0 0" />
      <mass
        value="0.00610257053905779" />
      <inertia
        ixx="4.25641380807015E-07"
        ixy="1.38655679161881E-13"
        ixz="-4.65295401747074E-13"
        iyy="3.42246799589699E-08"
        iyz="-2.62969045463303E-13"
        izz="4.25641102603532E-07" />
    </inertial>
    <visual>
      <origin
        xyz="0 0 0"
        rpy="0 0 0" />
      <geometry>
        <mesh
          filename="package://humanoid_arm_5dof/meshes/m5x22_screws_left_shoulder_roll.STL" />
      </geometry>
      <material
        name="">
        <color
          rgba="0.792156862745098 0.819607843137255 0.933333333333333 1" />
      </material>
    </visual>
    <collision>
      <origin
        xyz="0 0 0"
        rpy="0 0 0" />
      <geometry>
        <mesh
          filename="package://humanoid_arm_5dof/meshes/m5x22_screws_left_shoulder_roll.STL" />
      </geometry>
    </collision>
  </link>
  <joint
    name="m5x22_screws_left_shoulder_roll_fixture_joint"
    type="fixed">
    <origin
      xyz="0.080327 0.094212 -0.026075"
      rpy="0.56445 0 -2.6155" />
    <parent
      link="left_shoulder_pitch" />
    <child
      link="m5x22_screws_left_shoulder_roll" />
    <axis
      xyz="0 0 0" />
  </joint>
  <link
    name="left_shoulder_roll_rs04_flange">
    <inertial>
      <origin
        xyz="-1.34336985979644E-14 -0.00211063193642946 7.46815942420653E-11"
        rpy="0 0 0" />
      <mass
        value="0.00758352122244519" />
      <inertia
        ixx="1.19406420659585E-06"
        ixy="-4.0432588341592E-21"
        ixz="-3.32195734001296E-21"
        iyy="2.3623080270334E-06"
        iyz="-1.7320961385931E-15"
        izz="1.19406420659586E-06" />
    </inertial>
    <visual>
      <origin
        xyz="0 0 0"
        rpy="0 0 0" />
      <geometry>
        <mesh
          filename="package://humanoid_arm_5dof/meshes/left_shoulder_roll_rs04_flange.STL" />
      </geometry>
      <material
        name="">
        <color
          rgba="0.823529411764706 0.823529411764706 1 1" />
      </material>
    </visual>
    <collision>
      <origin
        xyz="0 0 0"
        rpy="0 0 0" />
      <geometry>
        <mesh
          filename="package://humanoid_arm_5dof/meshes/left_shoulder_roll_rs04_flange.STL" />
      </geometry>
    </collision>
  </link>
  <joint
    name="left_shoulder_roll_rs04_flange_joint"
    type="fixed">
    <origin
      xyz="0 0 0"
      rpy="0 0 0" />
    <parent
      link="m5x22_screws_left_shoulder_roll" />
    <child
      link="left_shoulder_roll_rs04_flange" />
    <axis
      xyz="0 0 0" />
  </joint>
  <link
    name="left_shoulder_roll_rs04_actuator">
    <inertial>
      <origin
        xyz="7.5431275802007E-05 0.0205322216645345 2.70558479296135E-05"
        rpy="0 0 0" />
      <mass
        value="0.517423577893356" />
      <inertia
        ixx="0.000542006962748034"
        ixy="-5.36027182384581E-15"
        ixz="-3.59408880621033E-06"
        iyy="0.000876413569064536"
        iyz="-4.9662097351133E-13"
        izz="0.000541562181671229" />
    </inertial>
    <visual>
      <origin
        xyz="0 0 0"
        rpy="0 0 0" />
      <geometry>
        <mesh
          filename="package://humanoid_arm_5dof/meshes/left_shoulder_roll_rs04_actuator.STL" />
      </geometry>
      <material
        name="">
        <color
          rgba="0.823529411764706 0.823529411764706 1 1" />
      </material>
    </visual>
    <collision>
      <origin
        xyz="0 0 0"
        rpy="0 0 0" />
      <geometry>
        <mesh
          filename="package://humanoid_arm_5dof/meshes/left_shoulder_roll_rs04_actuator.STL" />
      </geometry>
    </collision>
  </link>
  <joint
    name="left_shoulder_roll_rs04_actuator_fixture_link"
    type="revolute">
    <origin
      xyz="0 0 0"
      rpy="0 0 0" />
    <parent
      link="left_shoulder_roll_rs04_flange" />
    <child
      link="left_shoulder_roll_rs04_actuator" />
    <axis
      xyz="0 -1 0" />
    <limit
      lower="-3.5"
      upper="0.6"
      effort="120"
      velocity="3" />
    <safety_controller
      soft_upper_limit="3.14"
      soft_lower_limit="-3.14"
      k_velocity="0" />
  </joint>
  <link
    name="m4x25_left_shoulder_screws_roll">
    <inertial>
      <origin
        xyz="5.45041063216845E-05 0.0496289837028829 5.40653512253186E-05"
        rpy="0 0 0" />
      <mass
        value="0.00451430348886326" />
      <inertia
        ixx="3.68173387240362E-07"
        ixy="-6.77491830959558E-15"
        ixz="6.50698981886879E-17"
        iyy="1.54230097659281E-08"
        iyz="3.60255028003978E-17"
        izz="3.68173386339825E-07" />
    </inertial>
    <visual>
      <origin
        xyz="0 0 0"
        rpy="0 0 0" />
      <geometry>
        <mesh
          filename="package://humanoid_arm_5dof/meshes/m4x25_left_shoulder_screws_roll.STL" />
      </geometry>
      <material
        name="">
        <color
          rgba="0.792156862745098 0.819607843137255 0.933333333333333 1" />
      </material>
    </visual>
    <collision>
      <origin
        xyz="0 0 0"
        rpy="0 0 0" />
      <geometry>
        <mesh
          filename="package://humanoid_arm_5dof/meshes/m4x25_left_shoulder_screws_roll.STL" />
      </geometry>
    </collision>
  </link>
  <joint
    name="m4x25_left_shoulder_screws_roll_fixture_joint"
    type="fixed">
    <origin
      xyz="0 0 0"
      rpy="0 0 0" />
    <parent
      link="left_shoulder_roll_rs04_actuator" />
    <child
      link="m4x25_left_shoulder_screws_roll" />
    <axis
      xyz="0 0 0" />
  </joint>
  <link
    name="left_shoulder_roll">
    <inertial>
      <origin
        xyz="-0.00752228698896562 0.0497547009080019 -0.0556811677837489"
        rpy="0 0 0" />
      <mass
        value="0.997620685191693" />
      <inertia
        ixx="0.00534467263689589"
        ixy="-8.46143391551476E-05"
        ixz="-0.000430210477280065"
        iyy="0.00591903783379285"
        iyz="-0.000640722355068562"
        izz="0.00178281860512672" />
    </inertial>
    <visual>
      <origin
        xyz="0 0 0"
        rpy="0 0 0" />
      <geometry>
        <mesh
          filename="package://humanoid_arm_5dof/meshes/left_shoulder_roll.STL" />
      </geometry>
      <material
        name="">
        <color
          rgba="0.952941176470588 0.996078431372549 0.694117647058824 1" />
      </material>
    </visual>
    <collision>
      <origin
        xyz="0 0 0"
        rpy="0 0 0" />
      <geometry>
        <mesh
          filename="package://humanoid_arm_5dof/meshes/left_shoulder_roll.STL" />
      </geometry>
    </collision>
  </link>
  <joint
    name="left_shoulde_roll_fixture_joint"
    type="fixed">
    <origin
      xyz="0 0 0"
      rpy="0 0 0" />
    <parent
      link="m4x25_left_shoulder_screws_roll" />
    <child
      link="left_shoulder_roll" />
    <axis
      xyz="0 0 0" />
  </joint>
  <link
    name="m4x16_left_shoulder_yaw_screws">
    <inertial>
      <origin
        xyz="2.8149127473398E-10 6.03576300051145E-10 0.0451525729626134"
        rpy="0 0 0" />
      <mass
        value="0.0027018447469342" />
      <inertia
        ixx="1.03557857485274E-07"
        ixy="1.55850046126122E-16"
        ixz="-1.88623037508984E-15"
        iyy="1.03557857737464E-07"
        iyz="-3.94399367615451E-15"
        izz="1.05098007898707E-08" />
    </inertial>
    <visual>
      <origin
        xyz="0 0 0"
        rpy="0 0 0" />
      <geometry>
        <mesh
          filename="package://humanoid_arm_5dof/meshes/m4x16_left_shoulder_yaw_screws.STL" />
      </geometry>
      <material
        name="">
        <color
          rgba="0.792156862745098 0.819607843137255 0.933333333333333 1" />
      </material>
    </visual>
    <collision>
      <origin
        xyz="0 0 0"
        rpy="0 0 0" />
      <geometry>
        <mesh
          filename="package://humanoid_arm_5dof/meshes/m4x16_left_shoulder_yaw_screws.STL" />
      </geometry>
    </collision>
  </link>
  <joint
    name="m4x16_left_shoulder_yaw_screws_fixture_joint"
    type="fixed">
    <origin
      xyz="-0.021972 0.0377 -0.17358"
      rpy="0.057123 0.11257 0.47088" />
    <parent
      link="left_shoulder_roll" />
    <child
      link="m4x16_left_shoulder_yaw_screws" />
    <axis
      xyz="0 0 0" />
  </joint>
  <link
    name="left_shoulder_yaw_rs03_actuator">
    <inertial>
      <origin
        xyz="-0.000137350512888212 -0.000269996821934626 0.0250841651613147"
        rpy="0 0 0" />
      <mass
        value="0.356550969588107" />
      <inertia
        ixx="0.000274320425081544"
        ixy="-2.07349930530572E-06"
        ixz="-2.56253688974251E-07"
        iyy="0.000271291938182595"
        iyz="-5.14924832664405E-07"
        izz="0.000381662133736736" />
    </inertial>
    <visual>
      <origin
        xyz="0 0 0"
        rpy="0 0 0" />
      <geometry>
        <mesh
          filename="package://humanoid_arm_5dof/meshes/left_shoulder_yaw_rs03_actuator.STL" />
      </geometry>
      <material
        name="">
        <color
          rgba="0.823529411764706 0.823529411764706 1 1" />
      </material>
    </visual>
    <collision>
      <origin
        xyz="0 0 0"
        rpy="0 0 0" />
      <geometry>
        <mesh
          filename="package://humanoid_arm_5dof/meshes/left_shoulder_yaw_rs03_actuator.STL" />
      </geometry>
    </collision>
  </link>
  <joint
    name="left_shoulder_yaw_rs03_actuator_fixture_link"
    type="fixed">
    <origin
      xyz="0 0 0"
      rpy="0 0 0" />
    <parent
      link="m4x16_left_shoulder_yaw_screws" />
    <child
      link="left_shoulder_yaw_rs03_actuator" />
    <axis
      xyz="0 0 0" />
  </joint>
  <link
    name="left_shoulder_yaw_rs03_flange">
    <inertial>
      <origin
        xyz="-1.19021681399545E-10 -2.31721308807664E-10 -0.00125625968350374"
        rpy="0 0 0" />
      <mass
        value="0.00407555097398891" />
      <inertia
        ixx="5.67676746163455E-07"
        ixy="2.85708183575816E-21"
        ixz="4.32658281851184E-16"
        iyy="5.67676746163458E-07"
        iyz="8.55579959678349E-16"
        izz="1.13114082374849E-06" />
    </inertial>
    <visual>
      <origin
        xyz="0 0 0"
        rpy="0 0 0" />
      <geometry>
        <mesh
          filename="package://humanoid_arm_5dof/meshes/left_shoulder_yaw_rs03_flange.STL" />
      </geometry>
      <material
        name="">
        <color
          rgba="0.823529411764706 0.823529411764706 1 1" />
      </material>
    </visual>
    <collision>
      <origin
        xyz="0 0 0"
        rpy="0 0 0" />
      <geometry>
        <mesh
          filename="package://humanoid_arm_5dof/meshes/left_shoulder_yaw_rs03_flange.STL" />
      </geometry>
    </collision>
  </link>
  <joint
    name="left_shoulder_yaw_rs03_flange_joint"
    type="revolute">
    <origin
      xyz="0 0 0"
      rpy="0 0 0" />
    <parent
      link="left_shoulder_yaw_rs03_actuator" />
    <child
      link="left_shoulder_yaw_rs03_flange" />
    <axis
      xyz="0 0 1" />
    <limit
      lower="-3.14"
      upper="3.14"
      effort="60"
      velocity="1.6" />
    <safety_controller
      soft_upper_limit="3.14"
      soft_lower_limit="-3.14"
      k_velocity="0" />
  </joint>
  <link
    name="left_shoulder_yaw_shaft">
    <inertial>
      <origin
        xyz="-1.30441546453142E-10 -2.48904452604393E-10 -0.0119851125653883"
        rpy="0 0 0" />
      <mass
        value="0.000903649674373974" />
      <inertia
        ixx="4.41715688076216E-08"
        ixy="-6.20385459414771E-25"
        ixz="-3.25311558573123E-17"
        iyy="4.41715688076216E-08"
        iyz="-6.4330077723289E-17"
        izz="1.80539813295945E-09" />
    </inertial>
    <visual>
      <origin
        xyz="0 0 0"
        rpy="0 0 0" />
      <geometry>
        <mesh
          filename="package://humanoid_arm_5dof/meshes/left_shoulder_yaw_shaft.STL" />
      </geometry>
      <material
        name="">
        <color
          rgba="0.823529411764706 0.823529411764706 1 1" />
      </material>
    </visual>
    <collision>
      <origin
        xyz="0 0 0"
        rpy="0 0 0" />
      <geometry>
        <mesh
          filename="package://humanoid_arm_5dof/meshes/left_shoulder_yaw_shaft.STL" />
      </geometry>
    </collision>
  </link>
  <joint
    name="left_shoulder_yaw_shaft_fixture_joint"
    type="fixed">
    <origin
      xyz="0 0 0"
      rpy="0 0 0" />
    <parent
      link="left_shoulder_yaw_rs03_flange" />
    <child
      link="left_shoulder_yaw_shaft" />
    <axis
      xyz="0 0 0" />
    <limit
      lower="0"
      upper="0"
      effort="0"
      velocity="0" />
  </joint>
  <link
    name="left_shoulder_yaw_flange">
    <inertial>
      <origin
        xyz="-1.2410161787102E-10 -2.38561170817775E-10 -0.0089803782656781"
        rpy="0 0 0" />
      <mass
        value="0.0353531461099524" />
      <inertia
        ixx="9.85459914703462E-06"
        ixy="-7.54070449445109E-08"
        ixz="7.27474540563909E-15"
        iyy="9.59337705820242E-06"
        iyz="1.34190932088549E-14"
        izz="1.87117812635897E-05" />
    </inertial>
    <visual>
      <origin
        xyz="0 0 0"
        rpy="0 0 0" />
      <geometry>
        <mesh
          filename="package://humanoid_arm_5dof/meshes/left_shoulder_yaw_flange.STL" />
      </geometry>
      <material
        name="">
        <color
          rgba="0.952941176470588 0.996078431372549 0.694117647058824 1" />
      </material>
    </visual>
    <collision>
      <origin
        xyz="0 0 0"
        rpy="0 0 0" />
      <geometry>
        <mesh
          filename="package://humanoid_arm_5dof/meshes/left_shoulder_yaw_flange.STL" />
      </geometry>
    </collision>
  </link>
  <joint
    name="left_shoulder_yaw_flange_fixture_joint"
    type="fixed">
    <origin
      xyz="0 0 0"
      rpy="0 0 0" />
    <parent
      link="left_shoulder_yaw_shaft" />
    <child
      link="left_shoulder_yaw_flange" />
    <axis
      xyz="0 0 0" />
  </joint>
  <link
    name="1220_m4x16_left_shoulder_yaw_screws">
    <inertial>
      <origin
        xyz="-2.09471440193454E-10 1.53741464004042E-10 -0.0114719356155148"
        rpy="0 0 0" />
      <mass
        value="0.00141036418698182" />
      <inertia
        ixx="3.71610598568614E-08"
        ixy="-3.45554700894027E-21"
        ixz="-2.50151071047644E-17"
        iyy="3.71610598568597E-08"
        iyz="-4.94544342837001E-17"
        izz="4.58636225470957E-09" />
    </inertial>
    <visual>
      <origin
        xyz="0 0 0"
        rpy="0 0 0" />
      <geometry>
        <mesh
          filename="package://humanoid_arm_5dof/meshes/1220_m4x16_left_shoulder_yaw_screws.STL" />
      </geometry>
      <material
        name="">
        <color
          rgba="0.792156862745098 0.819607843137255 0.933333333333333 1" />
      </material>
    </visual>
    <collision>
      <origin
        xyz="0 0 0"
        rpy="0 0 0" />
      <geometry>
        <mesh
          filename="package://humanoid_arm_5dof/meshes/1220_m4x16_left_shoulder_yaw_screws.STL" />
      </geometry>
    </collision>
  </link>
  <joint
    name="1220_m4x16_left_shoulder_yaw_screws_fixture_joint"
    type="fixed">
    <origin
      xyz="0 0 0"
      rpy="0 0 0" />
    <parent
      link="left_shoulder_yaw_flange" />
    <child
      link="1220_m4x16_left_shoulder_yaw_screws" />
    <axis
      xyz="0 0 0" />
  </joint>
  <link
    name="m4x25_left_shoulder_yaw_screws">
    <inertial>
      <origin
        xyz="-6.40714037380974E-10 -1.32397381946703E-09 -0.0144289836669567"
        rpy="0 0 0" />
      <mass
        value="0.00270858202481974" />
      <inertia
        ixx="2.20903769276247E-07"
        ixy="4.52767736066704E-13"
        ixz="-1.94283418987917E-15"
        iyy="2.20904293495991E-07"
        iyz="-4.05275228017035E-15"
        izz="9.25380471510276E-09" />
    </inertial>
    <visual>
      <origin
        xyz="0 0 0"
        rpy="0 0 0" />
      <geometry>
        <mesh
          filename="package://humanoid_arm_5dof/meshes/m4x25_left_shoulder_yaw_screws.STL" />
      </geometry>
      <material
        name="">
        <color
          rgba="0.792156862745098 0.819607843137255 0.933333333333333 1" />
      </material>
    </visual>
    <collision>
      <origin
        xyz="0 0 0"
        rpy="0 0 0" />
      <geometry>
        <mesh
          filename="package://humanoid_arm_5dof/meshes/m4x25_left_shoulder_yaw_screws.STL" />
      </geometry>
    </collision>
  </link>
  <joint
    name="m4x25_left_shoulder_yaw_screws_fixture_joint"
    type="fixed">
    <origin
      xyz="0 0 0"
      rpy="0 0 0" />
    <parent
      link="1220_m4x16_left_shoulder_yaw_screws" />
    <child
      link="m4x25_left_shoulder_yaw_screws" />
    <axis
      xyz="0 0 0" />
  </joint>
  <link
    name="left_shoulder_yaw">
    <inertial>
      <origin
        xyz="-0.0276085510830638 1.01209671576896E-06 -0.0766319307570027"
        rpy="0 0 0" />
      <mass
        value="0.488068654986632" />
      <inertia
        ixx="0.00146908224184929"
        ixy="2.07765763867938E-07"
        ixz="-0.000271215897354308"
        iyy="0.00131630379047568"
        iyz="6.91087690086404E-08"
        izz="0.000811624953047555" />
    </inertial>
    <visual>
      <origin
        xyz="0 0 0"
        rpy="0 0 0" />
      <geometry>
        <mesh
          filename="package://humanoid_arm_5dof/meshes/left_shoulder_yaw.STL" />
      </geometry>
      <material
        name="">
        <color
          rgba="0.952941176470588 0.996078431372549 0.694117647058824 1" />
      </material>
    </visual>
    <collision>
      <origin
        xyz="0 0 0"
        rpy="0 0 0" />
      <geometry>
        <mesh
          filename="package://humanoid_arm_5dof/meshes/left_shoulder_yaw.STL" />
      </geometry>
    </collision>
  </link>
  <joint
    name="left_shoulder_yaw_fixture_joint"
    type="fixed">
    <origin
      xyz="0 0 0"
      rpy="0 0 0" />
    <parent
      link="m4x25_left_shoulder_yaw_screws" />
    <child
      link="left_shoulder_yaw" />
    <axis
      xyz="0 0 0" />
  </joint>
  <link
    name="m4x16_eft_elbow_screws">
    <inertial>
      <origin
        xyz="0.0203953562940695 0.041290057911167 8.81478223746512E-10"
        rpy="0 0 0" />
      <mass
        value="0.0027018435864776" />
      <inertia
        ixx="8.53078781105143E-08"
        ixy="-3.69467569990185E-08"
        ixz="-1.79515831061645E-15"
        iyy="2.87597563262015E-08"
        iyz="-3.55430739279746E-15"
        izz="1.03557847634927E-07" />
    </inertial>
    <visual>
      <origin
        xyz="0 0 0"
        rpy="0 0 0" />
      <geometry>
        <mesh
          filename="package://humanoid_arm_5dof/meshes/m4x16_eft_elbow_screws.STL" />
      </geometry>
      <material
        name="">
        <color
          rgba="0.792156862745098 0.819607843137255 0.933333333333333 1" />
      </material>
    </visual>
    <collision>
      <origin
        xyz="0 0 0"
        rpy="0 0 0" />
      <geometry>
        <mesh
          filename="package://humanoid_arm_5dof/meshes/m4x16_eft_elbow_screws.STL" />
      </geometry>
    </collision>
  </link>
  <joint
    name="m4x16_eft_elbow_screws_fixture_joint"
    type="fixed">
    <origin
      xyz="0 0 -0.0987"
      rpy="0 0 2.0296" />
    <parent
      link="left_shoulder_yaw" />
    <child
      link="m4x16_eft_elbow_screws" />
    <axis
      xyz="0 0 0" />
  </joint>
  <link
    name="left_elbow_rs03_actuator">
    <inertial>
      <origin
        xyz="0.011109781341561 0.0224897320769979 -0.000302908497088028"
        rpy="0 0 0" />
      <mass
        value="0.356550890896861" />
      <inertia
        ixx="0.000296217970940722"
        ixy="4.22025243262797E-05"
        ixz="-2.44834233814142E-07"
        iyy="0.00036081822863925"
        iyz="-5.20600203970104E-07"
        izz="0.000270239476177468" />
    </inertial>
    <visual>
      <origin
        xyz="0 0 0"
        rpy="0 0 0" />
      <geometry>
        <mesh
          filename="package://humanoid_arm_5dof/meshes/left_elbow_rs03_actuator.STL" />
      </geometry>
      <material
        name="">
        <color
          rgba="0.823529411764706 0.823529411764706 1 1" />
      </material>
    </visual>
    <collision>
      <origin
        xyz="0 0 0"
        rpy="0 0 0" />
      <geometry>
        <mesh
          filename="package://humanoid_arm_5dof/meshes/left_elbow_rs03_actuator.STL" />
      </geometry>
    </collision>
  </link>
  <joint
    name="left_elbow_rs03_actuator_ficture_link"
    type="fixed">
    <origin
      xyz="0 0 0"
      rpy="0 0 0" />
    <parent
      link="m4x16_eft_elbow_screws" />
    <child
      link="left_elbow_rs03_actuator" />
    <axis
      xyz="0 0 0" />
  </joint>
  <link
    name="left_elbow_rs03_flange">
    <inertial>
      <origin
        xyz="-0.000556362055206705 -0.00112634330127914 -1.75823577919232E-10"
        rpy="0 0 0" />
      <mass
        value="0.00407555097398881" />
      <inertia
        ixx="6.78191701490765E-07"
        ixy="2.23735674428244E-07"
        ixz="1.65457695380981E-16"
        iyy="1.02062586842112E-06"
        iyz="3.34963771498474E-16"
        izz="5.67676746163437E-07" />
    </inertial>
    <visual>
      <origin
        xyz="0 0 0"
        rpy="0 0 0" />
      <geometry>
        <mesh
          filename="package://humanoid_arm_5dof/meshes/left_elbow_rs03_flange.STL" />
      </geometry>
      <material
        name="">
        <color
          rgba="0.823529411764706 0.823529411764706 1 1" />
      </material>
    </visual>
    <collision>
      <origin
        xyz="0 0 0"
        rpy="0 0 0" />
      <geometry>
        <mesh
          filename="package://humanoid_arm_5dof/meshes/left_elbow_rs03_flange.STL" />
      </geometry>
    </collision>
  </link>
  <joint
    name="left_elbow_rs03_flange_joint"
    type="revolute">
    <origin
      xyz="0 0 0"
      rpy="0 0 0" />
    <parent
      link="left_elbow_rs03_actuator" />
    <child
      link="left_elbow_rs03_flange" />
    <axis
      xyz="0.44287 0.89659 0" />
    <limit
      lower="-1.3"
      upper="1.9"
      effort="60"
      velocity="1.6" />
    <safety_controller
      soft_upper_limit="3.14"
      soft_lower_limit="-3.14"
      k_velocity="0" />
  </joint>
  <link
    name="left_elbow_shaft">
    <inertial>
      <origin
        xyz="-0.426183549857479 0.00226691531515577 -0.176826618802691"
        rpy="0 0 0" />
      <mass
        value="15.7008025632262" />
      <inertia
        ixx="2.2678969453616"
        ixy="0.25180017339468"
        ixz="-1.79738203148208"
        iyy="4.40181077604857"
        iyz="0.369996124901576"
        izz="2.53081553833424" />
    </inertial>
    <visual>
      <origin
        xyz="0 0 0"
        rpy="0 0 0" />
      <geometry>
        <mesh
          filename="package://humanoid_arm_5dof/meshes/left_elbow_shaft.STL" />
      </geometry>
      <material
        name="">
        <color
          rgba="0.752941176470588 0.752941176470588 0.752941176470588 1" />
      </material>
    </visual>
    <collision>
      <origin
        xyz="0 0 0"
        rpy="0 0 0" />
      <geometry>
        <mesh
          filename="package://humanoid_arm_5dof/meshes/left_elbow_shaft.STL" />
      </geometry>
    </collision>
  </link>
  <joint
    name="left_elbow_shaft_fixture_joint"
    type="fixed">
    <origin
      xyz="0 0 0"
      rpy="0 0 0" />
    <parent
      link="left_elbow_rs03_flange" />
    <child
      link="left_elbow_shaft" />
    <axis
      xyz="0 0 0" />
  </joint>
  <link
    name="m4x25_left_elbow_screws">
    <inertial>
      <origin
        xyz="-0.00623517620463376 -0.0126230083759222 -1.57904067599191E-09"
        rpy="0 0 0" />
      <mass
        value="0.002708580334445" />
      <inertia
        ixx="1.79392020976407E-07"
        ixy="-8.40403332969669E-08"
        ixz="-2.18575424656107E-15"
        iyy="5.07657695505485E-08"
        iyz="-4.7315734375029E-15"
        izz="2.2090401494749E-07" />
    </inertial>
    <visual>
      <origin
        xyz="0 0 0"
        rpy="0 0 0" />
      <geometry>
        <mesh
          filename="package://humanoid_arm_5dof/meshes/m4x25_left_elbow_screws.STL" />
      </geometry>
      <material
        name="">
        <color
          rgba="0.792156862745098 0.819607843137255 0.933333333333333 1" />
      </material>
    </visual>
    <collision>
      <origin
        xyz="0 0 0"
        rpy="0 0 0" />
      <geometry>
        <mesh
          filename="package://humanoid_arm_5dof/meshes/m4x25_left_elbow_screws.STL" />
      </geometry>
    </collision>
  </link>
  <joint
    name="m4x25_left_elbow_screws_fixture_joint"
    type="fixed">
    <origin
      xyz="0 0 0"
      rpy="0 0 0" />
    <parent
      link="left_elbow_shaft" />
    <child
      link="m4x25_left_elbow_screws" />
    <axis
      xyz="0 0 0" />
  </joint>
  <link
    name="left_elbow">
    <inertial>
      <origin
        xyz="-0.00117661277747461 -0.0226416926648785 -0.032359563009144"
        rpy="0 0 0" />
      <mass
        value="0.779765455665873" />
      <inertia
        ixx="0.00250248677042264"
        ixy="0.000107026041481092"
        ixz="0.000573100384839254"
        iyy="0.00291648264910015"
        iyz="0.000125954554813068"
        izz="0.000972783991647824" />
    </inertial>
    <visual>
      <origin
        xyz="0 0 0"
        rpy="0 0 0" />
      <geometry>
        <mesh
          filename="package://humanoid_arm_5dof/meshes/left_elbow.STL" />
      </geometry>
      <material
        name="">
        <color
          rgba="0.952941176470588 0.996078431372549 0.694117647058824 1" />
      </material>
    </visual>
    <collision>
      <origin
        xyz="0 0 0"
        rpy="0 0 0" />
      <geometry>
        <mesh
          filename="package://humanoid_arm_5dof/meshes/left_elbow.STL" />
      </geometry>
    </collision>
  </link>
  <joint
    name="left_elbow_fixture_joint"
    type="fixed">
    <origin
      xyz="0 0 0"
      rpy="0 0 0" />
    <parent
      link="m4x25_left_elbow_screws" />
    <child
      link="left_elbow" />
    <axis
      xyz="0 0 0" />
  </joint>
  <link
    name="m3x20_left_wrist_screws">
    <inertial>
      <origin
        xyz="-0.00322617482581966 -0.0374854471298596 0.00322627763645045"
        rpy="0 0 0" />
      <mass
        value="0.0016213702863793" />
      <inertia
        ixx="8.36724015923293E-08"
        ixy="6.90552998962278E-16"
        ixz="-1.0975505086598E-14"
        iyy="3.32920091129771E-09"
        iyz="-7.7809560369147E-14"
        izz="8.36724115122296E-08" />
    </inertial>
    <visual>
      <origin
        xyz="0 0 0"
        rpy="0 0 0" />
      <geometry>
        <mesh
          filename="package://humanoid_arm_5dof/meshes/m3x20_left_wrist_screws.STL" />
      </geometry>
      <material
        name="">
        <color
          rgba="0.792156862745098 0.819607843137255 0.933333333333333 1" />
      </material>
    </visual>
    <collision>
      <origin
        xyz="0 0 0"
        rpy="0 0 0" />
      <geometry>
        <mesh
          filename="package://humanoid_arm_5dof/meshes/m3x20_left_wrist_screws.STL" />
      </geometry>
    </collision>
  </link>
  <joint
    name="m3x20_left_wrist_screws_fixture_joint"
    type="fixed">
    <origin
      xyz="0.037069 -0.024445 -0.15849"
      rpy="-1.2996 0 -2.0296" />
    <parent
      link="left_elbow" />
    <child
      link="m3x20_left_wrist_screws" />
    <axis
      xyz="0 0 0" />
  </joint>
  <link
    name="left_wrist_actuator">
    <inertial>
      <origin
        xyz="-2.61171972937291E-10 -0.0230138333935841 1.16576661657319E-07"
        rpy="0 0 0" />
      <mass
        value="0.180583065420556" />
      <inertia
        ixx="8.80899821792285E-05"
        ixy="-2.55221218931659E-14"
        ixz="-1.03126261328211E-19"
        iyy="0.000127000739066174"
        iyz="3.76283939377826E-11"
        izz="8.80899821792651E-05" />
    </inertial>
    <visual>
      <origin
        xyz="0 0 0"
        rpy="0 0 0" />
      <geometry>
        <mesh
          filename="package://humanoid_arm_5dof/meshes/left_wrist_actuator.STL" />
      </geometry>
      <material
        name="">
        <color
          rgba="0.823529411764706 0.823529411764706 1 1" />
      </material>
    </visual>
    <collision>
      <origin
        xyz="0 0 0"
        rpy="0 0 0" />
      <geometry>
        <mesh
          filename="package://humanoid_arm_5dof/meshes/left_wrist_actuator.STL" />
      </geometry>
    </collision>
  </link>
  <joint
    name="left_wrist_actuator_fixture_link"
    type="fixed">
    <origin
      xyz="0 0 0"
      rpy="0 0 0" />
    <parent
      link="m3x20_left_wrist_screws" />
    <child
      link="left_wrist_actuator" />
    <axis
      xyz="0 0 0" />
  </joint>
  <link
    name="left_wrist_rs02_flange">
    <inertial>
      <origin
        xyz="-3.24093751835619E-10 -0.00198993491885391 1.37342849537703E-07"
        rpy="0 0 0" />
      <mass
        value="0.00245793392108131" />
      <inertia
        ixx="1.34950766910329E-07"
        ixy="-8.41704162894269E-17"
        ixz="4.40060085878211E-22"
        iyy="2.63403217776752E-07"
        iyz="1.24219150107879E-13"
        izz="1.34950766910449E-07" />
    </inertial>
    <visual>
      <origin
        xyz="0 0 0"
        rpy="0 0 0" />
      <geometry>
        <mesh
          filename="package://humanoid_arm_5dof/meshes/left_wrist_rs02_flange.STL" />
      </geometry>
      <material
        name="">
        <color
          rgba="0.823529411764706 0.823529411764706 1 1" />
      </material>
    </visual>
    <collision>
      <origin
        xyz="0 0 0"
        rpy="0 0 0" />
      <geometry>
        <mesh
          filename="package://humanoid_arm_5dof/meshes/left_wrist_rs02_flange.STL" />
      </geometry>
    </collision>
  </link>
  <joint
    name="left_wrist_rs02_flange_joint"
    type="revolute">
    <origin
      xyz="0 0 0"
      rpy="0 0 0" />
    <parent
      link="left_wrist_actuator" />
    <child
      link="left_wrist_rs02_flange" />
    <axis
      xyz="0 1 0" />
    <limit
      lower="-3.14"
      upper="3.14"
      effort="17"
      velocity="0.8" />
    <safety_controller
      soft_upper_limit="3.14"
      soft_lower_limit="-3.14"
      k_velocity="0" />
  </joint>
  <link
    name="m4x20_left_wrist_screws">
    <inertial>
      <origin
        xyz="3.33469427626909E-08 0.00840266508967247 1.6878232944606E-07"
        rpy="0 0 0" />
      <mass
        value="0.00232797016313314" />
      <inertia
        ixx="1.29587507987181E-07"
        ixy="-3.32287564401703E-13"
        ixz="3.13118250803152E-13"
        iyy="8.48546817324519E-09"
        iyz="-3.27038363557767E-13"
        izz="1.29587220640256E-07" />
    </inertial>
    <visual>
      <origin
        xyz="0 0 0"
        rpy="0 0 0" />
      <geometry>
        <mesh
          filename="package://humanoid_arm_5dof/meshes/m4x20_left_wrist_screws.STL" />
      </geometry>
      <material
        name="">
        <color
          rgba="0.792156862745098 0.819607843137255 0.933333333333333 1" />
      </material>
    </visual>
    <collision>
      <origin
        xyz="0 0 0"
        rpy="0 0 0" />
      <geometry>
        <mesh
          filename="package://humanoid_arm_5dof/meshes/m4x20_left_wrist_screws.STL" />
      </geometry>
    </collision>
  </link>
  <joint
    name="m4x20_left_wrist_screws_fixture_joint"
    type="fixed">
    <origin
      xyz="0 0 0"
      rpy="0 0 0" />
    <parent
      link="left_wrist_rs02_flange" />
    <child
      link="m4x20_left_wrist_screws" />
    <axis
      xyz="0 0 0" />
  </joint>
  <link
    name="left_wrist_shaft">
    <inertial>
      <origin
        xyz="-3.30478755472541E-10 0.0079851124723529 1.46989119542695E-07"
        rpy="0 0 0" />
      <mass
        value="0.000903649674374008" />
      <inertia
        ixx="4.41715688076248E-08"
        ixy="2.7761391322183E-17"
        ixz="2.79173456736647E-23"
        iyy="1.80539813299913E-09"
        iyz="-4.09699435710941E-14"
        izz="4.41715688075851E-08" />
    </inertial>
    <visual>
      <origin
        xyz="0 0 0"
        rpy="0 0 0" />
      <geometry>
        <mesh
          filename="package://humanoid_arm_5dof/meshes/left_wrist_shaft.STL" />
      </geometry>
      <material
        name="">
        <color
          rgba="0.823529411764706 0.823529411764706 1 1" />
      </material>
    </visual>
    <collision>
      <origin
        xyz="0 0 0"
        rpy="0 0 0" />
      <geometry>
        <mesh
          filename="package://humanoid_arm_5dof/meshes/left_wrist_shaft.STL" />
      </geometry>
    </collision>
  </link>
  <joint
    name="left_wrist_shaft_fixture_joint"
    type="fixed">
    <origin
      xyz="0 0 0"
      rpy="0 0 0" />
    <parent
      link="m4x20_left_wrist_screws" />
    <child
      link="left_wrist_shaft" />
    <axis
      xyz="0 0 0" />
  </joint>
  <link
    name="left_wrist">
    <inertial>
      <origin
        xyz="-0.0126284318643981 0.0418086833915599 0.00594041745205054"
        rpy="0 0 0" />
      <mass
        value="0.388950905166578" />
      <inertia
        ixx="0.000833659232996467"
        ixy="0.000191177318683077"
        ixz="2.04619116904629E-06"
        iyy="0.000517833839560631"
        iyz="-8.95572092038221E-05"
        izz="0.000838969538387841" />
    </inertial>
    <visual>
      <origin
        xyz="0 0 0"
        rpy="0 0 0" />
      <geometry>
        <mesh
          filename="package://humanoid_arm_5dof/meshes/left_wrist.STL" />
      </geometry>
      <material
        name="">
        <color
          rgba="0.952941176470588 0.996078431372549 0.694117647058824 1" />
      </material>
    </visual>
    <collision>
      <origin
        xyz="0 0 0"
        rpy="0 0 0" />
      <geometry>
        <mesh
          filename="package://humanoid_arm_5dof/meshes/left_wrist.STL" />
      </geometry>
    </collision>
  </link>
  <joint
    name="left_wrist_fixture_joint"
    type="fixed">
    <origin
      xyz="0 0 0"
      rpy="0 0 0" />
    <parent
      link="left_wrist_shaft" />
    <child
      link="left_wrist" />
    <axis
      xyz="0 0 0" />
  </joint>
  <link
    name="m3x16_left_hand_screws">
    <inertial>
      <origin
        xyz="-0.0363345313519528 0.00271813491059358 0.00366468538312237"
        rpy="0 0 0" />
      <mass
        value="0.00139374174732639" />
      <inertia
        ixx="3.07153113593459E-09"
        ixy="1.08336735349727E-15"
        ixz="-2.15966387711326E-14"
        iyy="4.88927935104739E-08"
        iyz="1.38730459791668E-16"
        izz="4.88928835911716E-08" />
    </inertial>
    <visual>
      <origin
        xyz="0 0 0"
        rpy="0 0 0" />
      <geometry>
        <mesh
          filename="package://humanoid_arm_5dof/meshes/m3x16_left_hand_screws.STL" />
      </geometry>
      <material
        name="">
        <color
          rgba="0.792156862745098 0.819607843137255 0.933333333333333 1" />
      </material>
    </visual>
    <collision>
      <origin
        xyz="0 0 0"
        rpy="0 0 0" />
      <geometry>
        <mesh
          filename="package://humanoid_arm_5dof/meshes/m3x16_left_hand_screws.STL" />
      </geometry>
    </collision>
  </link>
  <joint
    name="m3x16_left_hand_screws_fixture_joint"
    type="fixed">
    <origin
      xyz="0 0.0945 0"
      rpy="0.64485 0.44406 0" />
    <parent
      link="left_wrist" />
    <child
      link="m3x16_left_hand_screws" />
    <axis
      xyz="0 0 0" />
  </joint>
  <link
    name="left_hand_rs02">
    <inertial>
      <origin
        xyz="-0.0230139275754251 1.11887740850136E-07 1.62882608623072E-07"
        rpy="0 0 0" />
      <mass
        value="0.180583065420555" />
      <inertia
        ixx="0.000127000739066205"
        ixy="1.13148706213107E-11"
        ixz="-8.51834997938478E-12"
        iyy="8.80899821792299E-05"
        iyz="-2.30608107756008E-18"
        izz="8.80899821792286E-05" />
    </inertial>
    <visual>
      <origin
        xyz="0 0 0"
        rpy="0 0 0" />
      <geometry>
        <mesh
          filename="package://humanoid_arm_5dof/meshes/left_hand_rs02.STL" />
      </geometry>
      <material
        name="">
        <color
          rgba="0.823529411764706 0.823529411764706 1 1" />
      </material>
    </visual>
    <collision>
      <origin
        xyz="0 0 0"
        rpy="0 0 0" />
      <geometry>
        <mesh
          filename="package://humanoid_arm_5dof/meshes/left_hand_rs02.STL" />
      </geometry>
    </collision>
  </link>
  <joint
    name="left_hand_rs02_fixture_link"
    type="fixed">
    <origin
      xyz="0 0 0"
      rpy="0 0 0" />
    <parent
      link="m3x16_left_hand_screws" />
    <child
      link="left_hand_rs02" />
    <axis
      xyz="0 0 0" />
  </joint>
  <link
    name="left_hand_rs02_flange">
    <inertial>
      <origin
        xyz="-0.00201015947985911 1.17995438753127E-07 1.58284451989843E-07"
        rpy="0 0 0" />
      <mass
        value="0.00245793392108139" />
      <inertia
        ixx="2.63403217776866E-07"
        ixy="3.73528015203689E-14"
        ixz="-2.81208836707921E-14"
        iyy="1.34950766910345E-07"
        iyz="-7.49614463819065E-21"
        izz="1.34950766910341E-07" />
    </inertial>
    <visual>
      <origin
        xyz="0 0 0"
        rpy="0 0 0" />
      <geometry>
        <mesh
          filename="package://humanoid_arm_5dof/meshes/left_hand_rs02_flange.STL" />
      </geometry>
      <material
        name="">
        <color
          rgba="0.823529411764706 0.823529411764706 1 1" />
      </material>
    </visual>
    <collision>
      <origin
        xyz="0 0 0"
        rpy="0 0 0" />
      <geometry>
        <mesh
          filename="package://humanoid_arm_5dof/meshes/left_hand_rs02_flange.STL" />
      </geometry>
    </collision>
  </link>
  <joint
    name="left_hand_rs02_flange_joint"
    type="revolute">
    <origin
      xyz="0 0 0"
      rpy="0 0 0" />
    <parent
      link="left_hand_rs02" />
    <child
      link="left_hand_rs02_flange" />
    <axis
      xyz="1 0 0" />
    <limit
      lower="-1.5"
      upper="1.7"
      effort="17"
      velocity="0.8" />
    <safety_controller
      soft_upper_limit="1.7"
      soft_lower_limit="-1.5"
      k_velocity="0" />
  </joint>
  <link
    name="left_hand">
    <inertial>
      <origin
        xyz="0.0119774061084628 0.0114766334463337 -0.0111415842688378"
        rpy="0 0 0" />
      <mass
        value="0.285530356868975" />
      <inertia
        ixx="0.000354627600517714"
        ixy="1.61688448520984E-05"
        ixz="-1.60212066337271E-05"
        iyy="0.000247513430483904"
        iyz="3.07039787587995E-05"
        izz="0.000247329277621897" />
    </inertial>
    <visual>
      <origin
        xyz="0 0 0"
        rpy="0 0 0" />
      <geometry>
        <mesh
          filename="package://humanoid_arm_5dof/meshes/left_hand.STL" />
      </geometry>
      <material
        name="">
        <color
          rgba="0.952941176470588 0.996078431372549 0.694117647058824 1" />
      </material>
    </visual>
    <collision>
      <origin
        xyz="0 0 0"
        rpy="0 0 0" />
      <geometry>
        <mesh
          filename="package://humanoid_arm_5dof/meshes/left_hand.STL" />
      </geometry>
    </collision>
  </link>
  <joint
    name="left_hand_fixture_joint"
    type="fixed">
    <origin
      xyz="0 0 0"
      rpy="0 0 0" />
    <parent
      link="left_hand_rs02_flange" />
    <child
      link="left_hand" />
    <axis
      xyz="0 0 0" />
  </joint>
</robot>