<?xml version="1.0" encoding="utf-8"?>
<!-- This URDF was automatically created by SolidWorks to URDF Exporter! Originally created by Stephen Brawner (brawner@gmail.com) 
     Commit Version: 1.6.0-4-g7f85cfe  Build Version: 1.6.7995.38578
     For more information, please see http://wiki.ros.org/sw_urdf_exporter -->
<robot
  name="humanoid_arm_5dof">
  <link
    name="base_fixture_link">
    <inertial>
      <origin
        xyz="0.020038 0.011873 0.36664"
        rpy="0 0 0" />
      <mass
        value="400" />
      <inertia
        ixx="2.851"
        ixy="-0.025185"
        ixz="-0.21797"
        iyy="2.8785"
        iyz="-0.12915"
        izz="0.18525" />
    </inertial>
    <visual>
      <origin
        xyz="0 0 0"
        rpy="0 0 0" />
      <geometry>
        <mesh
          filename="package://humanoid_arm_5dof/meshes/base_fixture_link.STL" />
      </geometry>
      <material
        name="">
        <color
          rgba="0.79216 0.81961 0.93333 1" />
      </material>
    </visual>
    <collision>
      <origin
        xyz="0 0 0"
        rpy="0 0 0" />
      <geometry>
        <mesh
          filename="package://humanoid_arm_5dof/meshes/base_fixture_link.STL" />
      </geometry>
    </collision>
  </link>
  <link
    name="left_shoulder_pitch_rs04_actuator">
    <inertial>
      <origin
        xyz="-0.0245322216652195 1.17239551400417E-12 -9.62785406954936E-13"
        rpy="0 0 0" />
      <mass
        value="0.517423577893353" />
      <inertia
        ixx="0.000876413569064526"
        ixy="-1.15027074237134E-17"
        ixz="-1.47620902047479E-16"
        iyy="0.000542404795301473"
        iyz="-3.54714747575891E-06"
        izz="0.00054116434911771" />
    </inertial>
    <visual>
      <origin
        xyz="0 0 0"
        rpy="0 0 0" />
      <geometry>
        <mesh
          filename="package://humanoid_arm_5dof/meshes/left_shoulder_pitch_rs04_actuator.STL" />
      </geometry>
      <material
        name="">
        <color
          rgba="0.823529411764706 0.823529411764706 1 1" />
      </material>
    </visual>
    <collision>
      <origin
        xyz="0 0 0"
        rpy="0 0 0" />
      <geometry>
        <mesh
          filename="package://humanoid_arm_5dof/meshes/left_shoulder_pitch_rs04_actuator.STL" />
      </geometry>
    </collision>
  </link>
  <joint
    name="left_shoulder_pitch_rs04_actuator_fixture_link"
    type="fixed">
    <origin
      xyz="0.32924 0.19509 1.45"
      rpy="-0.6108 0 0.53491" />
    <parent
      link="base_fixture_link" />
    <child
      link="left_shoulder_pitch_rs04_actuator" />
    <axis
      xyz="0 0 0" />
  </joint>
  <link
    name="left_shoulder_pitch_rs04_flange">
    <inertial>
      <origin
        xyz="-0.00188936806429085 -9.55715032868731E-05 2.58079795634192E-05"
        rpy="0 0 0" />
      <mass
        value="0.00758352122244511" />
      <inertia
        ixx="2.3623080270334E-06"
        ixy="7.73579308859591E-21"
        ixz="-1.03629187140643E-20"
        iyy="1.19406420659585E-06"
        iyz="-3.70576914423756E-22"
        izz="1.19406420659585E-06" />
    </inertial>
    <visual>
      <origin
        xyz="0 0 0"
        rpy="0 0 0" />
      <geometry>
        <mesh
          filename="package://humanoid_arm_5dof/meshes/left_shoulder_pitch_rs04_flange.STL" />
      </geometry>
      <material
        name="">
        <color
          rgba="0.823529411764706 0.823529411764706 1 1" />
      </material>
    </visual>
    <collision>
      <origin
        xyz="0 0 0"
        rpy="0 0 0" />
      <geometry>
        <mesh
          filename="package://humanoid_arm_5dof/meshes/left_shoulder_pitch_rs04_flange.STL" />
      </geometry>
    </collision>
  </link>
  <joint
    name="left_shoulder_pitch_rs04_joint"
    type="revolute">
    <origin
      xyz="0 0 0"
      rpy="0 0 0" />
    <parent
      link="left_shoulder_pitch_rs04_actuator" />
    <child
      link="left_shoulder_pitch_rs04_flange" />
    <axis
      xyz="1 0 0" />
    <limit
      lower="-3.14"
      upper="3.14"
      effort="120"
      velocity="3" />
    <safety_controller
      soft_upper_limit="3.14"
      soft_lower_limit="-3.14"
      k_velocity="0" />
  </joint>
  <link
    name="m5x22_screws_left_shoulder_pitch">
    <inertial>
      <origin
        xyz="0.0063935043367962 -0.00479834508234633 0.00128572351659972"
        rpy="0 0 0" />
      <mass
        value="0.00474644340626598" />
      <inertia
        ixx="2.66191925293525E-08"
        ixy="-1.25098390873734E-13"
        ixz="-1.97477630156499E-13"
        iyy="3.31053916794916E-07"
        iyz="8.6257075062919E-14"
        izz="3.310546729657E-07" />
    </inertial>
    <visual>
      <origin
        xyz="0 0 0"
        rpy="0 0 0" />
      <geometry>
        <mesh
          filename="package://humanoid_arm_5dof/meshes/m5x22_screws_left_shoulder_pitch.STL" />
      </geometry>
      <material
        name="">
        <color
          rgba="0.792156862745098 0.819607843137255 0.933333333333333 1" />
      </material>
    </visual>
    <collision>
      <origin
        xyz="0 0 0"
        rpy="0 0 0" />
      <geometry>
        <mesh
          filename="package://humanoid_arm_5dof/meshes/m5x22_screws_left_shoulder_pitch.STL" />
      </geometry>
    </collision>
  </link>
  <joint
    name="m5x22_screws_left_shoulder_pitch_fixture_joint"
    type="fixed">
    <origin
      xyz="0 0 0"
      rpy="0 0 0" />
    <parent
      link="left_shoulder_pitch_rs04_flange" />
    <child
      link="m5x22_screws_left_shoulder_pitch" />
    <axis
      xyz="0 0 0" />
  </joint>
  <link
    name="left_shoulder_pitch">
    <inertial>
      <origin
        xyz="0.0682474669169862 0.0395514519450173 -5.2339778915389E-06"
        rpy="0 0 0" />
      <mass
        value="1.19772099854413" />
      <inertia
        ixx="0.00347656174231651"
        ixy="-0.00164350112429136"
        ixz="-3.1020989768154E-07"
        iyy="0.00604621894017105"
        iyz="-1.2948542512368E-07"
        izz="0.00615255051501155" />
    </inertial>
    <visual>
      <origin
        xyz="0 0 0"
        rpy="0 0 0" />
      <geometry>
        <mesh
          filename="package://humanoid_arm_5dof/meshes/left_shoulder_pitch.STL" />
      </geometry>
      <material
        name="">
        <color
          rgba="0.952941176470588 0.996078431372549 0.694117647058824 1" />
      </material>
    </visual>
    <collision>
      <origin
        xyz="0 0 0"
        rpy="0 0 0" />
      <geometry>
        <mesh
          filename="package://humanoid_arm_5dof/meshes/left_shoulder_pitch.STL" />
      </geometry>
    </collision>
  </link>
  <joint
    name="left_shoulder_pitch_fixture_joint"
    type="fixed">
    <origin
      xyz="0 0 0"
      rpy="0 0 0" />
    <parent
      link="m5x22_screws_left_shoulder_pitch" />
    <child
      link="left_shoulder_pitch" />
    <axis
      xyz="0 0 0" />
  </joint>
  <link
    name="m5x22_screws_left_shoulder_roll">
    <inertial>
      <origin
        xyz="0.116724155999398 0.0615935045052187 2.41514839759427E-05"
        rpy="0 0 0" />
      <mass
        value="0.00610257053905776" />
      <inertia
        ixx="4.25641380807005E-07"
        ixy="1.38655677969087E-13"
        ixz="4.65295401922437E-13"
        iyy="3.42246799589696E-08"
        iyz="2.62714511930304E-13"
        izz="4.25641102603522E-07" />
    </inertial>
    <visual>
      <origin
        xyz="0 0 0"
        rpy="0 0 0" />
      <geometry>
        <mesh
          filename="package://humanoid_arm_5dof/meshes/m5x22_screws_left_shoulder_roll.STL" />
      </geometry>
      <material
        name="">
        <color
          rgba="0.792156862745098 0.819607843137255 0.933333333333333 1" />
      </material>
    </visual>
    <collision>
      <origin
        xyz="0 0 0"
        rpy="0 0 0" />
      <geometry>
        <mesh
          filename="package://humanoid_arm_5dof/meshes/m5x22_screws_left_shoulder_roll.STL" />
      </geometry>
    </collision>
  </link>
  <joint
    name="m5x22_screws_left_shoulder_roll_fixture_joint"
    type="fixed">
    <origin
      xyz="0 0 0"
      rpy="0 0 0" />
    <parent
      link="left_shoulder_pitch" />
    <child
      link="m5x22_screws_left_shoulder_roll" />
    <axis
      xyz="0 0 0" />
  </joint>
  <link
    name="left_shoulder_roll_rs04_flange">
    <inertial>
      <origin
        xyz="-5.32907051820075E-14 -0.00211063193644812 1.07766684465105E-10"
        rpy="0 0 0" />
      <mass
        value="0.00758352122244501" />
      <inertia
        ixx="1.19406420659583E-06"
        ixy="-2.66683029487096E-21"
        ixz="-1.07202607386872E-21"
        iyy="2.36230802703336E-06"
        iyz="-2.4917986654965E-15"
        izz="1.19406420659584E-06" />
    </inertial>
    <visual>
      <origin
        xyz="0 0 0"
        rpy="0 0 0" />
      <geometry>
        <mesh
          filename="package://humanoid_arm_5dof/meshes/left_shoulder_roll_rs04_flange.STL" />
      </geometry>
      <material
        name="">
        <color
          rgba="0.823529411764706 0.823529411764706 1 1" />
      </material>
    </visual>
    <collision>
      <origin
        xyz="0 0 0"
        rpy="0 0 0" />
      <geometry>
        <mesh
          filename="package://humanoid_arm_5dof/meshes/left_shoulder_roll_rs04_flange.STL" />
      </geometry>
    </collision>
  </link>
  <joint
    name="left_shoulder_roll_rs04_flange_joint"
    type="fixed">
    <origin
      xyz="0.11678 0.0487 -2.7056E-05"
      rpy="0 0 3.1416" />
    <parent
      link="m5x22_screws_left_shoulder_roll" />
    <child
      link="left_shoulder_roll_rs04_flange" />
    <axis
      xyz="0 0 0" />
  </joint>
  <link
    name="left_shoulder_roll_rs04_actuator">
    <inertial>
      <origin
        xyz="7.54312757612619E-05 0.0205322216645349 2.70558662898157E-05"
        rpy="0 0 0" />
      <mass
        value="0.517423577893354" />
      <inertia
        ixx="0.000542006962748031"
        ixy="-7.69749661146818E-15"
        ixz="-3.59408880621031E-06"
        iyy="0.000876413569064532"
        iyz="-7.14373194930437E-13"
        izz="0.000541562181671226" />
    </inertial>
    <visual>
      <origin
        xyz="0 0 0"
        rpy="0 0 0" />
      <geometry>
        <mesh
          filename="package://humanoid_arm_5dof/meshes/left_shoulder_roll_rs04_actuator.STL" />
      </geometry>
      <material
        name="">
        <color
          rgba="0.823529411764706 0.823529411764706 1 1" />
      </material>
    </visual>
    <collision>
      <origin
        xyz="0 0 0"
        rpy="0 0 0" />
      <geometry>
        <mesh
          filename="package://humanoid_arm_5dof/meshes/left_shoulder_roll_rs04_actuator.STL" />
      </geometry>
    </collision>
  </link>
  <joint
    name="left_shoulder_roll_rs04_actuator_joint"
    type="revolute">
    <origin
      xyz="0 0 0"
      rpy="0 0 0" />
    <parent
      link="left_shoulder_roll_rs04_flange" />
    <child
      link="left_shoulder_roll_rs04_actuator" />
    <axis
      xyz="0 -1 0" />
    <limit
      lower="-3.5"
      upper="0.6"
      effort="120"
      velocity="3" />
    <safety_controller
      soft_upper_limit="3.14"
      soft_lower_limit="-3.14"
      k_velocity="0" />
  </joint>
  <link
    name="m4x25_left_shoulder_screws_roll">
    <inertial>
      <origin
        xyz="5.45041062935958E-05 0.0496289837029003 5.40653506522215E-05"
        rpy="0 0 0" />
      <mass
        value="0.00451430348886333" />
      <inertia
        ixx="3.6817338724036E-07"
        ixy="-6.77491293840167E-15"
        ixz="6.50699048061328E-17"
        iyy="1.54230097659284E-08"
        iyz="2.65419109918824E-16"
        izz="3.68173386339824E-07" />
    </inertial>
    <visual>
      <origin
        xyz="0 0 0"
        rpy="0 0 0" />
      <geometry>
        <mesh
          filename="package://humanoid_arm_5dof/meshes/m4x25_left_shoulder_screws_roll.STL" />
      </geometry>
      <material
        name="">
        <color
          rgba="0.792156862745098 0.819607843137255 0.933333333333333 1" />
      </material>
    </visual>
    <collision>
      <origin
        xyz="0 0 0"
        rpy="0 0 0" />
      <geometry>
        <mesh
          filename="package://humanoid_arm_5dof/meshes/m4x25_left_shoulder_screws_roll.STL" />
      </geometry>
    </collision>
  </link>
  <joint
    name="m4x25_left_shoulder_screws_roll_fixture_joint"
    type="fixed">
    <origin
      xyz="0 0 0"
      rpy="0 0 0" />
    <parent
      link="left_shoulder_roll_rs04_actuator" />
    <child
      link="m4x25_left_shoulder_screws_roll" />
    <axis
      xyz="0 0 0" />
  </joint>
  <link
    name="left_shoulder_roll">
    <inertial>
      <origin
        xyz="-0.00752228684461964 0.0497547008452837 -0.0556811675725345"
        rpy="0 0 0" />
      <mass
        value="0.997620680698827" />
      <inertia
        ixx="0.00534467262744179"
        ixy="-8.46143440203765E-05"
        ixz="-0.000430210470880688"
        iyy="0.00591903781324534"
        iyz="-0.000640722358388087"
        izz="0.00178281859692324" />
    </inertial>
    <visual>
      <origin
        xyz="0 0 0"
        rpy="0 0 0" />
      <geometry>
        <mesh
          filename="package://humanoid_arm_5dof/meshes/left_shoulder_roll.STL" />
      </geometry>
      <material
        name="">
        <color
          rgba="0.952941176470588 0.996078431372549 0.694117647058824 1" />
      </material>
    </visual>
    <collision>
      <origin
        xyz="0 0 0"
        rpy="0 0 0" />
      <geometry>
        <mesh
          filename="package://humanoid_arm_5dof/meshes/left_shoulder_roll.STL" />
      </geometry>
    </collision>
  </link>
  <joint
    name="left_shoulde_roll_fixture_joint"
    type="fixed">
    <origin
      xyz="0 0 0"
      rpy="0 0 0" />
    <parent
      link="m4x25_left_shoulder_screws_roll" />
    <child
      link="left_shoulder_roll" />
    <axis
      xyz="0 0 0" />
  </joint>
  <link
    name="m4x16_left_shoulder_yaw_screws">
    <inertial>
      <origin
        xyz="2.42854403254E-10 5.29228660894887E-10 0.0451525729697173"
        rpy="0 0 0" />
      <mass
        value="0.00270184474693417" />
      <inertia
        ixx="1.03557857485274E-07"
        ixy="1.55850018829162E-16"
        ixz="-1.91328927652366E-15"
        iyy="1.03557857737463E-07"
        iyz="-3.99757712060493E-15"
        izz="1.05098007898704E-08" />
    </inertial>
    <visual>
      <origin
        xyz="0 0 0"
        rpy="0 0 0" />
      <geometry>
        <mesh
          filename="package://humanoid_arm_5dof/meshes/m4x16_left_shoulder_yaw_screws.STL" />
      </geometry>
      <material
        name="">
        <color
          rgba="0.792156862745098 0.819607843137255 0.933333333333333 1" />
      </material>
    </visual>
    <collision>
      <origin
        xyz="0 0 0"
        rpy="0 0 0" />
      <geometry>
        <mesh
          filename="package://humanoid_arm_5dof/meshes/m4x16_left_shoulder_yaw_screws.STL" />
      </geometry>
    </collision>
  </link>
  <joint
    name="m4x16_left_shoulder_yaw_screws_fixture_joint"
    type="fixed">
    <origin
      xyz="-0.021972 0.0377 -0.17358"
      rpy="0.057123 0.11257 0.47088" />
    <parent
      link="left_shoulder_roll" />
    <child
      link="m4x16_left_shoulder_yaw_screws" />
    <axis
      xyz="0 0 0" />
  </joint>
  <link
    name="left_shoulder_yaw_rs03_actuator">
    <inertial>
      <origin
        xyz="-0.00013735055744557 -0.000269996907811709 0.0250841651686169"
        rpy="0 0 0" />
      <mass
        value="0.356550969588107" />
      <inertia
        ixx="0.000274320425081058"
        ixy="-2.07349930584694E-06"
        ixz="-2.5625365660784E-07"
        iyy="0.00027129193818234"
        iyz="-5.14924768481629E-07"
        izz="0.00038166213373748" />
    </inertial>
    <visual>
      <origin
        xyz="0 0 0"
        rpy="0 0 0" />
      <geometry>
        <mesh
          filename="package://humanoid_arm_5dof/meshes/left_shoulder_yaw_rs03_actuator.STL" />
      </geometry>
      <material
        name="">
        <color
          rgba="0.823529411764706 0.823529411764706 1 1" />
      </material>
    </visual>
    <collision>
      <origin
        xyz="0 0 0"
        rpy="0 0 0" />
      <geometry>
        <mesh
          filename="package://humanoid_arm_5dof/meshes/left_shoulder_yaw_rs03_actuator.STL" />
      </geometry>
    </collision>
  </link>
  <joint
    name="left_shoulder_yaw_rs03_actuator_fixture_link"
    type="fixed">
    <origin
      xyz="0 0 0"
      rpy="0 0 0" />
    <parent
      link="m4x16_left_shoulder_yaw_screws" />
    <child
      link="left_shoulder_yaw_rs03_actuator" />
    <axis
      xyz="0 0 0" />
  </joint>
  <link
    name="left_shoulder_yaw_rs03_flange">
    <inertial>
      <origin
        xyz="-1.70902070273371E-10 -3.3285152412077E-10 -0.00125625967639764"
        rpy="0 0 0" />
      <mass
        value="0.00407555097398915" />
      <inertia
        ixx="5.67676746163483E-07"
        ixy="1.99846835992811E-21"
        ixz="5.96516431611892E-16"
        iyy="5.67676746163482E-07"
        iyz="1.18005525306322E-15"
        izz="1.13114082374854E-06" />
    </inertial>
    <visual>
      <origin
        xyz="0 0 0"
        rpy="0 0 0" />
      <geometry>
        <mesh
          filename="package://humanoid_arm_5dof/meshes/left_shoulder_yaw_rs03_flange.STL" />
      </geometry>
      <material
        name="">
        <color
          rgba="0.823529411764706 0.823529411764706 1 1" />
      </material>
    </visual>
    <collision>
      <origin
        xyz="0 0 0"
        rpy="0 0 0" />
      <geometry>
        <mesh
          filename="package://humanoid_arm_5dof/meshes/left_shoulder_yaw_rs03_flange.STL" />
      </geometry>
    </collision>
  </link>
  <joint
    name="left_shoulder_yaw_rs03_joint"
    type="revolute">
    <origin
      xyz="0 0 0"
      rpy="0 0 0" />
    <parent
      link="left_shoulder_yaw_rs03_actuator" />
    <child
      link="left_shoulder_yaw_rs03_flange" />
    <axis
      xyz="0 0 1" />
    <limit
      lower="-3.14"
      upper="3.14"
      effort="60"
      velocity="1.6" />
    <safety_controller
      soft_upper_limit="3.14"
      soft_lower_limit="-3.14"
      k_velocity="0" />
  </joint>
  <link
    name="left_shoulder_yaw_shaft">
    <inertial>
      <origin
        xyz="-1.85636284122381E-10 -3.56167095816318E-10 -0.0119851125582828"
        rpy="0 0 0" />
      <mass
        value="0.000903649674373999" />
      <inertia
        ixx="4.41715688076241E-08"
        ixy="-3.72231275648862E-24"
        ixz="-4.48514208911538E-17"
        iyy="4.41715688076241E-08"
        iyz="-8.87269371781577E-17"
        izz="1.8053981329595E-09" />
    </inertial>
    <visual>
      <origin
        xyz="0 0 0"
        rpy="0 0 0" />
      <geometry>
        <mesh
          filename="package://humanoid_arm_5dof/meshes/left_shoulder_yaw_shaft.STL" />
      </geometry>
      <material
        name="">
        <color
          rgba="0.823529411764706 0.823529411764706 1 1" />
      </material>
    </visual>
    <collision>
      <origin
        xyz="0 0 0"
        rpy="0 0 0" />
      <geometry>
        <mesh
          filename="package://humanoid_arm_5dof/meshes/left_shoulder_yaw_shaft.STL" />
      </geometry>
    </collision>
  </link>
  <joint
    name="left_shoulder_yaw_shaft_fixture_joint"
    type="fixed">
    <origin
      xyz="0 0 0"
      rpy="0 0 0" />
    <parent
      link="left_shoulder_yaw_rs03_flange" />
    <child
      link="left_shoulder_yaw_shaft" />
    <axis
      xyz="0 0 0" />
    <limit
      lower="0"
      upper="0"
      effort="0"
      velocity="0" />
  </joint>
  <link
    name="left_shoulder_yaw_flange">
    <inertial>
      <origin
        xyz="-1.78706716091881E-10 -3.44034134514004E-10 -0.00898037825858222"
        rpy="0 0 0" />
      <mass
        value="0.0353531461099523" />
      <inertia
        ixx="9.85459914701812E-06"
        ixy="-7.54070449731821E-08"
        ixz="9.89355774683734E-15"
        iyy="9.59337705821899E-06"
        iyz="1.86921223331994E-14"
        izz="1.87117812635898E-05" />
    </inertial>
    <visual>
      <origin
        xyz="0 0 0"
        rpy="0 0 0" />
      <geometry>
        <mesh
          filename="package://humanoid_arm_5dof/meshes/left_shoulder_yaw_flange.STL" />
      </geometry>
      <material
        name="">
        <color
          rgba="0.952941176470588 0.996078431372549 0.694117647058824 1" />
      </material>
    </visual>
    <collision>
      <origin
        xyz="0 0 0"
        rpy="0 0 0" />
      <geometry>
        <mesh
          filename="package://humanoid_arm_5dof/meshes/left_shoulder_yaw_flange.STL" />
      </geometry>
    </collision>
  </link>
  <joint
    name="left_shoulder_yaw_flange_fixture_joint"
    type="fixed">
    <origin
      xyz="0 0 0"
      rpy="0 0 0" />
    <parent
      link="left_shoulder_yaw_shaft" />
    <child
      link="left_shoulder_yaw_flange" />
    <axis
      xyz="0 0 0" />
  </joint>
  <link
    name="1220_m4x16_left_shoulder_yaw_screws">
    <inertial>
      <origin
        xyz="-2.64435695562781E-10 4.6746606585657E-11 -0.011471935608425"
        rpy="0 0 0" />
      <mass
        value="0.0014103641869818" />
      <inertia
        ixx="3.71610598568607E-08"
        ixy="-3.44158833610344E-21"
        ixz="-3.44866803408708E-17"
        iyy="3.7161059856859E-08"
        iyz="-6.82136913713098E-17"
        izz="4.58636225470959E-09" />
    </inertial>
    <visual>
      <origin
        xyz="0 0 0"
        rpy="0 0 0" />
      <geometry>
        <mesh
          filename="package://humanoid_arm_5dof/meshes/1220_m4x16_left_shoulder_yaw_screws.STL" />
      </geometry>
      <material
        name="">
        <color
          rgba="0.792156862745098 0.819607843137255 0.933333333333333 1" />
      </material>
    </visual>
    <collision>
      <origin
        xyz="0 0 0"
        rpy="0 0 0" />
      <geometry>
        <mesh
          filename="package://humanoid_arm_5dof/meshes/1220_m4x16_left_shoulder_yaw_screws.STL" />
      </geometry>
    </collision>
  </link>
  <joint
    name="1220_m4x16_left_shoulder_yaw_screws_fixture_joint"
    type="fixed">
    <origin
      xyz="0 0 0"
      rpy="0 0 0" />
    <parent
      link="left_shoulder_yaw_flange" />
    <child
      link="1220_m4x16_left_shoulder_yaw_screws" />
    <axis
      xyz="0 0 0" />
  </joint>
  <link
    name="m4x25_left_shoulder_yaw_screws">
    <inertial>
      <origin
        xyz="-6.97044977293615E-10 -1.43254785811564E-09 -0.0144289836598566"
        rpy="0 0 0" />
      <mass
        value="0.0027085820248196" />
      <inertia
        ixx="2.20903769276234E-07"
        ixy="4.52767736114267E-13"
        ixz="-2.0043820814394E-15"
        iyy="2.20904293495979E-07"
        iyz="-4.1746333514564E-15"
        izz="9.25380471510219E-09" />
    </inertial>
    <visual>
      <origin
        xyz="0 0 0"
        rpy="0 0 0" />
      <geometry>
        <mesh
          filename="package://humanoid_arm_5dof/meshes/m4x25_left_shoulder_yaw_screws.STL" />
      </geometry>
      <material
        name="">
        <color
          rgba="0.792156862745098 0.819607843137255 0.933333333333333 1" />
      </material>
    </visual>
    <collision>
      <origin
        xyz="0 0 0"
        rpy="0 0 0" />
      <geometry>
        <mesh
          filename="package://humanoid_arm_5dof/meshes/m4x25_left_shoulder_yaw_screws.STL" />
      </geometry>
    </collision>
  </link>
  <joint
    name="m4x25_left_shoulder_yaw_screws_fixture_joint"
    type="fixed">
    <origin
      xyz="0 0 0"
      rpy="0 0 0" />
    <parent
      link="1220_m4x16_left_shoulder_yaw_screws" />
    <child
      link="m4x25_left_shoulder_yaw_screws" />
    <axis
      xyz="0 0 0" />
  </joint>
  <link
    name="left_shoulder_yaw">
    <inertial>
      <origin
        xyz="-0.0276085880181826 9.90178547155551E-07 -0.0766318652062483"
        rpy="0 0 0" />
      <mass
        value="0.48806958571119" />
      <inertia
        ixx="0.00146908378466534"
        ixy="2.0772484023333E-07"
        ixz="-0.00027121480640661"
        iyy="0.00131630634257071"
        iyz="6.92128897391241E-08"
        izz="0.000811625641004684" />
    </inertial>
    <visual>
      <origin
        xyz="0 0 0"
        rpy="0 0 0" />
      <geometry>
        <mesh
          filename="package://humanoid_arm_5dof/meshes/left_shoulder_yaw.STL" />
      </geometry>
      <material
        name="">
        <color
          rgba="0.952941176470588 0.996078431372549 0.694117647058824 1" />
      </material>
    </visual>
    <collision>
      <origin
        xyz="0 0 0"
        rpy="0 0 0" />
      <geometry>
        <mesh
          filename="package://humanoid_arm_5dof/meshes/left_shoulder_yaw.STL" />
      </geometry>
    </collision>
  </link>
  <joint
    name="left_shoulder_yaw_fixture_joint"
    type="fixed">
    <origin
      xyz="0 0 0"
      rpy="0 0 0" />
    <parent
      link="m4x25_left_shoulder_yaw_screws" />
    <child
      link="left_shoulder_yaw" />
    <axis
      xyz="0 0 0" />
  </joint>
  <link
    name="m4x16_eft_elbow_screws">
    <inertial>
      <origin
        xyz="0.0203953561932368 0.041290058050647 9.01928975949318E-10"
        rpy="0 0 0" />
      <mass
        value="0.00270184358647751" />
      <inertia
        ixx="8.5307878102415E-08"
        ixy="-3.69467570052111E-08"
        ixz="-1.80714194415702E-15"
        iyy="2.87597563342944E-08"
        iyz="-3.57856808069421E-15"
        izz="1.03557847634921E-07" />
    </inertial>
    <visual>
      <origin
        xyz="0 0 0"
        rpy="0 0 0" />
      <geometry>
        <mesh
          filename="package://humanoid_arm_5dof/meshes/m4x16_eft_elbow_screws.STL" />
      </geometry>
      <material
        name="">
        <color
          rgba="0.792156862745098 0.819607843137255 0.933333333333333 1" />
      </material>
    </visual>
    <collision>
      <origin
        xyz="0 0 0"
        rpy="0 0 0" />
      <geometry>
        <mesh
          filename="package://humanoid_arm_5dof/meshes/m4x16_eft_elbow_screws.STL" />
      </geometry>
    </collision>
  </link>
  <joint
    name="m4x16_eft_elbow_screws_fixture_joint"
    type="fixed">
    <origin
      xyz="0 0 -0.0987"
      rpy="0 0 2.0296" />
    <parent
      link="left_shoulder_yaw" />
    <child
      link="m4x16_eft_elbow_screws" />
    <axis
      xyz="0 0 0" />
  </joint>
  <link
    name="left_elbow_rs03_actuator">
    <inertial>
      <origin
        xyz="0.0111097812385186 0.0224897322177018 -0.000302908482876729"
        rpy="0 0 0" />
      <mass
        value="0.35655089089686" />
      <inertia
        ixx="0.000296217970949778"
        ixy="4.22025243332798E-05"
        ixz="-2.44834222170638E-07"
        iyy="0.000360818228630538"
        iyz="-5.20600173581645E-07"
        izz="0.000270239476177119" />
    </inertial>
    <visual>
      <origin
        xyz="0 0 0"
        rpy="0 0 0" />
      <geometry>
        <mesh
          filename="package://humanoid_arm_5dof/meshes/left_elbow_rs03_actuator.STL" />
      </geometry>
      <material
        name="">
        <color
          rgba="0.823529411764706 0.823529411764706 1 1" />
      </material>
    </visual>
    <collision>
      <origin
        xyz="0 0 0"
        rpy="0 0 0" />
      <geometry>
        <mesh
          filename="package://humanoid_arm_5dof/meshes/left_elbow_rs03_actuator.STL" />
      </geometry>
    </collision>
  </link>
  <joint
    name="left_elbow_rs03_actuator_ficture_link"
    type="fixed">
    <origin
      xyz="0 0 0"
      rpy="0 0 0" />
    <parent
      link="m4x16_eft_elbow_screws" />
    <child
      link="left_elbow_rs03_actuator" />
    <axis
      xyz="0 0 0" />
  </joint>
  <link
    name="left_elbow_rs03_flange">
    <inertial>
      <origin
        xyz="-0.000556362160733848 -0.00112634315944726 -1.6931278601362E-10"
        rpy="0 0 0" />
      <mass
        value="0.00407555097398886" />
      <inertia
        ixx="6.78191701539799E-07"
        ixy="2.23735674465762E-07"
        ixz="2.3802413293789E-16"
        iyy="1.02062586837213E-06"
        iyz="4.81878340712172E-16"
        izz="5.6767674616345E-07" />
    </inertial>
    <visual>
      <origin
        xyz="0 0 0"
        rpy="0 0 0" />
      <geometry>
        <mesh
          filename="package://humanoid_arm_5dof/meshes/left_elbow_rs03_flange.STL" />
      </geometry>
      <material
        name="">
        <color
          rgba="0.823529411764706 0.823529411764706 1 1" />
      </material>
    </visual>
    <collision>
      <origin
        xyz="0 0 0"
        rpy="0 0 0" />
      <geometry>
        <mesh
          filename="package://humanoid_arm_5dof/meshes/left_elbow_rs03_flange.STL" />
      </geometry>
    </collision>
  </link>
  <joint
    name="left_elbow_rs03_joint"
    type="revolute">
    <origin
      xyz="0 0 0"
      rpy="0 0 0" />
    <parent
      link="left_elbow_rs03_actuator" />
    <child
      link="left_elbow_rs03_flange" />
    <axis
      xyz="0.44287 0.89659 0" />
    <limit
      lower="-1.3"
      upper="1.9"
      effort="60"
      velocity="1.6" />
    <safety_controller
      soft_upper_limit="3.14"
      soft_lower_limit="-3.14"
      k_velocity="0" />
  </joint>
  <link
    name="left_elbow_shaft">
    <inertial>
      <origin
        xyz="-0.514023070767117 0.0789116762990678 -0.29461265881492"
        rpy="0 0 0" />
      <mass
        value="16.3859228521728" />
      <inertia
        ixx="4.16738711607485"
        ixy="0.924028137207305"
        ixz="-3.13052393335368"
        iyy="7.10700850559293"
        iyz="1.12422208080911"
        izz="3.92149048013828" />
    </inertial>
    <visual>
      <origin
        xyz="0 0 0"
        rpy="0 0 0" />
      <geometry>
        <mesh
          filename="package://humanoid_arm_5dof/meshes/left_elbow_shaft.STL" />
      </geometry>
      <material
        name="">
        <color
          rgba="0.752941176470588 0.752941176470588 0.752941176470588 1" />
      </material>
    </visual>
    <collision>
      <origin
        xyz="0 0 0"
        rpy="0 0 0" />
      <geometry>
        <mesh
          filename="package://humanoid_arm_5dof/meshes/left_elbow_shaft.STL" />
      </geometry>
    </collision>
  </link>
  <joint
    name="left_elbow_shaft_fixture_joint"
    type="fixed">
    <origin
      xyz="0 0 0"
      rpy="0 0 0" />
    <parent
      link="left_elbow_rs03_flange" />
    <child
      link="left_elbow_shaft" />
    <axis
      xyz="0 0 0" />
  </joint>
  <link
    name="m4x25_left_elbow_screws">
    <inertial>
      <origin
        xyz="-0.00623517631130888 -0.0126230082334886 -1.57600399397495E-09"
        rpy="0 0 0" />
      <mass
        value="0.00270858033444492" />
      <inertia
        ixx="1.79392020957991E-07"
        ixy="-8.40403333110533E-08"
        ixz="-2.21301596226378E-15"
        iyy="5.07657695689575E-08"
        iyz="-4.78676431101842E-15"
        izz="2.20904014947483E-07" />
    </inertial>
    <visual>
      <origin
        xyz="0 0 0"
        rpy="0 0 0" />
      <geometry>
        <mesh
          filename="package://humanoid_arm_5dof/meshes/m4x25_left_elbow_screws.STL" />
      </geometry>
      <material
        name="">
        <color
          rgba="0.792156862745098 0.819607843137255 0.933333333333333 1" />
      </material>
    </visual>
    <collision>
      <origin
        xyz="0 0 0"
        rpy="0 0 0" />
      <geometry>
        <mesh
          filename="package://humanoid_arm_5dof/meshes/m4x25_left_elbow_screws.STL" />
      </geometry>
    </collision>
  </link>
  <joint
    name="m4x25_left_elbow_screws_fixture_joint"
    type="fixed">
    <origin
      xyz="0 0 0"
      rpy="0 0 0" />
    <parent
      link="left_elbow_shaft" />
    <child
      link="m4x25_left_elbow_screws" />
    <axis
      xyz="0 0 0" />
  </joint>
  <link
    name="left_elbow">
    <inertial>
      <origin
        xyz="-0.00117660234956452 -0.0226416977163577 -0.032359559750992"
        rpy="0 0 0" />
      <mass
        value="0.779765455664584" />
      <inertia
        ixx="0.00250248639726526"
        ixy="0.000107026092493216"
        ixz="0.000573100865707412"
        iyy="0.00291648268951669"
        iyz="0.000125954277641002"
        izz="0.000972784324400934" />
    </inertial>
    <visual>
      <origin
        xyz="0 0 0"
        rpy="0 0 0" />
      <geometry>
        <mesh
          filename="package://humanoid_arm_5dof/meshes/left_elbow.STL" />
      </geometry>
      <material
        name="">
        <color
          rgba="0.952941176470588 0.996078431372549 0.694117647058824 1" />
      </material>
    </visual>
    <collision>
      <origin
        xyz="0 0 0"
        rpy="0 0 0" />
      <geometry>
        <mesh
          filename="package://humanoid_arm_5dof/meshes/left_elbow.STL" />
      </geometry>
    </collision>
  </link>
  <joint
    name="left_elbow_fixture_joint"
    type="fixed">
    <origin
      xyz="0 0 0"
      rpy="0 0 0" />
    <parent
      link="m4x25_left_elbow_screws" />
    <child
      link="left_elbow" />
    <axis
      xyz="0 0 0" />
  </joint>
  <link
    name="m3x20_left_wrist_screws">
    <inertial>
      <origin
        xyz="-0.00322617493750421 -0.0374854483493885 0.00322632359111319"
        rpy="0 0 0" />
      <mass
        value="0.00162137028637948" />
      <inertia
        ixx="8.36724015923368E-08"
        ixy="7.10712002513376E-16"
        ixz="-1.09755048810436E-14"
        iyy="3.32920091136483E-09"
        iyz="-1.06973087931358E-13"
        izz="8.36724115121701E-08" />
    </inertial>
    <visual>
      <origin
        xyz="0 0 0"
        rpy="0 0 0" />
      <geometry>
        <mesh
          filename="package://humanoid_arm_5dof/meshes/m3x20_left_wrist_screws.STL" />
      </geometry>
      <material
        name="">
        <color
          rgba="0.792156862745098 0.819607843137255 0.933333333333333 1" />
      </material>
    </visual>
    <collision>
      <origin
        xyz="0 0 0"
        rpy="0 0 0" />
      <geometry>
        <mesh
          filename="package://humanoid_arm_5dof/meshes/m3x20_left_wrist_screws.STL" />
      </geometry>
    </collision>
  </link>
  <joint
    name="m3x20_left_wrist_screws_fixture_joint"
    type="fixed">
    <origin
      xyz="0.0370688771049235 -0.0244446769789257 -0.15848929336033"
      rpy="-1.29963611177836 0 -2.02959481544726" />
    <parent
      link="left_elbow" />
    <child
      link="m3x20_left_wrist_screws" />
    <axis
      xyz="0 0 0" />
  </joint>
  <link
    name="left_wrist_actuator">
    <inertial>
      <origin
        xyz="-3.77126108119796E-10 -0.0230138334412424 1.67783743343364E-07"
        rpy="0 0 0" />
      <mass
        value="0.180583065420556" />
      <inertia
        ixx="8.80899821792286E-05"
        ixy="-3.52831641941415E-14"
        ixz="-1.33831205666179E-19"
        iyy="0.000127000739066142"
        iyz="5.17524854351178E-11"
        izz="8.80899821792976E-05" />
    </inertial>
    <visual>
      <origin
        xyz="0 0 0"
        rpy="0 0 0" />
      <geometry>
        <mesh
          filename="package://humanoid_arm_5dof/meshes/left_wrist_actuator.STL" />
      </geometry>
      <material
        name="">
        <color
          rgba="0.823529411764706 0.823529411764706 1 1" />
      </material>
    </visual>
    <collision>
      <origin
        xyz="0 0 0"
        rpy="0 0 0" />
      <geometry>
        <mesh
          filename="package://humanoid_arm_5dof/meshes/left_wrist_actuator.STL" />
      </geometry>
    </collision>
  </link>
  <joint
    name="left_wrist_actuator_fixture_link"
    type="fixed">
    <origin
      xyz="0 0 0"
      rpy="0 0 0" />
    <parent
      link="m3x20_left_wrist_screws" />
    <child
      link="left_wrist_actuator" />
    <axis
      xyz="0 0 0" />
  </joint>
  <link
    name="left_wrist_rs02_flange">
    <inertial>
      <origin
        xyz="-4.4503589702316E-10 -0.00198993496652022 1.96181248135474E-07"
        rpy="0 0 0" />
      <mass
        value="0.00245793392108132" />
      <inertia
        ixx="1.34950766910329E-07"
        ixy="-1.16395222905286E-16"
        ixz="3.09365549094832E-22"
        iyy="2.63403217776643E-07"
        iyz="1.70845692399753E-13"
        izz="1.34950766910555E-07" />
    </inertial>
    <visual>
      <origin
        xyz="0 0 0"
        rpy="0 0 0" />
      <geometry>
        <mesh
          filename="package://humanoid_arm_5dof/meshes/left_wrist_rs02_flange.STL" />
      </geometry>
      <material
        name="">
        <color
          rgba="0.823529411764706 0.823529411764706 1 1" />
      </material>
    </visual>
    <collision>
      <origin
        xyz="0 0 0"
        rpy="0 0 0" />
      <geometry>
        <mesh
          filename="package://humanoid_arm_5dof/meshes/left_wrist_rs02_flange.STL" />
      </geometry>
    </collision>
  </link>
  <joint
    name="left_wrist_rs02_joint"
    type="revolute">
    <origin
      xyz="0 0 0"
      rpy="0 0 0" />
    <parent
      link="left_wrist_actuator" />
    <child
      link="left_wrist_rs02_flange" />
    <axis
      xyz="0 1 0" />
    <limit
      lower="-3.14"
      upper="3.14"
      effort="17"
      velocity="0.8" />
    <safety_controller
      soft_upper_limit="3.14"
      soft_lower_limit="-3.14"
      k_velocity="0" />
  </joint>
  <link
    name="m4x20_left_wrist_screws">
    <inertial>
      <origin
        xyz="3.32231431254826E-08 0.00840266504194132 2.31393215699427E-07"
        rpy="0 0 0" />
      <mass
        value="0.00232797016313311" />
      <inertia
        ixx="1.29587507987165E-07"
        ixy="-3.32257297681938E-13"
        ixz="3.13118139572589E-13"
        iyy="8.48546817348723E-09"
        iyz="-3.70996711126139E-13"
        izz="1.29587220639998E-07" />
    </inertial>
    <visual>
      <origin
        xyz="0 0 0"
        rpy="0 0 0" />
      <geometry>
        <mesh
          filename="package://humanoid_arm_5dof/meshes/m4x20_left_wrist_screws.STL" />
      </geometry>
      <material
        name="">
        <color
          rgba="0.792156862745098 0.819607843137255 0.933333333333333 1" />
      </material>
    </visual>
    <collision>
      <origin
        xyz="0 0 0"
        rpy="0 0 0" />
      <geometry>
        <mesh
          filename="package://humanoid_arm_5dof/meshes/m4x20_left_wrist_screws.STL" />
      </geometry>
    </collision>
  </link>
  <joint
    name="m4x20_left_wrist_screws_fixture_joint"
    type="fixed">
    <origin
      xyz="0 0 0"
      rpy="0 0 0" />
    <parent
      link="left_wrist_rs02_flange" />
    <child
      link="m4x20_left_wrist_screws" />
    <axis
      xyz="0 0 0" />
  </joint>
  <link
    name="left_wrist_shaft">
    <inertial>
      <origin
        xyz="-4.54187132348238E-10 0.00798511242463107 2.09448445698257E-07"
        rpy="0 0 0" />
      <mass
        value="0.000903649674373992" />
      <inertia
        ixx="4.41715688076237E-08"
        ixy="3.83890578217614E-17"
        ixz="5.29395592033938E-23"
        iyy="1.80539813303442E-09"
        iyz="-5.63483048571913E-14"
        izz="4.41715688075487E-08" />
    </inertial>
    <visual>
      <origin
        xyz="0 0 0"
        rpy="0 0 0" />
      <geometry>
        <mesh
          filename="package://humanoid_arm_5dof/meshes/left_wrist_shaft.STL" />
      </geometry>
      <material
        name="">
        <color
          rgba="0.823529411764706 0.823529411764706 1 1" />
      </material>
    </visual>
    <collision>
      <origin
        xyz="0 0 0"
        rpy="0 0 0" />
      <geometry>
        <mesh
          filename="package://humanoid_arm_5dof/meshes/left_wrist_shaft.STL" />
      </geometry>
    </collision>
  </link>
  <joint
    name="left_wrist_shaft_fixture_joint"
    type="fixed">
    <origin
      xyz="0 0 0"
      rpy="0 0 0" />
    <parent
      link="m4x20_left_wrist_screws" />
    <child
      link="left_wrist_shaft" />
    <axis
      xyz="0 0 0" />
  </joint>
  <link
    name="left_wrist">
    <inertial>
      <origin
        xyz="-0.012628431996669 0.0418086811844822 0.00594049218869808"
        rpy="0 0 0" />
      <mass
        value="0.388950905166564" />
      <inertia
        ixx="0.00083365923290049"
        ixy="0.000191177318020605"
        ixz="2.04626058625995E-06"
        iyy="0.000517833904672794"
        iyz="-8.95573257691428E-05"
        izz="0.00083896947337168" />
    </inertial>
    <visual>
      <origin
        xyz="0 0 0"
        rpy="0 0 0" />
      <geometry>
        <mesh
          filename="package://humanoid_arm_5dof/meshes/left_wrist.STL" />
      </geometry>
      <material
        name="">
        <color
          rgba="0.952941176470588 0.996078431372549 0.694117647058824 1" />
      </material>
    </visual>
    <collision>
      <origin
        xyz="0 0 0"
        rpy="0 0 0" />
      <geometry>
        <mesh
          filename="package://humanoid_arm_5dof/meshes/left_wrist.STL" />
      </geometry>
    </collision>
  </link>
  <joint
    name="left_wrist_fixture_joint"
    type="fixed">
    <origin
      xyz="0 0 0"
      rpy="0 0 0" />
    <parent
      link="left_wrist_shaft" />
    <child
      link="left_wrist" />
    <axis
      xyz="0 0 0" />
  </joint>
  <link
    name="m3x16_left_hand_screws">
    <inertial>
      <origin
        xyz="-0.0363345718033279 0.00271818004603031 0.00366475740200278"
        rpy="0 0 0" />
      <mass
        value="0.00139374174732657" />
      <inertia
        ixx="3.07153113593326E-09"
        ixy="-4.63588684731837E-15"
        ixz="-1.72957826597481E-14"
        iyy="4.88927935104815E-08"
        iyz="1.38699305440141E-16"
        izz="4.88928835911824E-08" />
    </inertial>
    <visual>
      <origin
        xyz="0 0 0"
        rpy="0 0 0" />
      <geometry>
        <mesh
          filename="package://humanoid_arm_5dof/meshes/m3x16_left_hand_screws.STL" />
      </geometry>
      <material
        name="">
        <color
          rgba="0.792156862745098 0.819607843137255 0.933333333333333 1" />
      </material>
    </visual>
    <collision>
      <origin
        xyz="0 0 0"
        rpy="0 0 0" />
      <geometry>
        <mesh
          filename="package://humanoid_arm_5dof/meshes/m3x16_left_hand_screws.STL" />
      </geometry>
    </collision>
  </link>
  <joint
    name="m3x16_left_hand_screws_fixture_joint"
    type="fixed">
    <origin
      xyz="0 0.0945 0"
      rpy="0.64485 0.44406 0" />
    <parent
      link="left_wrist" />
    <child
      link="m3x16_left_hand_screws" />
    <axis
      xyz="0 0 0" />
  </joint>
  <link
    name="left_hand_rs02">
    <inertial>
      <origin
        xyz="-0.0230139680314971 1.59886605288762E-07 2.32760471341464E-07"
        rpy="0 0 0" />
      <mass
        value="0.180583065420555" />
      <inertia
        ixx="0.000127000739066199"
        ixy="1.61715863926224E-11"
        ixz="-1.21705636308588E-11"
        iyy="8.80899821792334E-05"
        iyz="-4.87354977788967E-18"
        izz="8.80899821792305E-05" />
    </inertial>
    <visual>
      <origin
        xyz="0 0 0"
        rpy="0 0 0" />
      <geometry>
        <mesh
          filename="package://humanoid_arm_5dof/meshes/left_hand_rs02.STL" />
      </geometry>
      <material
        name="">
        <color
          rgba="0.823529411764706 0.823529411764706 1 1" />
      </material>
    </visual>
    <collision>
      <origin
        xyz="0 0 0"
        rpy="0 0 0" />
      <geometry>
        <mesh
          filename="package://humanoid_arm_5dof/meshes/left_hand_rs02.STL" />
      </geometry>
    </collision>
  </link>
  <joint
    name="left_hand_rs02_fixture_link"
    type="fixed">
    <origin
      xyz="0 0 0"
      rpy="0 0 0" />
    <parent
      link="m3x16_left_hand_screws" />
    <child
      link="left_hand_rs02" />
    <axis
      xyz="0 0 0" />
  </joint>
  <link
    name="left_hand_rs02_flange">
    <inertial>
      <origin
        xyz="-0.00201019993593277 1.68615926554594E-07 2.26190866259302E-07"
        rpy="0 0 0" />
      <mass
        value="0.0024579339210813" />
      <inertia
        ixx="2.63403217776834E-07"
        ixy="5.33858254342926E-14"
        ixz="-4.01775960873127E-14"
        iyy="1.34950766910349E-07"
        iyz="-1.71418184964277E-20"
        izz="1.3495076691034E-07" />
    </inertial>
    <visual>
      <origin
        xyz="0 0 0"
        rpy="0 0 0" />
      <geometry>
        <mesh
          filename="package://humanoid_arm_5dof/meshes/left_hand_rs02_flange.STL" />
      </geometry>
      <material
        name="">
        <color
          rgba="0.823529411764706 0.823529411764706 1 1" />
      </material>
    </visual>
    <collision>
      <origin
        xyz="0 0 0"
        rpy="0 0 0" />
      <geometry>
        <mesh
          filename="package://humanoid_arm_5dof/meshes/left_hand_rs02_flange.STL" />
      </geometry>
    </collision>
  </link>
  <joint
    name="left_hand_rs02_joint"
    type="revolute">
    <origin
      xyz="0 0 0"
      rpy="0 0 0" />
    <parent
      link="left_hand_rs02" />
    <child
      link="left_hand_rs02_flange" />
    <axis
      xyz="1 0 0" />
    <limit
      lower="-1.5"
      upper="1.7"
      effort="17"
      velocity="0.8" />
    <safety_controller
      soft_upper_limit="1.7"
      soft_lower_limit="-1.5"
      k_velocity="0" />
  </joint>
  <link
    name="left_hand">
    <inertial>
      <origin
        xyz="0.0119773759214538 0.0114767014118771 -0.0111415074327191"
        rpy="0 0 0" />
      <mass
        value="0.285530151595695" />
      <inertia
        ixx="0.000354627427730649"
        ixy="1.61689467822956E-05"
        ixz="-1.60211594472004E-05"
        iyy="0.000247513336377023"
        iyz="3.07040256530212E-05"
        izz="0.000247329108795639" />
    </inertial>
    <visual>
      <origin
        xyz="0 0 0"
        rpy="0 0 0" />
      <geometry>
        <mesh
          filename="package://humanoid_arm_5dof/meshes/left_hand.STL" />
      </geometry>
      <material
        name="">
        <color
          rgba="0.952941176470588 0.996078431372549 0.694117647058824 1" />
      </material>
    </visual>
    <collision>
      <origin
        xyz="0 0 0"
        rpy="0 0 0" />
      <geometry>
        <mesh
          filename="package://humanoid_arm_5dof/meshes/left_hand.STL" />
      </geometry>
    </collision>
  </link>
  <joint
    name="left_hand_fixture_joint"
    type="fixed">
    <origin
      xyz="0 0 0"
      rpy="0 0 0" />
    <parent
      link="left_hand_rs02_flange" />
    <child
      link="left_hand" />
    <axis
      xyz="0 0 0" />
  </joint>
</robot>