<?xml version="1.0" encoding="utf-8"?>
<!-- This URDF was automatically created by SolidWorks to URDF Exporter! Originally created by Stephen Brawner (brawner@gmail.com) 
     Commit Version: 1.6.0-4-g7f85cfe  Build Version: 1.6.7995.38578
     For more information, please see http://wiki.ros.org/sw_urdf_exporter -->
<robot
  name="urdf brat stang 7">
  <link
    name="base_fixture_link">
    <inertial>
      <origin
        xyz="-0.30933 -0.17963 -0.83636"
        rpy="0 0 0" />
      <mass
        value="400" />
      <inertia
        ixx="1.5338"
        ixy="-0.024766"
        ixz="-0.16927"
        iyy="1.5621"
        iyz="-0.098299"
        izz="0.18464" />
    </inertial>
    <visual>
      <origin
        xyz="0 0 0"
        rpy="0 0 0" />
      <geometry>
        <mesh
          filename="package://urdf brat stang 7/meshes/base_fixture_link.STL" />
      </geometry>
      <material
        name="">
        <color
          rgba="0.82353 0.82353 1 1" />
      </material>
    </visual>
    <collision>
      <origin
        xyz="0 0 0"
        rpy="0 0 0" />
      <geometry>
        <mesh
          filename="package://urdf brat stang 7/meshes/base_fixture_link.STL" />
      </geometry>
    </collision>
  </link>
  <link
    name="left_shoulder_pitch_rs04_actuator">
    <inertial>
      <origin
        xyz="-0.0212144936357581 -0.0123197061496141 -1.4773737788687E-12"
        rpy="0 0 0" />
      <mass
        value="0.517423577893353" />
      <inertia
        ixx="0.000791281929906339"
        ixy="0.000146596403770864"
        ixz="1.04334286421383E-06"
        iyy="0.000623975041966309"
        iyz="-1.79663299480508E-06"
        izz="0.000544725741611065" />
    </inertial>
    <visual>
      <origin
        xyz="0 0 0"
        rpy="0 0 0" />
      <geometry>
        <mesh
          filename="package://urdf brat stang 7/meshes/left_shoulder_pitch_rs04_actuator.STL" />
      </geometry>
      <material
        name="">
        <color
          rgba="0.823529411764706 0.823529411764706 1 1" />
      </material>
    </visual>
    <collision>
      <origin
        xyz="0 0 0"
        rpy="0 0 0" />
      <geometry>
        <mesh
          filename="package://urdf brat stang 7/meshes/left_shoulder_pitch_rs04_actuator.STL" />
      </geometry>
    </collision>
  </link>
  <joint
    name="left_shoulder_pitch_rs04_actuator_fixture_link"
    type="fixed">
    <origin
      xyz="0 0 0"
      rpy="0 0 0" />
    <parent
      link="base_fixture_link" />
    <child
      link="left_shoulder_pitch_rs04_actuator" />
    <axis
      xyz="0 0 0" />
  </joint>
  <link
    name="left_shoulder_pitch_rs04_flange">
    <inertial>
      <origin
        xyz="-0.00160023400776765 -0.00100669949731991 7.29307138803703E-05"
        rpy="0 0 0" />
      <mass
        value="0.00758352122244494" />
      <inertia
        ixx="2.06768924459384E-06"
        ixy="5.07332578299122E-07"
        ixz="-2.28963593554678E-21"
        iyy="1.48868298903532E-06"
        iyz="-1.7205356741103E-22"
        izz="1.19406420659582E-06" />
    </inertial>
    <visual>
      <origin
        xyz="0 0 0"
        rpy="0 0 0" />
      <geometry>
        <mesh
          filename="package://urdf brat stang 7/meshes/left_shoulder_pitch_rs04_flange.STL" />
      </geometry>
      <material
        name="">
        <color
          rgba="0.823529411764706 0.823529411764706 1 1" />
      </material>
    </visual>
    <collision>
      <origin
        xyz="0 0 0"
        rpy="0 0 0" />
      <geometry>
        <mesh
          filename="package://urdf brat stang 7/meshes/left_shoulder_pitch_rs04_flange.STL" />
      </geometry>
    </collision>
  </link>
  <joint
    name="left_shoulder_pitch_rs04_flange_joint"
    type="revolute">
    <origin
      xyz="0 0 0"
      rpy="0 0 0" />
    <parent
      link="left_shoulder_pitch_rs04_actuator" />
    <child
      link="left_shoulder_pitch_rs04_flange" />
    <axis
      xyz="0.864760392474123 0.502184690734396 0" />
    <limit
      lower="-3.14"
      upper="3.14"
      effort="120"
      velocity="3" />
    <safety_controller
      soft_upper_limit="3.14"
      soft_lower_limit="-3.14"
      k_velocity="0" />
  </joint>
  <link
    name="m5x22_screws_left_shoulder_pitch">
    <inertial>
      <origin
        xyz="0.00721932653725377 0.000299723766531201 0.00365316139893568"
        rpy="0 0 0" />
      <mass
        value="0.00474644340626585" />
      <inertia
        ixx="1.03394680133485E-07"
        ixy="-1.32206926832093E-07"
        ixz="-2.76565465658249E-13"
        iyy="2.54278723556555E-07"
        iyz="2.77265718511042E-13"
        izz="3.31054378599859E-07" />
    </inertial>
    <visual>
      <origin
        xyz="0 0 0"
        rpy="0 0 0" />
      <geometry>
        <mesh
          filename="package://urdf brat stang 7/meshes/m5x22_screws_left_shoulder_pitch.STL" />
      </geometry>
      <material
        name="">
        <color
          rgba="0.792156862745098 0.819607843137255 0.933333333333333 1" />
      </material>
    </visual>
    <collision>
      <origin
        xyz="0 0 0"
        rpy="0 0 0" />
      <geometry>
        <mesh
          filename="package://urdf brat stang 7/meshes/m5x22_screws_left_shoulder_pitch.STL" />
      </geometry>
    </collision>
  </link>
  <joint
    name="m5x22_screws_left_shoulder_pitch_fixture_joint"
    type="fixed">
    <origin
      xyz="0 0 0"
      rpy="0 0 0" />
    <parent
      link="left_shoulder_pitch_rs04_flange" />
    <child
      link="m5x22_screws_left_shoulder_pitch" />
    <axis
      xyz="0 0 0" />
  </joint>
  <link
    name="left_shoulder_pitch">
    <inertial>
      <origin
        xyz="0.0422379184792105 0.0631675726295917 -0.021162469711781"
        rpy="0 0 0" />
      <mass
        value="1.19772099744743" />
      <inertia
        ixx="0.00533841544478267"
        ixy="-0.00181737265176679"
        ixz="0.000735956231723286"
        iyy="0.00421467724838482"
        iyz="0.000482895979159517"
        izz="0.00612223849669078" />
    </inertial>
    <visual>
      <origin
        xyz="0 0 0"
        rpy="0 0 0" />
      <geometry>
        <mesh
          filename="package://urdf brat stang 7/meshes/left_shoulder_pitch.STL" />
      </geometry>
      <material
        name="">
        <color
          rgba="0.952941176470588 0.996078431372549 0.694117647058824 1" />
      </material>
    </visual>
    <collision>
      <origin
        xyz="0 0 0"
        rpy="0 0 0" />
      <geometry>
        <mesh
          filename="package://urdf brat stang 7/meshes/left_shoulder_pitch.STL" />
      </geometry>
    </collision>
  </link>
  <joint
    name="left_shoulder_pitch_fixture_joint"
    type="fixed">
    <origin
      xyz="0 0 0"
      rpy="0 0 0" />
    <parent
      link="m5x22_screws_left_shoulder_pitch" />
    <child
      link="left_shoulder_pitch" />
    <axis
      xyz="0 0 0" />
  </joint>
  <link
    name="m5x22_screws_left_shoulder_roll">
    <inertial>
      <origin
        xyz="5.12752764351143E-05 -0.0128935045048073 5.12072378634487E-05"
        rpy="0 0 0" />
      <mass
        value="0.00610257053905764" />
      <inertia
        ixx="4.25641380807002E-07"
        ixy="1.38655679975827E-13"
        ixz="-4.65295401727222E-13"
        iyy="3.42246799589694E-08"
        iyz="-2.63052839856934E-13"
        izz="4.25641102603519E-07" />
    </inertial>
    <visual>
      <origin
        xyz="0 0 0"
        rpy="0 0 0" />
      <geometry>
        <mesh
          filename="package://urdf brat stang 7/meshes/m5x22_screws_left_shoulder_roll.STL" />
      </geometry>
      <material
        name="">
        <color
          rgba="0.792156862745098 0.819607843137255 0.933333333333333 1" />
      </material>
    </visual>
    <collision>
      <origin
        xyz="0 0 0"
        rpy="0 0 0" />
      <geometry>
        <mesh
          filename="package://urdf brat stang 7/meshes/m5x22_screws_left_shoulder_roll.STL" />
      </geometry>
    </collision>
  </link>
  <joint
    name="m5x22_screws_left_shoulder_roll_fixture_joint"
    type="fixed">
    <origin
      xyz="0.0803272260170873 0.0942116090989131 -0.0260749219194687"
      rpy="0.564448515429829 0 -2.61546937197944" />
    <parent
      link="left_shoulder_pitch" />
    <child
      link="m5x22_screws_left_shoulder_roll" />
    <axis
      xyz="0 0 0" />
  </joint>
  <link
    name="left_shoulder_roll_rs04_flange">
    <inertial>
      <origin
        xyz="-4.16333634234434E-14 -0.00211063193642413 6.38313846224037E-11"
        rpy="0 0 0" />
      <mass
        value="0.00758352122244508" />
      <inertia
        ixx="1.19406420659584E-06"
        ixy="-1.12430388858208E-20"
        ixz="1.48230765769503E-21"
        iyy="2.36230802703339E-06"
        iyz="-1.48200182586151E-15"
        izz="1.19406420659585E-06" />
    </inertial>
    <visual>
      <origin
        xyz="0 0 0"
        rpy="0 0 0" />
      <geometry>
        <mesh
          filename="package://urdf brat stang 7/meshes/left_shoulder_roll_rs04_flange.STL" />
      </geometry>
      <material
        name="">
        <color
          rgba="0.823529411764706 0.823529411764706 1 1" />
      </material>
    </visual>
    <collision>
      <origin
        xyz="0 0 0"
        rpy="0 0 0" />
      <geometry>
        <mesh
          filename="package://urdf brat stang 7/meshes/left_shoulder_roll_rs04_flange.STL" />
      </geometry>
    </collision>
  </link>
  <joint
    name="left_shoulder_roll_rs04_flange_joint"
    type="fixed">
    <origin
      xyz="0 0 0"
      rpy="0 0 0" />
    <parent
      link="m5x22_screws_left_shoulder_roll" />
    <child
      link="left_shoulder_roll_rs04_flange" />
    <axis
      xyz="0 0 0" />
  </joint>
  <link
    name="left_shoulder_roll_rs04_actuator">
    <inertial>
      <origin
        xyz="7.54312758008968E-05 0.0205322216645349 2.70558418999922E-05"
        rpy="0 0 0" />
      <mass
        value="0.517423577893356" />
      <inertia
        ixx="0.000542006962748033"
        ixy="-4.59109475697134E-15"
        ixz="-3.59408880621049E-06"
        iyy="0.000876413569064535"
        iyz="-4.24937943990442E-13"
        izz="0.000541562181671229" />
    </inertial>
    <visual>
      <origin
        xyz="0 0 0"
        rpy="0 0 0" />
      <geometry>
        <mesh
          filename="package://urdf brat stang 7/meshes/left_shoulder_roll_rs04_actuator.STL" />
      </geometry>
      <material
        name="">
        <color
          rgba="0.823529411764706 0.823529411764706 1 1" />
      </material>
    </visual>
    <collision>
      <origin
        xyz="0 0 0"
        rpy="0 0 0" />
      <geometry>
        <mesh
          filename="package://urdf brat stang 7/meshes/left_shoulder_roll_rs04_actuator.STL" />
      </geometry>
    </collision>
  </link>
  <joint
    name="left_shoulder_roll_rs04_actuator_fixture_link"
    type="revolute">
    <origin
      xyz="0 0 0"
      rpy="0 0 0" />
    <parent
      link="left_shoulder_roll_rs04_flange" />
    <child
      link="left_shoulder_roll_rs04_actuator" />
    <axis
      xyz="0 -1 0" />
    <limit
      lower="-3.5"
      upper="0.6"
      effort="120"
      velocity="3" />
    <safety_controller
      soft_upper_limit="3.14"
      soft_lower_limit="-3.14"
      k_velocity="0" />
  </joint>
  <link
    name="m4x25_left_shoulder_screws_roll">
    <inertial>
      <origin
        xyz="5.45041063610974E-05 0.0496289837028789 5.40653513856348E-05"
        rpy="0 0 0" />
      <mass
        value="0.00451430348886334" />
      <inertia
        ixx="3.68173387240364E-07"
        ixy="-6.77491733962292E-15"
        ixz="6.50698948799655E-17"
        iyy="1.54230097659285E-08"
        iyz="-3.94880986289279E-17"
        izz="3.68173386339827E-07" />
    </inertial>
    <visual>
      <origin
        xyz="0 0 0"
        rpy="0 0 0" />
      <geometry>
        <mesh
          filename="package://urdf brat stang 7/meshes/m4x25_left_shoulder_screws_roll.STL" />
      </geometry>
      <material
        name="">
        <color
          rgba="0.792156862745098 0.819607843137255 0.933333333333333 1" />
      </material>
    </visual>
    <collision>
      <origin
        xyz="0 0 0"
        rpy="0 0 0" />
      <geometry>
        <mesh
          filename="package://urdf brat stang 7/meshes/m4x25_left_shoulder_screws_roll.STL" />
      </geometry>
    </collision>
  </link>
  <joint
    name="m4x25_left_shoulder_screws_roll_fixture_joint"
    type="fixed">
    <origin
      xyz="0 0 0"
      rpy="0 0 0" />
    <parent
      link="left_shoulder_roll_rs04_actuator" />
    <child
      link="m4x25_left_shoulder_screws_roll" />
    <axis
      xyz="0 0 0" />
  </joint>
  <link
    name="left_shoulder_roll">
    <inertial>
      <origin
        xyz="-0.00752228686656664 0.0497547008472168 -0.055681167948436"
        rpy="0 0 0" />
      <mass
        value="0.997620688400226" />
      <inertia
        ixx="0.00534467265132067"
        ixy="-8.46143392882667E-05"
        ixz="-0.000430210471278774"
        iyy="0.00591903784346482"
        iyz="-0.000640722357597432"
        izz="0.00178281861079861" />
    </inertial>
    <visual>
      <origin
        xyz="0 0 0"
        rpy="0 0 0" />
      <geometry>
        <mesh
          filename="package://urdf brat stang 7/meshes/left_shoulder_roll.STL" />
      </geometry>
      <material
        name="">
        <color
          rgba="0.952941176470588 0.996078431372549 0.694117647058824 1" />
      </material>
    </visual>
    <collision>
      <origin
        xyz="0 0 0"
        rpy="0 0 0" />
      <geometry>
        <mesh
          filename="package://urdf brat stang 7/meshes/left_shoulder_roll.STL" />
      </geometry>
    </collision>
  </link>
  <joint
    name="left_shoulde_roll_fixture_joint"
    type="fixed">
    <origin
      xyz="0 0 0"
      rpy="0 0 0" />
    <parent
      link="m4x25_left_shoulder_screws_roll" />
    <child
      link="left_shoulder_roll" />
    <axis
      xyz="0 0 0" />
  </joint>
  <link
    name="m4x16_left_shoulder_yaw_screws">
    <inertial>
      <origin
        xyz="2.94195667827069E-10 6.28038065997316E-10 0.0451525729602269"
        rpy="0 0 0" />
      <mass
        value="0.00270184474693412" />
      <inertia
        ixx="1.0355785748527E-07"
        ixy="1.55850036199955E-16"
        ixz="-1.87732105419708E-15"
        iyy="1.03557857737459E-07"
        iyz="-3.9263557482072E-15"
        izz="1.05098007898703E-08" />
    </inertial>
    <visual>
      <origin
        xyz="0 0 0"
        rpy="0 0 0" />
      <geometry>
        <mesh
          filename="package://urdf brat stang 7/meshes/m4x16_left_shoulder_yaw_screws.STL" />
      </geometry>
      <material
        name="">
        <color
          rgba="0.792156862745098 0.819607843137255 0.933333333333333 1" />
      </material>
    </visual>
    <collision>
      <origin
        xyz="0 0 0"
        rpy="0 0 0" />
      <geometry>
        <mesh
          filename="package://urdf brat stang 7/meshes/m4x16_left_shoulder_yaw_screws.STL" />
      </geometry>
    </collision>
  </link>
  <joint
    name="m4x16_left_shoulder_yaw_screws_fixture_joint"
    type="fixed">
    <origin
      xyz="-0.0219716026665047 0.037700000000231 -0.173578614834026"
      rpy="0.0571232457871902 0.112571265320765 0.47087557604578" />
    <parent
      link="left_shoulder_roll" />
    <child
      link="m4x16_left_shoulder_yaw_screws" />
    <axis
      xyz="0 0 0" />
  </joint>
  <link
    name="left_shoulder_yaw_rs03_actuator">
    <inertial>
      <origin
        xyz="-0.000137350498326194 -0.000269996793656357 0.025084165158858"
        rpy="0 0 0" />
      <mass
        value="0.356550969588107" />
      <inertia
        ixx="0.000274320425081703"
        ixy="-2.07349930512738E-06"
        ixz="-2.5625369963248E-07"
        iyy="0.000271291938182678"
        iyz="-5.1492485379041E-07"
        izz="0.000381662133736491" />
    </inertial>
    <visual>
      <origin
        xyz="0 0 0"
        rpy="0 0 0" />
      <geometry>
        <mesh
          filename="package://urdf brat stang 7/meshes/left_shoulder_yaw_rs03_actuator.STL" />
      </geometry>
      <material
        name="">
        <color
          rgba="0.823529411764706 0.823529411764706 1 1" />
      </material>
    </visual>
    <collision>
      <origin
        xyz="0 0 0"
        rpy="0 0 0" />
      <geometry>
        <mesh
          filename="package://urdf brat stang 7/meshes/left_shoulder_yaw_rs03_actuator.STL" />
      </geometry>
    </collision>
  </link>
  <joint
    name="left_shoulder_yaw_rs03_actuator_fixture_link"
    type="fixed">
    <origin
      xyz="0 0 0"
      rpy="0 0 0" />
    <parent
      link="m4x16_left_shoulder_yaw_screws" />
    <child
      link="left_shoulder_yaw_rs03_actuator" />
    <axis
      xyz="0 0 0" />
  </joint>
  <link
    name="left_shoulder_yaw_rs03_flange">
    <inertial>
      <origin
        xyz="-1.01978425703919E-10 -1.98439042975451E-10 -0.00125625968589538"
        rpy="0 0 0" />
      <mass
        value="0.00407555097398888" />
      <inertia
        ixx="5.67676746163448E-07"
        ixy="-2.84550130718242E-22"
        ixz="3.78701346742632E-16"
        iyy="5.6767674616345E-07"
        iyz="7.48770296169664E-16"
        izz="1.13114082374848E-06" />
    </inertial>
    <visual>
      <origin
        xyz="0 0 0"
        rpy="0 0 0" />
      <geometry>
        <mesh
          filename="package://urdf brat stang 7/meshes/left_shoulder_yaw_rs03_flange.STL" />
      </geometry>
      <material
        name="">
        <color
          rgba="0.823529411764706 0.823529411764706 1 1" />
      </material>
    </visual>
    <collision>
      <origin
        xyz="0 0 0"
        rpy="0 0 0" />
      <geometry>
        <mesh
          filename="package://urdf brat stang 7/meshes/left_shoulder_yaw_rs03_flange.STL" />
      </geometry>
    </collision>
  </link>
  <joint
    name="left_shoulder_yaw_rs03_flange_joint"
    type="revolute">
    <origin
      xyz="0 0 0"
      rpy="0 0 0" />
    <parent
      link="left_shoulder_yaw_rs03_actuator" />
    <child
      link="left_shoulder_yaw_rs03_flange" />
    <axis
      xyz="0 0 1" />
    <limit
      lower="-3.14"
      upper="3.14"
      effort="60"
      velocity="1.6" />
    <safety_controller
      soft_upper_limit="3.14"
      soft_lower_limit="-3.14"
      k_velocity="0" />
  </joint>
  <link
    name="left_shoulder_yaw_shaft">
    <inertial>
      <origin
        xyz="-1.12223230708253E-10 -2.13622897149435E-10 -0.0119851125677803"
        rpy="0 0 0" />
      <mass
        value="0.000903649674373974" />
      <inertia
        ixx="4.41715688076217E-08"
        ixy="-3.92910790962688E-24"
        ixz="-2.84740481585426E-17"
        iyy="4.41715688076217E-08"
        iyz="-5.6299203047211E-17"
        izz="1.80539813295945E-09" />
    </inertial>
    <visual>
      <origin
        xyz="0 0 0"
        rpy="0 0 0" />
      <geometry>
        <mesh
          filename="package://urdf brat stang 7/meshes/left_shoulder_yaw_shaft.STL" />
      </geometry>
      <material
        name="">
        <color
          rgba="0.823529411764706 0.823529411764706 1 1" />
      </material>
    </visual>
    <collision>
      <origin
        xyz="0 0 0"
        rpy="0 0 0" />
      <geometry>
        <mesh
          filename="package://urdf brat stang 7/meshes/left_shoulder_yaw_shaft.STL" />
      </geometry>
    </collision>
  </link>
  <joint
    name="left_shoulder_yaw_shaft_fixture_joint"
    type="continuous">
    <origin
      xyz="0 0 0"
      rpy="0 0 0" />
    <parent
      link="left_shoulder_yaw_rs03_flange" />
    <child
      link="left_shoulder_yaw_shaft" />
    <axis
      xyz="0 0 1" />
    <limit
      lower="0"
      upper="0"
      effort="0"
      velocity="0" />
  </joint>
  <link
    name="left_shoulder_yaw_flange">
    <inertial>
      <origin
        xyz="-1.06492481499743E-10 -2.03767225315232E-10 -0.00898037826805287"
        rpy="0 0 0" />
      <mass
        value="0.0353531461099521" />
      <inertia
        ixx="9.85459914704043E-06"
        ixy="-7.54070449341709E-08"
        ixz="6.41250564941296E-15"
        iyy="9.59337705819639E-06"
        iyz="1.16833579520226E-14"
        izz="1.87117812635895E-05" />
    </inertial>
    <visual>
      <origin
        xyz="0 0 0"
        rpy="0 0 0" />
      <geometry>
        <mesh
          filename="package://urdf brat stang 7/meshes/left_shoulder_yaw_flange.STL" />
      </geometry>
      <material
        name="">
        <color
          rgba="0.952941176470588 0.996078431372549 0.694117647058824 1" />
      </material>
    </visual>
    <collision>
      <origin
        xyz="0 0 0"
        rpy="0 0 0" />
      <geometry>
        <mesh
          filename="package://urdf brat stang 7/meshes/left_shoulder_yaw_flange.STL" />
      </geometry>
    </collision>
  </link>
  <joint
    name="left_shoulder_yaw_flange_fixture_joint"
    type="fixed">
    <origin
      xyz="0 0 0"
      rpy="0 0 0" />
    <parent
      link="left_shoulder_yaw_shaft" />
    <child
      link="left_shoulder_yaw_flange" />
    <axis
      xyz="0 0 0" />
  </joint>
  <link
    name="1220_m4x16_left_shoulder_yaw_screws">
    <inertial>
      <origin
        xyz="-1.91902826962576E-10 1.89071425182874E-10 -0.0114719356178909"
        rpy="0 0 0" />
      <mass
        value="0.00141036418698186" />
      <inertia
        ixx="3.71610598568626E-08"
        ixy="-3.45234168406663E-21"
        ixz="-2.18969719919941E-17"
        iyy="3.71610598568608E-08"
        iyz="-4.32794460181838E-17"
        izz="4.58636225471012E-09" />
    </inertial>
    <visual>
      <origin
        xyz="0 0 0"
        rpy="0 0 0" />
      <geometry>
        <mesh
          filename="package://urdf brat stang 7/meshes/1220_m4x16_left_shoulder_yaw_screws.STL" />
      </geometry>
      <material
        name="">
        <color
          rgba="0.792156862745098 0.819607843137255 0.933333333333333 1" />
      </material>
    </visual>
    <collision>
      <origin
        xyz="0 0 0"
        rpy="0 0 0" />
      <geometry>
        <mesh
          filename="package://urdf brat stang 7/meshes/1220_m4x16_left_shoulder_yaw_screws.STL" />
      </geometry>
    </collision>
  </link>
  <joint
    name="1220_m4x16_left_shoulder_yaw_screws_fixture_joint"
    type="fixed">
    <origin
      xyz="0 0 0"
      rpy="0 0 0" />
    <parent
      link="left_shoulder_yaw_flange" />
    <child
      link="1220_m4x16_left_shoulder_yaw_screws" />
    <axis
      xyz="0 0 0" />
  </joint>
  <link
    name="m4x25_left_shoulder_yaw_screws">
    <inertial>
      <origin
        xyz="-6.22595752730604E-10 -1.28815313971131E-09 -0.0144289836693576"
        rpy="0 0 0" />
      <mass
        value="0.00270858202481973" />
      <inertia
        ixx="2.20903769276245E-07"
        ixy="4.52767736097723E-13"
        ixz="-1.92256851928136E-15"
        iyy="2.20904293495989E-07"
        iyz="-4.01263024272767E-15"
        izz="9.25380471510248E-09" />
    </inertial>
    <visual>
      <origin
        xyz="0 0 0"
        rpy="0 0 0" />
      <geometry>
        <mesh
          filename="package://urdf brat stang 7/meshes/m4x25_left_shoulder_yaw_screws.STL" />
      </geometry>
      <material
        name="">
        <color
          rgba="0.792156862745098 0.819607843137255 0.933333333333333 1" />
      </material>
    </visual>
    <collision>
      <origin
        xyz="0 0 0"
        rpy="0 0 0" />
      <geometry>
        <mesh
          filename="package://urdf brat stang 7/meshes/m4x25_left_shoulder_yaw_screws.STL" />
      </geometry>
    </collision>
  </link>
  <joint
    name="m4x25_left_shoulder_yaw_screws_fixture_joint"
    type="fixed">
    <origin
      xyz="0 0 0"
      rpy="0 0 0" />
    <parent
      link="1220_m4x16_left_shoulder_yaw_screws" />
    <child
      link="m4x25_left_shoulder_yaw_screws" />
    <axis
      xyz="0 0 0" />
  </joint>
  <link
    name="left_shoulder_yaw">
    <inertial>
      <origin
        xyz="-0.02760855105879 1.01214308401154E-06 -0.0766319307621743"
        rpy="0 0 0" />
      <mass
        value="0.488068654983253" />
      <inertia
        ixx="0.00146908224189927"
        ixy="2.07765822094386E-07"
        ixz="-0.000271215897289947"
        iyy="0.00131630379047291"
        iyz="6.9108854864171E-08"
        izz="0.000811624952993794" />
    </inertial>
    <visual>
      <origin
        xyz="0 0 0"
        rpy="0 0 0" />
      <geometry>
        <mesh
          filename="package://urdf brat stang 7/meshes/left_shoulder_yaw.STL" />
      </geometry>
      <material
        name="">
        <color
          rgba="0.952941176470588 0.996078431372549 0.694117647058824 1" />
      </material>
    </visual>
    <collision>
      <origin
        xyz="0 0 0"
        rpy="0 0 0" />
      <geometry>
        <mesh
          filename="package://urdf brat stang 7/meshes/left_shoulder_yaw.STL" />
      </geometry>
    </collision>
  </link>
  <joint
    name="left_shoulder_yaw_fixture_joint"
    type="fixed">
    <origin
      xyz="0 0 0"
      rpy="0 0 0" />
    <parent
      link="m4x25_left_shoulder_yaw_screws" />
    <child
      link="left_shoulder_yaw" />
    <axis
      xyz="0 0 0" />
  </joint>
  <link
    name="m4x16_eft_elbow_screws">
    <inertial>
      <origin
        xyz="0.0203953563270431 0.0412900578652691 8.74640360137846E-10"
        rpy="0 0 0" />
      <mass
        value="0.00270184358647762" />
      <inertia
        ixx="8.53078781134226E-08"
        ixy="-3.69467569967935E-08"
        ixz="-1.79121241755783E-15"
        iyy="2.87597563232936E-08"
        iyz="-3.5463190250719E-15"
        izz="1.03557847634927E-07" />
    </inertial>
    <visual>
      <origin
        xyz="0 0 0"
        rpy="0 0 0" />
      <geometry>
        <mesh
          filename="package://urdf brat stang 7/meshes/m4x16_eft_elbow_screws.STL" />
      </geometry>
      <material
        name="">
        <color
          rgba="0.792156862745098 0.819607843137255 0.933333333333333 1" />
      </material>
    </visual>
    <collision>
      <origin
        xyz="0 0 0"
        rpy="0 0 0" />
      <geometry>
        <mesh
          filename="package://urdf brat stang 7/meshes/m4x16_eft_elbow_screws.STL" />
      </geometry>
    </collision>
  </link>
  <joint
    name="m4x16_eft_elbow_screws_fixture_joint"
    type="fixed">
    <origin
      xyz="0 0 -0.0987000004167595"
      rpy="0 0 2.02959481544726" />
    <parent
      link="left_shoulder_yaw" />
    <child
      link="m4x16_eft_elbow_screws" />
    <axis
      xyz="0 0 0" />
  </joint>
  <link
    name="left_elbow_rs03_actuator">
    <inertial>
      <origin
        xyz="0.0111097813753016 0.02248973203071 -0.000302908501975452"
        rpy="0 0 0" />
      <mass
        value="0.356550890896862" />
      <inertia
        ixx="0.000296217970937463"
        ixy="4.22025243237621E-05"
        ixz="-2.44834237646248E-07"
        iyy="0.000360818228642397"
        iyz="-5.20600213977642E-07"
        izz="0.000270239476177585" />
    </inertial>
    <visual>
      <origin
        xyz="0 0 0"
        rpy="0 0 0" />
      <geometry>
        <mesh
          filename="package://urdf brat stang 7/meshes/left_elbow_rs03_actuator.STL" />
      </geometry>
      <material
        name="">
        <color
          rgba="0.823529411764706 0.823529411764706 1 1" />
      </material>
    </visual>
    <collision>
      <origin
        xyz="0 0 0"
        rpy="0 0 0" />
      <geometry>
        <mesh
          filename="package://urdf brat stang 7/meshes/left_elbow_rs03_actuator.STL" />
      </geometry>
    </collision>
  </link>
  <joint
    name="left_elbow_rs03_actuator_ficture_link"
    type="fixed">
    <origin
      xyz="0 0 0"
      rpy="0 0 0" />
    <parent
      link="m4x16_eft_elbow_screws" />
    <child
      link="left_elbow_rs03_actuator" />
    <axis
      xyz="0 0 0" />
  </joint>
  <link
    name="left_elbow_rs03_flange">
    <inertial>
      <origin
        xyz="-0.000556362020586842 -0.00112634334796891 -1.78221659652422E-10"
        rpy="0 0 0" />
      <mass
        value="0.0040755509739889" />
      <inertia
        ixx="6.7819170147317E-07"
        ixy="2.23735674414772E-07"
        ixz="1.41560844531018E-16"
        iyy="1.02062586843876E-06"
        iyz="2.86592499207639E-16"
        izz="5.6767674616345E-07" />
    </inertial>
    <visual>
      <origin
        xyz="0 0 0"
        rpy="0 0 0" />
      <geometry>
        <mesh
          filename="package://urdf brat stang 7/meshes/left_elbow_rs03_flange.STL" />
      </geometry>
      <material
        name="">
        <color
          rgba="0.823529411764706 0.823529411764706 1 1" />
      </material>
    </visual>
    <collision>
      <origin
        xyz="0 0 0"
        rpy="0 0 0" />
      <geometry>
        <mesh
          filename="package://urdf brat stang 7/meshes/left_elbow_rs03_flange.STL" />
      </geometry>
    </collision>
  </link>
  <joint
    name="left_elbow_rs03_flange_joint"
    type="revolute">
    <origin
      xyz="0 0 0"
      rpy="0 0 0" />
    <parent
      link="left_elbow_rs03_actuator" />
    <child
      link="left_elbow_rs03_flange" />
    <axis
      xyz="0.442871169532449 0.896585259301624 0" />
    <limit
      lower="-1.3"
      upper="1.9"
      effort="60"
      velocity="1.6" />
    <safety_controller
      soft_upper_limit="3.14"
      soft_lower_limit="-3.14"
      k_velocity="0" />
  </joint>
  <link
    name="left_elbow_shaft">
    <inertial>
      <origin
        xyz="-0.426183551554712 0.00226691613099916 -0.176826619351449"
        rpy="0 0 0" />
      <mass
        value="15.7008025632262" />
      <inertia
        ixx="2.26789694520737"
        ixy="0.251800166452908"
        ixz="-1.79738202827734"
        iyy="4.40181075101217"
        iyz="0.369996125102797"
        izz="2.53081551195838" />
    </inertial>
    <visual>
      <origin
        xyz="0 0 0"
        rpy="0 0 0" />
      <geometry>
        <mesh
          filename="package://urdf brat stang 7/meshes/left_elbow_shaft.STL" />
      </geometry>
      <material
        name="">
        <color
          rgba="0.752941176470588 0.752941176470588 0.752941176470588 1" />
      </material>
    </visual>
    <collision>
      <origin
        xyz="0 0 0"
        rpy="0 0 0" />
      <geometry>
        <mesh
          filename="package://urdf brat stang 7/meshes/left_elbow_shaft.STL" />
      </geometry>
    </collision>
  </link>
  <joint
    name="left_elbow_shaft_fixture_joint"
    type="fixed">
    <origin
      xyz="0 0 0"
      rpy="0 0 0" />
    <parent
      link="left_elbow_rs03_flange" />
    <child
      link="left_elbow_shaft" />
    <axis
      xyz="0 0 0" />
  </joint>
  <link
    name="m4x25_left_elbow_screws">
    <inertial>
      <origin
        xyz="-0.00623517616945923 -0.0126230084228056 -1.5800547537026E-09"
        rpy="0 0 0" />
      <mass
        value="0.00270858033444495" />
      <inertia
        ixx="1.79392020983022E-07"
        ixy="-8.40403332919024E-08"
        ixz="-2.17678380369018E-15"
        iyy="5.07657695439309E-08"
        iyz="-4.71341285920786E-15"
        izz="2.20904014947488E-07" />
    </inertial>
    <visual>
      <origin
        xyz="0 0 0"
        rpy="0 0 0" />
      <geometry>
        <mesh
          filename="package://urdf brat stang 7/meshes/m4x25_left_elbow_screws.STL" />
      </geometry>
      <material
        name="">
        <color
          rgba="0.792156862745098 0.819607843137255 0.933333333333333 1" />
      </material>
    </visual>
    <collision>
      <origin
        xyz="0 0 0"
        rpy="0 0 0" />
      <geometry>
        <mesh
          filename="package://urdf brat stang 7/meshes/m4x25_left_elbow_screws.STL" />
      </geometry>
    </collision>
  </link>
  <joint
    name="m4x25_left_elbow_screws_fixture_joint"
    type="fixed">
    <origin
      xyz="0 0 0"
      rpy="0 0 0" />
    <parent
      link="left_elbow_shaft" />
    <child
      link="m4x25_left_elbow_screws" />
    <axis
      xyz="0 0 0" />
  </joint>
  <link
    name="left_elbow">
    <inertial>
      <origin
        xyz="-0.0011766162325757 -0.0226416909878782 -0.0323595640978438"
        rpy="0 0 0" />
      <mass
        value="0.779765456176632" />
      <inertia
        ixx="0.00250248689492046"
        ixy="0.00010702602467171"
        ixz="0.000573100224582793"
        iyy="0.0029164826362284"
        iyz="0.000125954647195335"
        izz="0.000972783881372284" />
    </inertial>
    <visual>
      <origin
        xyz="0 0 0"
        rpy="0 0 0" />
      <geometry>
        <mesh
          filename="package://urdf brat stang 7/meshes/left_elbow.STL" />
      </geometry>
      <material
        name="">
        <color
          rgba="0.952941176470588 0.996078431372549 0.694117647058824 1" />
      </material>
    </visual>
    <collision>
      <origin
        xyz="0 0 0"
        rpy="0 0 0" />
      <geometry>
        <mesh
          filename="package://urdf brat stang 7/meshes/left_elbow.STL" />
      </geometry>
    </collision>
  </link>
  <joint
    name="left_elbow_fixture_joint"
    type="fixed">
    <origin
      xyz="0 0 0"
      rpy="0 0 0" />
    <parent
      link="m4x25_left_elbow_screws" />
    <child
      link="left_elbow" />
    <axis
      xyz="0 0 0" />
  </joint>
  <link
    name="m3x20_left_wrist_screws">
    <inertial>
      <origin
        xyz="-0.00322617478917386 -0.0374854467235402 0.00322626231628043"
        rpy="0 0 0" />
      <mass
        value="0.00162137028637935" />
      <inertia
        ixx="8.36724015923341E-08"
        ixy="6.8399216009266E-16"
        ixz="-1.09755051476026E-14"
        iyy="3.32920091128032E-09"
        iyz="-6.80875305447723E-14"
        izz="8.3672411512252E-08" />
    </inertial>
    <visual>
      <origin
        xyz="0 0 0"
        rpy="0 0 0" />
      <geometry>
        <mesh
          filename="package://urdf brat stang 7/meshes/m3x20_left_wrist_screws.STL" />
      </geometry>
      <material
        name="">
        <color
          rgba="0.792156862745098 0.819607843137255 0.933333333333333 1" />
      </material>
    </visual>
    <collision>
      <origin
        xyz="0 0 0"
        rpy="0 0 0" />
      <geometry>
        <mesh
          filename="package://urdf brat stang 7/meshes/m3x20_left_wrist_screws.STL" />
      </geometry>
    </collision>
  </link>
  <joint
    name="m3x20_left_wrist_screws_fixture_joint"
    type="fixed">
    <origin
      xyz="0.0370688771049235 -0.0244446769789257 -0.15848929336033"
      rpy="-1.29963611177836 0 -2.02959481544726" />
    <parent
      link="left_elbow" />
    <child
      link="m3x20_left_wrist_screws" />
    <axis
      xyz="0 0 0" />
  </joint>
  <link
    name="left_wrist_actuator">
    <inertial>
      <origin
        xyz="-2.23280616218346E-10 -0.0230138333779122 9.95055797758937E-08"
        rpy="0 0 0" />
      <mass
        value="0.180583065420557" />
      <inertia
        ixx="8.80899821792289E-05"
        ixy="-2.23449366716405E-14"
        ixz="-1.17737579668348E-19"
        iyy="0.000127000739066183"
        iyz="3.29199492779585E-11"
        izz="8.80899821792569E-05" />
    </inertial>
    <visual>
      <origin
        xyz="0 0 0"
        rpy="0 0 0" />
      <geometry>
        <mesh
          filename="package://urdf brat stang 7/meshes/left_wrist_actuator.STL" />
      </geometry>
      <material
        name="">
        <color
          rgba="0.823529411764706 0.823529411764706 1 1" />
      </material>
    </visual>
    <collision>
      <origin
        xyz="0 0 0"
        rpy="0 0 0" />
      <geometry>
        <mesh
          filename="package://urdf brat stang 7/meshes/left_wrist_actuator.STL" />
      </geometry>
    </collision>
  </link>
  <joint
    name="left_wrist_actuator_fixture_link"
    type="fixed">
    <origin
      xyz="0 0 0"
      rpy="0 0 0" />
    <parent
      link="m3x20_left_wrist_screws" />
    <child
      link="left_wrist_actuator" />
    <axis
      xyz="0 0 0" />
  </joint>
  <link
    name="left_wrist_rs02_flange">
    <inertial>
      <origin
        xyz="-2.84328338651108E-10 -0.00198993490318111 1.17727700477133E-07"
        rpy="0 0 0" />
      <mass
        value="0.00245793392108135" />
      <inertia
        ixx="1.34950766910333E-07"
        ixy="-7.368168567894E-17"
        ixz="5.0416658335107E-22"
        iyy="2.63403217776789E-07"
        iyz="1.08675600798964E-13"
        izz="1.34950766910425E-07" />
    </inertial>
    <visual>
      <origin
        xyz="0 0 0"
        rpy="0 0 0" />
      <geometry>
        <mesh
          filename="package://urdf brat stang 7/meshes/left_wrist_rs02_flange.STL" />
      </geometry>
      <material
        name="">
        <color
          rgba="0.823529411764706 0.823529411764706 1 1" />
      </material>
    </visual>
    <collision>
      <origin
        xyz="0 0 0"
        rpy="0 0 0" />
      <geometry>
        <mesh
          filename="package://urdf brat stang 7/meshes/left_wrist_rs02_flange.STL" />
      </geometry>
    </collision>
  </link>
  <joint
    name="left_wrist_rs02_flange_joint"
    type="revolute">
    <origin
      xyz="0 0 0"
      rpy="0 0 0" />
    <parent
      link="left_wrist_actuator" />
    <child
      link="left_wrist_rs02_flange" />
    <axis
      xyz="0 1 0" />
    <limit
      lower="-3.14"
      upper="3.14"
      effort="17"
      velocity="0.8" />
    <safety_controller
      soft_upper_limit="3.14"
      soft_lower_limit="-3.14"
      k_velocity="0" />
  </joint>
  <link
    name="m4x20_left_wrist_screws">
    <inertial>
      <origin
        xyz="3.33874400348932E-08 0.0084026651053235 1.47909658743117E-07"
        rpy="0 0 0" />
      <mass
        value="0.00232797016313321" />
      <inertia
        ixx="1.29587507987178E-07"
        ixy="-3.32297411344836E-13"
        ixz="3.13118287866634E-13"
        iyy="8.48546817317182E-09"
        iyz="-3.12384289243143E-13"
        izz="1.29587220640328E-07" />
    </inertial>
    <visual>
      <origin
        xyz="0 0 0"
        rpy="0 0 0" />
      <geometry>
        <mesh
          filename="package://urdf brat stang 7/meshes/m4x20_left_wrist_screws.STL" />
      </geometry>
      <material
        name="">
        <color
          rgba="0.792156862745098 0.819607843137255 0.933333333333333 1" />
      </material>
    </visual>
    <collision>
      <origin
        xyz="0 0 0"
        rpy="0 0 0" />
      <geometry>
        <mesh
          filename="package://urdf brat stang 7/meshes/m4x20_left_wrist_screws.STL" />
      </geometry>
    </collision>
  </link>
  <joint
    name="m4x20_left_wrist_screws_fixture_joint"
    type="fixed">
    <origin
      xyz="0 0 0"
      rpy="0 0 0" />
    <parent
      link="left_wrist_rs02_flange" />
    <child
      link="m4x20_left_wrist_screws" />
    <axis
      xyz="0 0 0" />
  </joint>
  <link
    name="left_wrist_shaft">
    <inertial>
      <origin
        xyz="-2.89938628661446E-10 0.00798511248800171 1.26166955993767E-07"
        rpy="0 0 0" />
      <mass
        value="0.000903649674373975" />
      <inertia
        ixx="4.41715688076223E-08"
        ixy="2.43014598068629E-17"
        ixz="1.89217565121505E-23"
        iyy="1.80539813298977E-09"
        iyz="-3.58433727003308E-14"
        izz="4.4171568807592E-08" />
    </inertial>
    <visual>
      <origin
        xyz="0 0 0"
        rpy="0 0 0" />
      <geometry>
        <mesh
          filename="package://urdf brat stang 7/meshes/left_wrist_shaft.STL" />
      </geometry>
      <material
        name="">
        <color
          rgba="0.823529411764706 0.823529411764706 1 1" />
      </material>
    </visual>
    <collision>
      <origin
        xyz="0 0 0"
        rpy="0 0 0" />
      <geometry>
        <mesh
          filename="package://urdf brat stang 7/meshes/left_wrist_shaft.STL" />
      </geometry>
    </collision>
  </link>
  <joint
    name="left_wrist_shaft_fixture_joint"
    type="fixed">
    <origin
      xyz="0 0 0"
      rpy="0 0 0" />
    <parent
      link="m4x20_left_wrist_screws" />
    <child
      link="left_wrist_shaft" />
    <axis
      xyz="0 0 0" />
  </joint>
  <link
    name="left_wrist">
    <inertial>
      <origin
        xyz="-0.0126284318210228 0.0418086841269973 0.00594039253722034"
        rpy="0 0 0" />
      <mass
        value="0.388950905166577" />
      <inertia
        ixx="0.00083365923302771"
        ixy="0.000191177318903803"
        ixz="2.04616802815707E-06"
        iyy="0.000517833817855438"
        iyz="-8.95571703468385E-05"
        izz="0.000838969560061725" />
    </inertial>
    <visual>
      <origin
        xyz="0 0 0"
        rpy="0 0 0" />
      <geometry>
        <mesh
          filename="package://urdf brat stang 7/meshes/left_wrist.STL" />
      </geometry>
      <material
        name="">
        <color
          rgba="0.952941176470588 0.996078431372549 0.694117647058824 1" />
      </material>
    </visual>
    <collision>
      <origin
        xyz="0 0 0"
        rpy="0 0 0" />
      <geometry>
        <mesh
          filename="package://urdf brat stang 7/meshes/left_wrist.STL" />
      </geometry>
    </collision>
  </link>
  <joint
    name="left_wrist_fixture_joint"
    type="fixed">
    <origin
      xyz="0 0 0"
      rpy="0 0 0" />
    <parent
      link="left_wrist_shaft" />
    <child
      link="left_wrist" />
    <axis
      xyz="0 0 0" />
  </joint>
  <link
    name="m3x16_left_hand_screws">
    <inertial>
      <origin
        xyz="-0.0363345178674755 0.00271811986352866 0.00366466137443122"
        rpy="0 0 0" />
      <mass
        value="0.00139374174732651" />
      <inertia
        ixx="3.07153113593584E-09"
        ixy="2.99011246526283E-15"
        ixz="-2.30300347815179E-14"
        iyy="4.88927935104831E-08"
        iyz="1.38741075276256E-16"
        izz="4.88928835911799E-08" />
    </inertial>
    <visual>
      <origin
        xyz="0 0 0"
        rpy="0 0 0" />
      <geometry>
        <mesh
          filename="package://urdf brat stang 7/meshes/m3x16_left_hand_screws.STL" />
      </geometry>
      <material
        name="">
        <color
          rgba="0.792156862745098 0.819607843137255 0.933333333333333 1" />
      </material>
    </visual>
    <collision>
      <origin
        xyz="0 0 0"
        rpy="0 0 0" />
      <geometry>
        <mesh
          filename="package://urdf brat stang 7/meshes/m3x16_left_hand_screws.STL" />
      </geometry>
    </collision>
  </link>
  <joint
    name="m3x16_left_hand_screws_fixture_joint"
    type="fixed">
    <origin
      xyz="0 0.0944999999998815 0"
      rpy="0.644848119833412 0.444064009162365 0" />
    <parent
      link="left_wrist" />
    <child
      link="m3x16_left_hand_screws" />
    <axis
      xyz="0 0 0" />
  </joint>
  <link
    name="left_hand_rs02">
    <inertial>
      <origin
        xyz="-0.0230139140894014 9.58860999489275E-08 1.39587437941735E-07"
        rpy="0 0 0" />
      <mass
        value="0.180583065420555" />
      <inertia
        ixx="0.000127000739066206"
        ixy="9.69568717547113E-12"
        ixz="-7.30113439629707E-12"
        iyy="8.80899821792287E-05"
        iyz="-1.63250733667733E-18"
        izz="8.80899821792277E-05" />
    </inertial>
    <visual>
      <origin
        xyz="0 0 0"
        rpy="0 0 0" />
      <geometry>
        <mesh
          filename="package://urdf brat stang 7/meshes/left_hand_rs02.STL" />
      </geometry>
      <material
        name="">
        <color
          rgba="0.823529411764706 0.823529411764706 1 1" />
      </material>
    </visual>
    <collision>
      <origin
        xyz="0 0 0"
        rpy="0 0 0" />
      <geometry>
        <mesh
          filename="package://urdf brat stang 7/meshes/left_hand_rs02.STL" />
      </geometry>
    </collision>
  </link>
  <joint
    name="left_hand_rs02_fixture_link"
    type="fixed">
    <origin
      xyz="0 0 0"
      rpy="0 0 0" />
    <parent
      link="m3x16_left_hand_screws" />
    <child
      link="left_hand_rs02" />
    <axis
      xyz="0 0 0" />
  </joint>
  <link
    name="left_hand_rs02_flange">
    <inertial>
      <origin
        xyz="-0.00201014599383542 1.01119780993031E-07 1.35646284760149E-07"
        rpy="0 0 0" />
      <mass
        value="0.00245793392108132" />
      <inertia
        ixx="2.63403217776863E-07"
        ixy="3.20075427798838E-14"
        ixz="-2.4102603437892E-14"
        iyy="1.34950766910338E-07"
        iyz="-6.33410495096549E-21"
        izz="1.34950766910335E-07" />
    </inertial>
    <visual>
      <origin
        xyz="0 0 0"
        rpy="0 0 0" />
      <geometry>
        <mesh
          filename="package://urdf brat stang 7/meshes/left_hand_rs02_flange.STL" />
      </geometry>
      <material
        name="">
        <color
          rgba="0.823529411764706 0.823529411764706 1 1" />
      </material>
    </visual>
    <collision>
      <origin
        xyz="0 0 0"
        rpy="0 0 0" />
      <geometry>
        <mesh
          filename="package://urdf brat stang 7/meshes/left_hand_rs02_flange.STL" />
      </geometry>
    </collision>
  </link>
  <joint
    name="left_hand_rs02_flange_joint"
    type="revolute">
    <origin
      xyz="0 0 0"
      rpy="0 0 0" />
    <parent
      link="left_hand_rs02" />
    <child
      link="left_hand_rs02_flange" />
    <axis
      xyz="1 0 0" />
    <limit
      lower="-1.5"
      upper="1.7"
      effort="17"
      velocity="0.8" />
    <safety_controller
      soft_upper_limit="1.7"
      soft_lower_limit="-1.5"
      k_velocity="0" />
  </joint>
  <link
    name="left_hand">
    <inertial>
      <origin
        xyz="0.0119774204155371 0.0114766160008068 -0.011141606469449"
        rpy="0 0 0" />
      <mass
        value="0.285530357044819" />
      <inertia
        ixx="0.000354627603110874"
        ixy="1.61688394612827E-05"
        ixz="-1.6021202001183E-05"
        iyy="0.000247513429239453"
        iyz="3.0703979843658E-05"
        izz="0.000247329276786552" />
    </inertial>
    <visual>
      <origin
        xyz="0 0 0"
        rpy="0 0 0" />
      <geometry>
        <mesh
          filename="package://urdf brat stang 7/meshes/left_hand.STL" />
      </geometry>
      <material
        name="">
        <color
          rgba="0.952941176470588 0.996078431372549 0.694117647058824 1" />
      </material>
    </visual>
    <collision>
      <origin
        xyz="0 0 0"
        rpy="0 0 0" />
      <geometry>
        <mesh
          filename="package://urdf brat stang 7/meshes/left_hand.STL" />
      </geometry>
    </collision>
  </link>
  <joint
    name="left_hand_fixture_joint"
    type="fixed">
    <origin
      xyz="0 0 0"
      rpy="0 0 0" />
    <parent
      link="left_hand_rs02_flange" />
    <child
      link="left_hand" />
    <axis
      xyz="0 0 0" />
  </joint>
</robot>