<?xml version="1.0" encoding="utf-8"?>
<!-- This URDF was automatically created by SolidWorks to URDF Exporter! Originally created by Stephen Brawner (brawner@gmail.com) 
     Commit Version: 1.6.0-4-g7f85cfe  Build Version: 1.6.7995.38578
     For more information, please see http://wiki.ros.org/sw_urdf_exporter -->
<robot
  name="humanoid_arm_5dof_1.2">
  <link
    name="base_link">
    <inertial>
      <origin
        xyz="-7.688E-08 -6.1286E-07 0.33673"
        rpy="0 0 0" />
      <mass
        value="81.158" />
      <inertia
        ixx="15.828"
        ixy="-6.0733E-06"
        ixz="3.5965E-06"
        iyy="17.002"
        iyz="3.1799E-05"
        izz="2.1791" />
    </inertial>
    <visual>
      <origin
        xyz="0 0 0"
        rpy="0 0 0" />
      <geometry>
        <mesh
          filename="package://humanoid_arm_5dof_1.2/meshes/base_link.STL" />
      </geometry>
      <material
        name="">
        <color
          rgba="1 0.94902 0.9098 1" />
      </material>
    </visual>
    <collision>
      <origin
        xyz="0 0 0"
        rpy="0 0 0" />
      <geometry>
        <mesh
          filename="package://humanoid_arm_5dof_1.2/meshes/base_link.STL" />
      </geometry>
    </collision>
  </link>
  <link
    name="left_shoulder_pitch_rs04_actuator">
    <inertial>
      <origin
        xyz="-0.024532 1.1728E-12 -9.6234E-13"
        rpy="0 0 0" />
      <mass
        value="1.345" />
      <inertia
        ixx="0.00087641"
        ixy="-1.1503E-17"
        ixz="-1.4762E-16"
        iyy="0.0005424"
        iyz="-3.5471E-06"
        izz="0.00054116" />
    </inertial>
    <visual>
      <origin
        xyz="0 0 0"
        rpy="0 0 0" />
      <geometry>
        <mesh
          filename="package://humanoid_arm_5dof_1.2/meshes/left_shoulder_pitch_rs04_actuator.STL" />
      </geometry>
      <material
        name="">
        <color
          rgba="0.82353 0.82353 1 1" />
      </material>
    </visual>
    <collision>
      <origin
        xyz="0 0 0"
        rpy="0 0 0" />
      <geometry>
        <mesh
          filename="package://humanoid_arm_5dof_1.2/meshes/left_shoulder_pitch_rs04_actuator.STL" />
      </geometry>
    </collision>
  </link>
  <joint
    name="left_shoulder_pitch_rs04_actuator_fixture_link"
    type="fixed">
    <origin
      xyz="-0.407699999999937 0 1.05000000000147"
      rpy="-0.638663834670851 0 3.14159265358979" />
    <parent
      link="base_link" />
    <child
      link="left_shoulder_pitch_rs04_actuator" />
    <axis
      xyz="0 0 0" />
  </joint>
  <link
    name="left_shoulder_pitch_rs04_flange">
    <inertial>
      <origin
        xyz="-0.0018894 -9.5572E-05 2.5808E-05"
        rpy="0 0 0" />
      <mass
        value="0.0075" />
      <inertia
        ixx="2.3623E-06"
        ixy="8.4902E-21"
        ixz="-1.0813E-20"
        iyy="1.1941E-06"
        iyz="3.7058E-21"
        izz="1.1941E-06" />
    </inertial>
    <visual>
      <origin
        xyz="0 0 0"
        rpy="0 0 0" />
      <geometry>
        <mesh
          filename="package://humanoid_arm_5dof_1.2/meshes/left_shoulder_pitch_rs04_flange.STL" />
      </geometry>
      <material
        name="">
        <color
          rgba="0.82353 0.82353 1 1" />
      </material>
    </visual>
    <collision>
      <origin
        xyz="0 0 0"
        rpy="0 0 0" />
      <geometry>
        <mesh
          filename="package://humanoid_arm_5dof_1.2/meshes/left_shoulder_pitch_rs04_flange.STL" />
      </geometry>
    </collision>
  </link>
  <joint
    name="left_shoulder_pitch_rs04"
    type="revolute">
    <origin
      xyz="0 0 0"
      rpy="0 0 0" />
    <parent
      link="left_shoulder_pitch_rs04_actuator" />
    <child
      link="left_shoulder_pitch_rs04_flange" />
    <axis
      xyz="1 0 0" />
    <limit
      lower="-3.14"
      upper="3.14"
      effort="120"
      velocity="3" />
    <safety_controller
      soft_upper_limit="3.14"
      soft_lower_limit="-3.14"
      k_velocity="0" />
  </joint>
  <link
    name="left_shoulder_pitch">
    <inertial>
      <origin
        xyz="0.068247 0.039551 -5.234E-06"
        rpy="0 0 0" />
      <mass
        value="0.3" />
      <inertia
        ixx="0.0043457"
        ixy="-0.0020544"
        ixz="-3.8776E-07"
        iyy="0.0075578"
        iyz="-1.6186E-07"
        izz="0.0076907" />
    </inertial>
    <visual>
      <origin
        xyz="0 0 0"
        rpy="0 0 0" />
      <geometry>
        <mesh
          filename="package://humanoid_arm_5dof_1.2/meshes/left_shoulder_pitch.STL" />
      </geometry>
      <material
        name="">
        <color
          rgba="0.69804 0.69804 0.69804 1" />
      </material>
    </visual>
    <collision>
      <origin
        xyz="0 0 0"
        rpy="0 0 0" />
      <geometry>
        <mesh
          filename="package://humanoid_arm_5dof_1.2/meshes/left_shoulder_pitch.STL" />
      </geometry>
    </collision>
  </link>
  <joint
    name="left_shoulder_pitch_fixture"
    type="fixed">
    <origin
      xyz="0 0 0"
      rpy="0 0 0" />
    <parent
      link="left_shoulder_pitch_rs04_flange" />
    <child
      link="left_shoulder_pitch" />
    <axis
      xyz="0 0 0" />
  </joint>
  <link
    name="left_shoulder_roll_rs04_flange">
    <inertial>
      <origin
        xyz="-8.0793E-12 -0.0021106 2.1538E-10"
        rpy="0 0 0" />
      <mass
        value="0.0075" />
      <inertia
        ixx="1.1941E-06"
        ixy="2.5808E-22"
        ixz="8.6027E-22"
        iyy="2.3623E-06"
        iyz="-4.903E-15"
        izz="1.1941E-06" />
    </inertial>
    <visual>
      <origin
        xyz="0 0 0"
        rpy="0 0 0" />
      <geometry>
        <mesh
          filename="package://humanoid_arm_5dof_1.2/meshes/left_shoulder_roll_rs04_flange.STL" />
      </geometry>
      <material
        name="">
        <color
          rgba="0.82353 0.82353 1 1" />
      </material>
    </visual>
    <collision>
      <origin
        xyz="0 0 0"
        rpy="0 0 0" />
      <geometry>
        <mesh
          filename="package://humanoid_arm_5dof_1.2/meshes/left_shoulder_roll_rs04_flange.STL" />
      </geometry>
    </collision>
  </link>
  <joint
    name="left_shoulder_roll_rs04_flange"
    type="fixed">
    <origin
      xyz="0.116775431275821 0.0487000000004332 -2.70558071411298E-05"
      rpy="0 0 3.14159265358979" />
    <parent
      link="left_shoulder_pitch" />
    <child
      link="left_shoulder_roll_rs04_flange" />
    <axis
      xyz="0 0 0" />
  </joint>
  <link
    name="left_shoulder_roll_rs04_actuator">
    <inertial>
      <origin
        xyz="7.5431E-05 0.020532 2.7056E-05"
        rpy="0 0 0" />
      <mass
        value="1.345" />
      <inertia
        ixx="0.00054201"
        ixy="-1.5116E-14"
        ixz="-3.5941E-06"
        iyy="0.00087641"
        iyz="-1.4055E-12"
        izz="0.00054156" />
    </inertial>
    <visual>
      <origin
        xyz="0 0 0"
        rpy="0 0 0" />
      <geometry>
        <mesh
          filename="package://humanoid_arm_5dof_1.2/meshes/left_shoulder_roll_rs04_actuator.STL" />
      </geometry>
      <material
        name="">
        <color
          rgba="0.82353 0.82353 1 1" />
      </material>
    </visual>
    <collision>
      <origin
        xyz="0 0 0"
        rpy="0 0 0" />
      <geometry>
        <mesh
          filename="package://humanoid_arm_5dof_1.2/meshes/left_shoulder_roll_rs04_actuator.STL" />
      </geometry>
    </collision>
  </link>
  <joint
    name="left_shoulder_roll_rs04"
    type="revolute">
    <origin
      xyz="0 0 0"
      rpy="0 0 0" />
    <parent
      link="left_shoulder_roll_rs04_flange" />
    <child
      link="left_shoulder_roll_rs04_actuator" />
    <axis
      xyz="0 -1 0" />
    <limit
      lower="-3.5"
      upper="0.6"
      effort="120"
      velocity="3" />
    <safety_controller
      soft_upper_limit="3.14"
      soft_lower_limit="-3.14"
      k_velocity="0" />
  </joint>
  <link
    name="left_shoulder_roll">
    <inertial>
      <origin
        xyz="-0.0075223 0.049755 -0.055681"
        rpy="0 0 0" />
      <mass
        value="0.2494" />
      <inertia
        ixx="0.0066808"
        ixy="-0.00010577"
        ixz="-0.00053776"
        iyy="0.0073988"
        iyz="-0.0008009"
        izz="0.0022285" />
    </inertial>
    <visual>
      <origin
        xyz="0 0 0"
        rpy="0 0 0" />
      <geometry>
        <mesh
          filename="package://humanoid_arm_5dof_1.2/meshes/left_shoulder_roll.STL" />
      </geometry>
      <material
        name="">
        <color
          rgba="0.69804 0.69804 0.69804 1" />
      </material>
    </visual>
    <collision>
      <origin
        xyz="0 0 0"
        rpy="0 0 0" />
      <geometry>
        <mesh
          filename="package://humanoid_arm_5dof_1.2/meshes/left_shoulder_roll.STL" />
      </geometry>
    </collision>
  </link>
  <joint
    name="left_shoulde_roll_fixture"
    type="fixed">
    <origin
      xyz="0 0 0"
      rpy="0 0 0" />
    <parent
      link="left_shoulder_roll_rs04_actuator" />
    <child
      link="left_shoulder_roll" />
    <axis
      xyz="0 0 0" />
  </joint>
  <link
    name="left_shoulder_yaw_rs03_actuator">
    <inertial>
      <origin
        xyz="-0.00013735 -0.00027 0.025084"
        rpy="0 0 0" />
      <mass
        value="0.83" />
      <inertia
        ixx="0.00027432"
        ixy="-2.0735E-06"
        ixz="-2.5625E-07"
        iyy="0.00027129"
        iyz="-5.1493E-07"
        izz="0.00038166" />
    </inertial>
    <visual>
      <origin
        xyz="0 0 0"
        rpy="0 0 0" />
      <geometry>
        <mesh
          filename="package://humanoid_arm_5dof_1.2/meshes/left_shoulder_yaw_rs03_actuator.STL" />
      </geometry>
      <material
        name="">
        <color
          rgba="0.82353 0.82353 1 1" />
      </material>
    </visual>
    <collision>
      <origin
        xyz="0 0 0"
        rpy="0 0 0" />
      <geometry>
        <mesh
          filename="package://humanoid_arm_5dof_1.2/meshes/left_shoulder_yaw_rs03_actuator.STL" />
      </geometry>
    </collision>
  </link>
  <joint
    name="left_shoulder_yaw_rs03_actuator_fixture_link"
    type="fixed">
    <origin
      xyz="-0.0219716026665047 0.037700000000231 -0.173578614834026"
      rpy="0.0571232415871479 0.112571267005327 0.470875575147914" />
    <parent
      link="left_shoulder_roll" />
    <child
      link="left_shoulder_yaw_rs03_actuator" />
    <axis
      xyz="0 0 0" />
  </joint>
  <link
    name="left_shoulder_yaw_rs03_flange">
    <inertial>
      <origin
        xyz="-2.7103E-10 -6.8048E-10 -0.0012563"
        rpy="0 0 0" />
      <mass
        value="0.005" />
      <inertia
        ixx="5.6768E-07"
        ixy="7.974E-22"
        ixz="9.3141E-22"
        iyy="5.6768E-07"
        iyz="2.647E-23"
        izz="1.1311E-06" />
    </inertial>
    <visual>
      <origin
        xyz="0 0 0"
        rpy="0 0 0" />
      <geometry>
        <mesh
          filename="package://humanoid_arm_5dof_1.2/meshes/left_shoulder_yaw_rs03_flange.STL" />
      </geometry>
      <material
        name="">
        <color
          rgba="0.82353 0.82353 1 1" />
      </material>
    </visual>
    <collision>
      <origin
        xyz="0 0 0"
        rpy="0 0 0" />
      <geometry>
        <mesh
          filename="package://humanoid_arm_5dof_1.2/meshes/left_shoulder_yaw_rs03_flange.STL" />
      </geometry>
    </collision>
  </link>
  <joint
    name="left_shoulder_yaw_rs03"
    type="revolute">
    <origin
      xyz="0 0 0"
      rpy="0 0 0" />
    <parent
      link="left_shoulder_yaw_rs03_actuator" />
    <child
      link="left_shoulder_yaw_rs03_flange" />
    <axis
      xyz="0 0 1" />
    <limit
      lower="-3.14"
      upper="3.14"
      effort="60"
      velocity="1.6" />
    <safety_controller
      soft_upper_limit="3.14"
      soft_lower_limit="-3.14"
      k_velocity="0" />
  </joint>
  <link
    name="left_shoulder_yaw_flange">
    <inertial>
      <origin
        xyz="-2.2487E-10 -3.6886E-10 -0.0089804"
        rpy="0 0 0" />
      <mass
        value="0.0089" />
      <inertia
        ixx="1.2318E-05"
        ixy="-9.4259E-08"
        ixz="4.4902E-16"
        iyy="1.1992E-05"
        iyz="-6.0556E-16"
        izz="2.339E-05" />
    </inertial>
    <visual>
      <origin
        xyz="0 0 0"
        rpy="0 0 0" />
      <geometry>
        <mesh
          filename="package://humanoid_arm_5dof_1.2/meshes/left_shoulder_yaw_flange.STL" />
      </geometry>
      <material
        name="">
        <color
          rgba="0.69804 0.69804 0.69804 1" />
      </material>
    </visual>
    <collision>
      <origin
        xyz="0 0 0"
        rpy="0 0 0" />
      <geometry>
        <mesh
          filename="package://humanoid_arm_5dof_1.2/meshes/left_shoulder_yaw_flange.STL" />
      </geometry>
    </collision>
  </link>
  <joint
    name="left_shoulder_yaw_flange_fixture"
    type="fixed">
    <origin
      xyz="0 0 0"
      rpy="0 0 0" />
    <parent
      link="left_shoulder_yaw_rs03_flange" />
    <child
      link="left_shoulder_yaw_flange" />
    <axis
      xyz="0 0 0" />
  </joint>
  <link
    name="left_shoulder_yaw">
    <inertial>
      <origin
        xyz="-0.027609 1.0121E-06 -0.076632"
        rpy="0 0 0" />
      <mass
        value="0.122" />
      <inertia
        ixx="0.0018364"
        ixy="2.5971E-07"
        ixz="-0.00033902"
        iyy="0.0016454"
        iyz="8.6387E-08"
        izz="0.0010145" />
    </inertial>
    <visual>
      <origin
        xyz="0 0 0"
        rpy="0 0 0" />
      <geometry>
        <mesh
          filename="package://humanoid_arm_5dof_1.2/meshes/left_shoulder_yaw.STL" />
      </geometry>
      <material
        name="">
        <color
          rgba="0.69804 0.69804 0.69804 1" />
      </material>
    </visual>
    <collision>
      <origin
        xyz="0 0 0"
        rpy="0 0 0" />
      <geometry>
        <mesh
          filename="package://humanoid_arm_5dof_1.2/meshes/left_shoulder_yaw.STL" />
      </geometry>
    </collision>
  </link>
  <joint
    name="left_shoulder_yaw_fixture"
    type="fixed">
    <origin
      xyz="0 0 0"
      rpy="0 0 0" />
    <parent
      link="left_shoulder_yaw_flange" />
    <child
      link="left_shoulder_yaw" />
    <axis
      xyz="0 0 0" />
  </joint>
  <link
    name="left_elbow_rs03_actuator">
    <inertial>
      <origin
        xyz="-0.025084 8.1191E-07 -0.00030291"
        rpy="0 0 0" />
      <mass
        value="0.83" />
      <inertia
        ixx="0.00038166"
        ixy="3.1874E-09"
        ixz="5.7519E-07"
        iyy="0.00027537"
        iyz="1.1044E-08"
        izz="0.00027024" />
    </inertial>
    <visual>
      <origin
        xyz="0 0 0"
        rpy="0 0 0" />
      <geometry>
        <mesh
          filename="package://humanoid_arm_5dof_1.2/meshes/left_elbow_rs03_actuator.STL" />
      </geometry>
      <material
        name="">
        <color
          rgba="0.82353 0.82353 1 1" />
      </material>
    </visual>
    <collision>
      <origin
        xyz="0 0 0"
        rpy="0 0 0" />
      <geometry>
        <mesh
          filename="package://humanoid_arm_5dof_1.2/meshes/left_elbow_rs03_actuator.STL" />
      </geometry>
    </collision>
  </link>
  <joint
    name="left_elbow_rs03_actuator_ficture_link"
    type="fixed">
    <origin
      xyz="0 0 -0.0987"
      rpy="0 0 0" />
    <parent
      link="left_shoulder_yaw" />
    <child
      link="left_elbow_rs03_actuator" />
    <axis
      xyz="0 0 0" />
  </joint>
  <link
    name="left_elbow_rs03_flange">
    <inertial>
      <origin
        xyz="0.0012563 -1.3768E-09 -1.6639E-10"
        rpy="0 0 0" />
      <mass
        value="0.005" />
      <inertia
        ixx="1.1311E-06"
        ixy="1.3533E-21"
        ixz="4.839E-21"
        iyy="5.6768E-07"
        iyz="-3.4411E-22"
        izz="5.6768E-07" />
    </inertial>
    <visual>
      <origin
        xyz="0 0 0"
        rpy="0 0 0" />
      <geometry>
        <mesh
          filename="package://humanoid_arm_5dof_1.2/meshes/left_elbow_rs03_flange.STL" />
      </geometry>
      <material
        name="">
        <color
          rgba="0.82353 0.82353 1 1" />
      </material>
    </visual>
    <collision>
      <origin
        xyz="0 0 0"
        rpy="0 0 0" />
      <geometry>
        <mesh
          filename="package://humanoid_arm_5dof_1.2/meshes/left_elbow_rs03_flange.STL" />
      </geometry>
    </collision>
  </link>
  <joint
    name="left_elbow_rs03"
    type="revolute">
    <origin
      xyz="0 0 0"
      rpy="0 0 0" />
    <parent
      link="left_elbow_rs03_actuator" />
    <child
      link="left_elbow_rs03_flange" />
    <axis
      xyz="-1 0 0" />
    <limit
      lower="-1.3"
      upper="1.9"
      effort="60"
      velocity="1.6" />
    <safety_controller
      soft_upper_limit="3.14"
      soft_lower_limit="-3.14"
      k_velocity="0" />
  </joint>
  <link
    name="left_elbow">
    <inertial>
      <origin
        xyz="0.020821 0.0089724 -0.03236"
        rpy="0 0 0" />
      <mass
        value="0.1948" />
      <inertia
        ixx="0.0036503"
        ixy="0.00012418"
        ixz="-0.00045842"
        iyy="0.0031234"
        iyz="0.00057257"
        izz="0.001216" />
    </inertial>
    <visual>
      <origin
        xyz="0 0 0"
        rpy="0 0 0" />
      <geometry>
        <mesh
          filename="package://humanoid_arm_5dof_1.2/meshes/left_elbow.STL" />
      </geometry>
      <material
        name="">
        <color
          rgba="0.69804 0.69804 0.69804 1" />
      </material>
    </visual>
    <collision>
      <origin
        xyz="0 0 0"
        rpy="0 0 0" />
      <geometry>
        <mesh
          filename="package://humanoid_arm_5dof_1.2/meshes/left_elbow.STL" />
      </geometry>
    </collision>
  </link>
  <joint
    name="left_elbow_fixture"
    type="fixed">
    <origin
      xyz="0 0 0"
      rpy="0 0 0" />
    <parent
      link="left_elbow_rs03_flange" />
    <child
      link="left_elbow" />
    <axis
      xyz="0 0 0" />
  </joint>
  <link
    name="left_wrist_actuator">
    <inertial>
      <origin
        xyz="-6.2923E-10 -0.023014 2.7886E-07"
        rpy="0 0 0" />
      <mass
        value="0.38" />
      <inertia
        ixx="8.809E-05"
        ixy="-1.0044E-17"
        ixz="-7.7715E-20"
        iyy="0.000127"
        iyz="3.6849E-17"
        izz="8.809E-05" />
    </inertial>
    <visual>
      <origin
        xyz="0 0 0"
        rpy="0 0 0" />
      <geometry>
        <mesh
          filename="package://humanoid_arm_5dof_1.2/meshes/left_wrist_actuator.STL" />
      </geometry>
      <material
        name="">
        <color
          rgba="0.82353 0.82353 1 1" />
      </material>
    </visual>
    <collision>
      <origin
        xyz="0 0 0"
        rpy="0 0 0" />
      <geometry>
        <mesh
          filename="package://humanoid_arm_5dof_1.2/meshes/left_wrist_actuator.STL" />
      </geometry>
    </collision>
  </link>
  <joint
    name="left_wrist_rs02_actuator_fixture_link"
    type="fixed">
    <origin
      xyz="0.00550000028936815 0.0440612514790653 -0.158489293351936"
      rpy="-1.29963429793404 0 0" />
    <parent
      link="left_elbow" />
    <child
      link="left_wrist_actuator" />
    <axis
      xyz="0 0 0" />
  </joint>
  <link
    name="left_wrist_rs02_flange">
    <inertial>
      <origin
        xyz="-6.0001E-10 -0.0019899 2.782E-07"
        rpy="0 0 0" />
      <mass
        value="0.0025" />
      <inertia
        ixx="1.3495E-07"
        ixy="8.379E-20"
        ixz="-2.6635E-22"
        iyy="2.634E-07"
        iyz="1.01E-19"
        izz="1.3495E-07" />
    </inertial>
    <visual>
      <origin
        xyz="0 0 0"
        rpy="0 0 0" />
      <geometry>
        <mesh
          filename="package://humanoid_arm_5dof_1.2/meshes/left_wrist_rs02_flange.STL" />
      </geometry>
      <material
        name="">
        <color
          rgba="0.82353 0.82353 1 1" />
      </material>
    </visual>
    <collision>
      <origin
        xyz="0 0 0"
        rpy="0 0 0" />
      <geometry>
        <mesh
          filename="package://humanoid_arm_5dof_1.2/meshes/left_wrist_rs02_flange.STL" />
      </geometry>
    </collision>
  </link>
  <joint
    name="left_wrist_rs02"
    type="revolute">
    <origin
      xyz="0 0 0"
      rpy="0 0 0" />
    <parent
      link="left_wrist_actuator" />
    <child
      link="left_wrist_rs02_flange" />
    <axis
      xyz="0 1 0" />
    <limit
      lower="-3.14"
      upper="3.14"
      effort="17"
      velocity="0.8" />
    <safety_controller
      soft_upper_limit="3.14"
      soft_lower_limit="-3.14"
      k_velocity="0" />
  </joint>
  <link
    name="left_wrist">
    <inertial>
      <origin
        xyz="-0.012628 0.041809 0.0059405"
        rpy="0 0 0" />
      <mass
        value="0.0972" />
      <inertia
        ixx="0.0010421"
        ixy="0.00023897"
        ixz="2.5575E-06"
        iyy="0.00064729"
        iyz="-0.00011195"
        izz="0.0010487" />
    </inertial>
    <visual>
      <origin
        xyz="0 0 0"
        rpy="0 0 0" />
      <geometry>
        <mesh
          filename="package://humanoid_arm_5dof_1.2/meshes/left_wrist.STL" />
      </geometry>
      <material
        name="">
        <color
          rgba="0.69804 0.69804 0.69804 1" />
      </material>
    </visual>
    <collision>
      <origin
        xyz="0 0 0"
        rpy="0 0 0" />
      <geometry>
        <mesh
          filename="package://humanoid_arm_5dof_1.2/meshes/left_wrist.STL" />
      </geometry>
    </collision>
  </link>
  <joint
    name="left_wrist_fixture"
    type="fixed">
    <origin
      xyz="0 0 0"
      rpy="0 0 0" />
    <parent
      link="left_wrist_rs02_flange" />
    <child
      link="left_wrist" />
    <axis
      xyz="0 0 0" />
  </joint>
  <link
    name="left_hand_rs02">
    <inertial>
      <origin
        xyz="-0.023014 2.2389E-07 3.2594E-07"
        rpy="0 0 0" />
      <mass
        value="0.38" />
      <inertia
        ixx="0.000127"
        ixy="2.2647E-11"
        ixz="-1.704E-11"
        iyy="8.809E-05"
        iyz="-9.7506E-18"
        izz="8.809E-05" />
    </inertial>
    <visual>
      <origin
        xyz="0 0 0"
        rpy="0 0 0" />
      <geometry>
        <mesh
          filename="package://humanoid_arm_5dof_1.2/meshes/left_hand_rs02.STL" />
      </geometry>
      <material
        name="">
        <color
          rgba="0.82353 0.82353 1 1" />
      </material>
    </visual>
    <collision>
      <origin
        xyz="0 0 0"
        rpy="0 0 0" />
      <geometry>
        <mesh
          filename="package://humanoid_arm_5dof_1.2/meshes/left_hand_rs02.STL" />
      </geometry>
    </collision>
  </link>
  <joint
    name="left_hand_rs02_fixture_link"
    type="fixed">
    <origin
      xyz="0 0.0944999999997473 0"
      rpy="0.644846111175764 0.444064007774013 0" />
    <parent
      link="left_wrist" />
    <child
      link="left_hand_rs02" />
    <axis
      xyz="0 0 0" />
  </joint>
  <link
    name="left_hand_rs02_flange">
    <inertial>
      <origin
        xyz="-0.0020103 2.3612E-07 3.1674E-07"
        rpy="0 0 0" />
      <mass
        value="0.0025" />
      <inertia
        ixx="2.634E-07"
        ixy="7.4761E-14"
        ixz="-5.6253E-14"
        iyy="1.3495E-07"
        iyz="-3.2489E-20"
        izz="1.3495E-07" />
    </inertial>
    <visual>
      <origin
        xyz="0 0 0"
        rpy="0 0 0" />
      <geometry>
        <mesh
          filename="package://humanoid_arm_5dof_1.2/meshes/left_hand_rs02_flange.STL" />
      </geometry>
      <material
        name="">
        <color
          rgba="0.82353 0.82353 1 1" />
      </material>
    </visual>
    <collision>
      <origin
        xyz="0 0 0"
        rpy="0 0 0" />
      <geometry>
        <mesh
          filename="package://humanoid_arm_5dof_1.2/meshes/left_hand_rs02_flange.STL" />
      </geometry>
    </collision>
  </link>
  <joint
    name="left_hand_rs02"
    type="revolute">
    <origin
      xyz="0 0 0"
      rpy="0 0 0" />
    <parent
      link="left_hand_rs02" />
    <child
      link="left_hand_rs02_flange" />
    <axis
      xyz="0.999999999999735 0 0" />
    <limit
      lower="-1.5"
      upper="1.7"
      effort="17"
      velocity="0.8" />
    <safety_controller
      soft_upper_limit="1.7"
      soft_lower_limit="-1.5"
      k_velocity="0" />
  </joint>
  <link
    name="left_hand">
    <inertial>
      <origin
        xyz="0.011977 0.011477 -0.011141"
        rpy="0 0 0" />
      <mass
        value="0.07138" />
      <inertia
        ixx="0.00044328"
        ixy="2.0211E-05"
        ixz="-2.0027E-05"
        iyy="0.00030939"
        iyz="3.838E-05"
        izz="0.00030916" />
    </inertial>
    <visual>
      <origin
        xyz="0 0 0"
        rpy="0 0 0" />
      <geometry>
        <mesh
          filename="package://humanoid_arm_5dof_1.2/meshes/left_hand.STL" />
      </geometry>
      <material
        name="">
        <color
          rgba="0.69804 0.69804 0.69804 1" />
      </material>
    </visual>
    <collision>
      <origin
        xyz="0 0 0"
        rpy="0 0 0" />
      <geometry>
        <mesh
          filename="package://humanoid_arm_5dof_1.2/meshes/left_hand.STL" />
      </geometry>
    </collision>
  </link>
  <joint
    name="left_hand_fixture"
    type="fixed">
    <origin
      xyz="0 0 0"
      rpy="0 0 0" />
    <parent
      link="left_hand_rs02_flange" />
    <child
      link="left_hand" />
    <axis
      xyz="0 0 0" />
  </joint>
  <link
    name="left_palm">
    <inertial>
      <origin
        xyz="-9.0329E-10 0.0065439 -1.9612E-09"
        rpy="0 0 0" />
      <mass
        value="0.04762" />
      <inertia
        ixx="0.00014804"
        ixy="1.9127E-12"
        ixz="2.4927E-11"
        iyy="0.00037746"
        iyz="3.0997E-12"
        izz="0.00028521" />
    </inertial>
    <visual>
      <origin
        xyz="0 0 0"
        rpy="0 0 0" />
      <geometry>
        <mesh
          filename="package://humanoid_arm_5dof_1.2/meshes/left_palm.STL" />
      </geometry>
      <material
        name="">
        <color
          rgba="0.69804 0.69804 0.69804 1" />
      </material>
    </visual>
    <collision>
      <origin
        xyz="0 0 0"
        rpy="0 0 0" />
      <geometry>
        <mesh
          filename="package://humanoid_arm_5dof_1.2/meshes/left_palm.STL" />
      </geometry>
    </collision>
  </link>
  <joint
    name="left_palm_fixture"
    type="fixed">
    <origin
      xyz="0 0.0468292785877469 -0.0458451123506719"
      rpy="-0.774935929629906 -0.017568105518168 0.0172027241786164" />
    <parent
      link="left_hand" />
    <child
      link="left_palm" />
    <axis
      xyz="0 0 0" />
  </joint>
  <link
    name="left_palm_right_finger">
    <inertial>
      <origin
        xyz="0.017481 0.050369 9.3983E-12"
        rpy="0 0 0" />
      <mass
        value="0.029" />
      <inertia
        ixx="0.00010609"
        ixy="1.2822E-05"
        ixz="-4.1669E-16"
        iyy="4.9057E-05"
        iyz="-3.9835E-16"
        izz="8.8986E-05" />
    </inertial>
    <visual>
      <origin
        xyz="0 0 0"
        rpy="0 0 0" />
      <geometry>
        <mesh
          filename="package://humanoid_arm_5dof_1.2/meshes/left_palm_right_finger.STL" />
      </geometry>
      <material
        name="">
        <color
          rgba="0.69804 0.69804 0.69804 1" />
      </material>
    </visual>
    <collision>
      <origin
        xyz="0 0 0"
        rpy="0 0 0" />
      <geometry>
        <mesh
          filename="package://humanoid_arm_5dof_1.2/meshes/left_palm_right_finger.STL" />
      </geometry>
    </collision>
  </link>
  <joint
    name="left_palm_right_finger"
    type="prismatic">
    <origin
      xyz="0 0 0"
      rpy="0 0 0" />
    <parent
      link="left_palm" />
    <child
      link="left_palm_right_finger" />
    <axis
      xyz="-1 0 0" />
    <limit
      lower="-0.033"
      upper="0.00026"
      effort="0"
      velocity="0" />
    <safety_controller
      soft_upper_limit="0.00026"
      soft_lower_limit="-0.033"
      k_velocity="0" />
  </joint>
  <link
    name="left_palm_left_finger">
    <inertial>
      <origin
        xyz="-0.019739 0.050369 1.0353E-11"
        rpy="0 0 0" />
      <mass
        value="0.029" />
      <inertia
        ixx="0.00010609"
        ixy="-1.2822E-05"
        ixz="-4.6155E-16"
        iyy="4.9057E-05"
        iyz="2.6035E-16"
        izz="8.8986E-05" />
    </inertial>
    <visual>
      <origin
        xyz="0 0 0"
        rpy="0 0 0" />
      <geometry>
        <mesh
          filename="package://humanoid_arm_5dof_1.2/meshes/left_palm_left_finger.STL" />
      </geometry>
      <material
        name="">
        <color
          rgba="0.69804 0.69804 0.69804 1" />
      </material>
    </visual>
    <collision>
      <origin
        xyz="0 0 0"
        rpy="0 0 0" />
      <geometry>
        <mesh
          filename="package://humanoid_arm_5dof_1.2/meshes/left_palm_left_finger.STL" />
      </geometry>
    </collision>
  </link>
  <joint
    name="left_palm_left_finger"
    type="prismatic">
    <origin
      xyz="0 0 0"
      rpy="0 0 0" />
    <parent
      link="left_palm" />
    <child
      link="left_palm_left_finger" />
    <axis
      xyz="-1 0 0" />
    <limit
      lower="-0.0041"
      upper="0.033"
      effort="0"
      velocity="0" />
    <safety_controller
      soft_upper_limit="0.033"
      soft_lower_limit="-0.0041"
      k_velocity="0" />
  </joint>
</robot>